Workbook
Name Hols: Static!$A$1:$A$29

Sheet H
A1: Entity Name | B1: Valuation First Level | C1: Valuation Second Level | D1: i Issue Name | E1: PrimaryAssetID | F1: Issue Description | G1: Original Nominal | H1: Clean Book Value | I1: Clean Market Value | J1: Accrued Income | K1: Dividend Receivable | L1: Sum of Market Value Income | M1: Market Price /Yield | N1: % of Total Market Value | O1: Next Coupon Date | P1: Maturity Date | Q1: Coupon | R1: Duration | S1: Modified Duration | T1: Investment Type | U1: Security Type | V1: Sub Security Type | W1: CCY | X1: Sector | Y1: Supersector | Z1: Industry | AA1: Issuer Rating | AB1: Security Rating | AC1: NACA Yield | AD1: NACM Yield | AE1: Weighted Avg NACA Yield | AF1: Weighted Avg NACM Yield | AG1: Market Value % | AH1: Current Exposure | AI1: Current Exposure % | AJ1: i Position Effective Date | AK1: Entity ID | AL1: Weighted Average NACS Yield | AM1: Weighted Average Coupon | AN1: Weighted Modified Duration | AO1: Issuer | AP1: ISIN Code | AQ1: Ticker
A2: 27four Life - Pos Ret | B2: BONDS | C2: Bonds (3 - 7 Years) | D2: LBK28 10.565% 150528 | E2: LBK28 | F2: LBK28 10.565% 150528 | G2: 712800 | H2: 723195.45 | I2: 669940.9 | J2: 32805.11 | K2: 0 | L2: 702746.01 | M2: 11.88 | N2: 0.00159882 | O2: 44697 | P2: 46888 | Q2: 10.565 | R2: 4.73 | S2: 4.4668326 | T2: FI | U2: FI | V2: VB | W2: ZAR | AA2: AA+ | AC2: 12.232836 | AD2: 11.596214 | AE2: 12.23 | AF2: 11.596214 | AG2: 2.41 | AH2: 702746.01 | AI2: 0 | AJ2: 44673 | AK2: PLPRNA | AL2: 11.88 | AM2: 10.56 | AN2: 4.47 | AO2: LANDBANK | AP2: ZAG000151275 | AQ2: LBK28
A3: 27four Life - Pos Ret | B3: BONDS | C3: Bonds (3 - 7 Years) | D3: RSA 10.50% R186 211226 | E3: R186 | F3: RSA 10.50% R186 211226 | G3: 5700000 | H3: 6355488.9 | I3: 6192648.2 | J3: 201686.3 | K3: 0 | L3: 6394334.5 | M3: 8.225 | N3: 0.0145478 | O3: 44733 | P3: 46377 | Q3: 10.5 | R3: 3.72 | S3: 3.572673 | T3: FI | U3: FI | V3: VB | W3: ZAR | X3: GOVI | AA3: AAA | AC3: 8.3941266 | AD3: 8.0875032 | AE3: 8.39 | AF3: 8.0875032 | AG3: 21.96 | AH3: 6394334.5 | AI3: 0.01 | AJ3: 44673 | AK3: PLPRNA | AL3: 8.23 | AM3: 10.5 | AN3: 3.57 | AO3: REP OF SOUTH AFRICA | AP3: ZAG000016320 | AQ3: R186
A4: 27four Life - Pos Ret | B4: BONDS | C4: Bonds (7 - 12 Years) | D4: Transnet 10.50% TN30 091030 | E4: TN30 | F4: Transnet 10.50% TN30 091030 | G4: 250000 | H4: 249155.29 | I4: 239047.7 | J4: 863.01 | K4: 0 | L4: 239910.71 | M4: 11.316 | N4: 0.00054582 | O4: 44844 | P4: 47765 | Q4: 10.5 | R4: 5.71 | S4: 5.4077134 | T4: FI | U4: FI | V4: VB | W4: ZAR | AA4: AA+ | AC4: 11.63613 | AD4: 11.058095 | AE4: 11.64 | AF4: 11.058095 | AG4: 0.82 | AH4: 239910.71 | AI4: 0 | AJ4: 44673 | AK4: PLPRNA | AL4: 11.32 | AM4: 10.5 | AN4: 5.41 | AO4: TRANSNET SOC LTD | AP4: ZAG000120312 | AQ4: TN30
A5: 27four Life - Pos Ret | B5: BONDS | C5: Bonds (Greater than 12 Years) | D5: R2048 8.75% 280248 | E5: R2048 | F5: R2048 8.75% 280248 | G5: 800000 | H5: 643705.51 | I5: 657589.12 | J5: 10571.92 | K5: 0 | L5: 668161.04 | M5: 10.805 | N5: 0.00152014 | O5: 44804 | P5: 54116 | Q5: 8.75 | R5: 9.22 | S5: 8.7507642 | T5: FI | U5: FI | V5: VB | W5: ZAR | X5: GOVI | AA5: AAA | AC5: 11.09687 | AD5: 10.56951 | AE5: 11.1 | AF5: 10.56951 | AG5: 2.29 | AH5: 668161.04 | AI5: 0 | AJ5: 44673 | AK5: PLPRNA | AL5: 10.8 | AM5: 8.75 | AN5: 8.75 | AO5: REP OF SOUTH AFRICA | AP5: ZAG000096173 | AQ5: R2048
A6: 27four Life - Pos Ret | B6: BONDS | C6: Bonds (Greater than 12 Years) | D6: RSA 8.50% R2037 310137 | E6: R2037 | F6: RSA 8.50% R2037 310137 | G6: 770000 | H6: 643445.5 | I6: 643822.03 | J6: 14494.25 | K6: 0 | L6: 658316.28 | M6: 10.735 | N6: 0.00149774 | O6: 44774 | P6: 50071 | Q6: 8.5 | R6: 7.91 | S6: 7.5106017 | T6: FI | U6: FI | V6: VB | W6: ZAR | X6: GOVI | AA6: AAA | AC6: 11.023101 | AD6: 10.502504 | AE6: 11.02 | AF6: 10.502504 | AG6: 2.26 | AH6: 658316.28 | AI6: 0 | AJ6: 44673 | AK6: PLPRNA | AL6: 10.73 | AM6: 8.5 | AN6: 7.51 | AO6: REP OF SOUTH AFRICA | AP6: ZAG000107012 | AQ6: R2037
A7: 27four Life - Pos Ret | B7: BONDS | C7: Bonds (Greater than 12 Years) | D7: Transnet 10.75% TN40 091040 | E7: TN40 | F7: Transnet 10.75% TN40 091040 | G7: 750000 | H7: 689768.42 | I7: 678319.58 | J7: 3092.47 | K7: 0 | L7: 681412.05 | M7: 12.05 | N7: 0.00155029 | O7: 44844 | P7: 51418 | Q7: 10.75 | R7: 7.89 | S7: 7.4432484 | T7: FI | U7: FI | V7: VB | W7: ZAR | X7: CR | AA7: AA+ | AC7: 12.413006 | AD7: 11.758178 | AE7: 12.41 | AF7: 11.758178 | AG7: 2.34 | AH7: 681412.05 | AI7: 0 | AJ7: 44673 | AK7: PLPRNA | AL7: 12.05 | AM7: 10.75 | AN7: 7.44 | AO7: TRANSNET SOC LTD | AP7: ZAG000120320 | AQ7: TN40
A8: 27four Life - Pos Ret | B8: BONDS | C8: Inflation Linked Bonds | D8: I2038 2.25% 310138 | E8: I2038 | F8: I2038 2.25% 310138 | G8: 560000 | H8: 721108.82 | I8: 724140.52 | J8: 4535.56 | K8: 0 | L8: 728676.08 | M8: 3.9 | N8: 0.00165782 | O8: 44774 | P8: 50436 | Q8: 2.25 | R8: 12.94 | S8: 12.689805 | T8: FI | U8: FI | V8: ILB | W8: ZAR | X8: GOVI | AA8: AAA | AC8: 3.938025 | AD8: 3.868685 | AE8: 3.94 | AF8: 3.868685 | AG8: 2.5 | AH8: 728676.08 | AI8: 0 | AJ8: 44673 | AK8: PLPRNA | AL8: 3.9 | AM8: 2.25 | AN8: 12.69 | AO8: REP OF SOUTH AFRICA | AP8: ZAG000096595 | AQ8: I2038
A9: 27four Life - Pos Ret | B9: BONDS | C9: Inflation Linked Bonds | D9: I2046 2.50% 310346 | E9: I2046 | F9: I2046 2.50% 310346 | G9: 610000 | H9: 717046.87 | I9: 721712.48 | J9: 1451.21 | K9: 0 | L9: 723163.69 | M9: 3.9 | N9: 0.00164528 | O9: 44834 | P9: 53417 | Q9: 2.5 | R9: 17.22 | S9: 16.886632 | T9: FI | U9: FI | V9: ILB | W9: ZAR | X9: GOVI | AA9: AAA | AC9: 3.938025 | AD9: 3.868685 | AE9: 3.94 | AF9: 3.868685 | AG9: 2.48 | AH9: 723163.69 | AI9: 0 | AJ9: 44673 | AK9: PLPRNA | AL9: 3.9 | AM9: 2.5 | AN9: 16.89 | AO9: REP OF SOUTH AFRICA | AP9: ZAG000106980 | AQ9: I2046
A10: 27four Life - Pos Ret | B10: BONDS | C10: Inflation Linked Bonds | D10: I2050 2.25% 2050 | E10: I2050 | F10: I2050 2.25% 2050 | G10: 670000 | H10: 799864.37 | I10: 814726.49 | J10: 8301.19 | K10: 0 | L10: 823027.68 | M10: 3.9 | N10: 0.00187248 | O10: 44742 | P10: 55153 | Q10: 2.5 | R10: 19.05 | S10: 18.689624 | T10: FI | U10: FI | V10: ILB | W10: ZAR | X10: GOVI | AA10: AAA | AC10: 3.938025 | AD10: 3.868685 | AE10: 3.94 | AF10: 3.868685 | AG10: 2.83 | AH10: 823027.68 | AI10: 0 | AJ10: 44673 | AK10: PLPRNA | AL10: 3.9 | AM10: 2.5 | AN10: 18.69 | AO10: REP OF SOUTH AFRICA | AP10: ZAG000096603 | AQ10: I2050
A11: 27four Life - Pos Ret | B11: BONDS | C11: Inflation Linked Bonds | D11: RSA 1.875% I2033 280233 | E11: I2033 | F11: RSA 1.875% I2033 280233 | G11: 630000 | H11: 714819.35 | I11: 712992.51 | J11: 2387.12 | K11: 0 | L11: 715379.63 | M11: 3.82 | N11: 0.00162757 | O11: 44804 | P11: 48638 | Q11: 1.875 | R11: 9.71 | S11: 9.5277219 | T11: FI | U11: FI | V11: ILB | W11: ZAR | X11: GOVI | AA11: AAA | AC11: 3.856481 | AD11: 3.7899493 | AE11: 3.86 | AF11: 3.7899493 | AG11: 2.46 | AH11: 715379.63 | AI11: 0 | AJ11: 44673 | AK11: PLPRNA | AL11: 3.82 | AM11: 1.88 | AN11: 9.53 | AO11: REP OF SOUTH AFRICA | AP11: ZAG000125998 | AQ11: I2033
A12: 27four Life - Pos Ret | B12: CASH | C12: Cash on Call | D12: Prescient Money Market Fund B3 | E12: PRMFB3 | F12: Prescient Money Market Fund B3 | G12: 641852.67 | H12: 641852.68 | I12: 641852.68 | J12: 2058.36 | K12: 0 | L12: 643911.04 | N12: 0.00146497 | O12: 40756 | P12: 73020 | Q12: 0 | T12: FI | U12: CIS | V12: CSH | W12: ZAR | AE12: 0 | AF12: 0 | AG12: 2.21 | AH12: 643911.04 | AI12: 0 | AJ12: 44673 | AK12: PLPRNA | AL12: 0 | AM12: 0 | AN12: 0 | AP12: ZAE000140885 | AQ12: PRMFB3
A13: 27four Life - Pos Ret | B13: CASH | C13: Safex Margin Deposits | D13: SAFEX Margin | E13: SAFEX | F13: Margin Account | G13: 922517 | H13: 922517 | I13: 922517 | J13: 3253.23 | K13: 0 | L13: 925770.23 | M13: 6.88 | N13: 0.00210623 | P13: 55153 | Q13: 6.88 | R13: 0.08 | S13: 0.002600675 | T13: ST | U13: CSH | V13: MARGIN | W13: ZAR | AE13: 0 | AF13: 0 | AG13: 3.18 | AH13: 925770.23 | AI13: 0 | AJ13: 44673 | AK13: PLPRNA | AL13: 0 | AM13: 6.88 | AN13: 0 | AO13: SAFEX | AQ13: SAFEX
A14: 27four Life - Pos Ret | B14: CASH | C14: Traded Cash | D14: Interest on Cash ZAR | E14: INTRZAR | F14: Interest on Cash | G14: 0 | H14: 0 | I14: 0 | J14: 0 | K14: 0 | L14: 312.49 | N14: 7.1e-07 | R14: 0.08 | T14: CASH | U14: CSH | W14: ZAR | AC14: 5.116339 | AD14: 5.0001425 | AE14: 5.12 | AF14: 5.0001425 | AG14: 0 | AH14: 312.49 | AI14: 0 | AJ14: 44673 | AK14: PLPRNA | AL14: 5.05 | AM14: 0 | AN14: 0
A15: 27four Life - Pos Ret | B15: CASH | C15: Traded Cash | D15: South African Rand | E15: CASHZAR | F15: South African Rand | G15: 311922.04 | H15: 311921.48 | I15: 311922.04 | J15: 0 | K15: 0 | L15: 311922.04 | N15: 0.00070966 | R15: 0.08 | T15: CASH | U15: CRNY | W15: ZAR | AC15: 5.116339 | AD15: 5.0001425 | AE15: 5.12 | AF15: 5.0001425 | AG15: 1.07 | AH15: 311922.04 | AI15: 0 | AJ15: 44673 | AK15: PLPRNA | AL15: 5.05 | AM15: 0 | AN15: 0 | AQ15: ZAR
A16: 27four Life - Pos Ret | B16: CASH | C16: Unsettled Cash | D16: Audit Fee | E16: AUDITFEE | F16: Audit Fee | G16: -12118.12 | H16: -12118.12 | I16: -12118.12 | J16: 0 | L16: -12118.12 | N16: -2.757e-05 | P16: 73051 | Q16: 0 | R16: 0.08 | T16: CASH | U16: EXP | W16: ZAR | AC16: 5.116339 | AD16: 5.0001425 | AE16: 5.12 | AF16: 5.0001425 | AG16: -0.04 | AH16: -12118.12 | AI16: 0 | AJ16: 44673 | AK16: PLPRNA | AL16: 5.05 | AM16: 0 | AN16: 0
A17: 27four Life - Pos Ret | B17: CASH | C17: Unsettled Cash | D17: Management Fee | E17: MGMTFEE | G17: -2499.98 | H17: -2499.98 | I17: -2499.98 | J17: 0 | L17: -2499.98 | N17: -5.69e-06 | P17: 73051 | Q17: 0 | R17: 0.08 | T17: CASH | W17: ZAR | AC17: 5.116339 | AD17: 5.0001425 | AE17: 5.12 | AF17: 5.0001425 | AG17: -0.01 | AH17: -2499.98 | AI17: 0 | AJ17: 44673 | AK17: PLPRNA | AL17: 5.05 | AM17: 0 | AN17: 0
A18: 27four Life - Pos Ret | B18: CASH | C18: Unsettled Cash | D18: Other Fee | E18: OTHFEE | G18: -3039.6 | H18: -3039.6 | I18: -3039.6 | J18: 0 | L18: -3039.6 | N18: -6.92e-06 | P18: 73051 | Q18: 0 | R18: 0.08 | T18: CASH | W18: ZAR | AC18: 5.116339 | AD18: 5.0001425 | AE18: 5.12 | AF18: 5.0001425 | AG18: -0.01 | AH18: -3039.6 | AI18: 0 | AJ18: 44673 | AK18: PLPRNA | AL18: 5.05 | AM18: 0 | AN18: 0
A19: 27four Life - Pos Ret | B19: CASH | C19: Unsettled Cash | D19: Variation Margin | E19: VARMARG | G19: -270103.1 | H19: -270103.1 | I19: -270103.1 | J19: 0 | L19: -270103.1 | N19: -0.00061451 | P19: 73051 | Q19: 0 | R19: 0.08 | T19: CASH | W19: ZAR | AC19: 5.116339 | AD19: 5.0001425 | AE19: 5.12 | AF19: 5.0001425 | AG19: -0.93 | AH19: -270103.1 | AI19: 0 | AJ19: 44673 | AK19: PLPRNA | AL19: 5.05 | AM19: 0 | AN19: 0
A20: 27four Life - Pos Ret | B20: COLLECTIVE INVESTMENT SCHEMES | C20: Domestic | D20: Prescient Flexible Fixed Interest Fund B3 | E20: PFFB3 | F20: Prescient Flexible Fixed Interest Fund B3 | G20: 4898432.2 | H20: 5152718.6 | I20: 5088001.5 | J20: 0 | K20: 0 | L20: 5088001.5 | M20: 1.0387 | N20: 0.01157575 | T20: EQ | U20: CIS | V20: CIS | W20: ZAR | AE20: 0 | AF20: 0 | AG20: 17.48 | AH20: 5088001.5 | AI20: 0.01 | AJ20: 44673 | AK20: PLPRNA | AL20: 0 | AM20: 0 | AN20: 0 | AP20: ZAE000222469 | AQ20: PFFB3
A21: 27four Life - Pos Ret | B21: COLLECTIVE INVESTMENT SCHEMES | C21: Domestic | D21: Prescient Income Plus Fund B3 | E21: PLUSB3 | F21: Prescient Income Plus Fund B3 | G21: 2968566.7 | H21: 2974464.9 | I21: 2985190.7 | J21: 0 | K21: 0 | L21: 2985190.7 | M21: 1.0056 | N21: 0.00679163 | T21: EQ | U21: CIS | V21: CIS | W21: ZAR | AE21: 0 | AF21: 0 | AG21: 10.25 | AH21: 2985190.7 | AI21: 0.01 | AJ21: 44673 | AK21: PLPRNA | AL21: 0 | AM21: 0 | AN21: 0 | AP21: ZAE000284303 | AQ21: PLUSB3
A22: 27four Life - Pos Ret | B22: COLLECTIVE INVESTMENT SCHEMES | C22: Domestic | D22: Prescient Property Equity Fund B3 | E22: PPEB3 | F22: Prescient Property Equity Fund B3 | G22: 2338538.6 | H22: 1974323.8 | I22: 2347892.7 | J22: 0 | K22: 0 | L22: 2347892.7 | M22: 1.004 | N22: 0.00534171 | T22: EQ | U22: CIS | V22: CIS | W22: ZAR | AE22: 0 | AF22: 0 | AG22: 8.06 | AH22: 2347892.7 | AI22: 0.01 | AJ22: 44673 | AK22: PLPRNA | AL22: 0 | AM22: 0 | AN22: 0 | AP22: ZAE000140117 | AQ22: PPEB3
A23: 27four Life - Pos Ret | B23: DERIVATIVES | C23: Equity Derivatives | D23: 15DEC22 ALSI | E23: 15DEC22 ALSI | F23: 15DEC22 ALSI | G23: -12 | H23: 0 | I23: 0 | J23: 0 | K23: 0 | L23: 0 | M23: 65943 | N23: 0 | P23: 44910 | T23: FT | U23: DER | V23: IDXFT | W23: ZAR | AE23: 0 | AF23: 0 | AG23: 0 | AH23: -7913160 | AI23: -0.02 | AJ23: 44673 | AK23: PLPRNA | AL23: 0 | AM23: 0 | AN23: 0 | AP23: ZAD000277689 | AQ23: 15DEC22 ALSI
A24: 27four Life - Pos Ret | B24: DERIVATIVES | C24: Equity Derivatives | D24: 15DEC22 ALSI 70000C | E24: 15DEC22 ALSI 70000C | F24: 15DEC22 ALSI 70000C | G24: 21 | H24: 0 | I24: 0 | J24: 0 | K24: 0 | L24: 0 | M24: 23175 | N24: 0 | P24: 44910 | T24: OP | U24: DER | V24: IDXOP | W24: ZAR | AE24: 0 | AF24: 0 | AG24: 0 | AH24: 5146819.8 | AI24: 0.01 | AJ24: 44673 | AK24: PLPRNA | AL24: 0 | AM24: 0 | AN24: 0 | AP24: ZADA00256149 | AQ24: 15DEC22 ALSI 70000C
A25: 27four Life - Pos Ret | B25: DERIVATIVES | C25: Equity Derivatives | D25: 15JUN22 ALSI | E25: 15JUN22 ALSI | F25: 15JUN22 ALSI | G25: 15 | H25: 0 | I25: 0 | J25: 0 | K25: 0 | L25: 0 | M25: 65704 | N25: 0 | P25: 44727 | T25: FT | U25: DER | V25: IDXFT | W25: ZAR | AE25: 0 | AF25: 0 | AG25: 0 | AH25: 9855600 | AI25: 0.02 | AJ25: 44673 | AK25: PLPRNA | AL25: 0 | AM25: 0 | AN25: 0 | AP25: ZAD000277663 | AQ25: 15JUN22 ALSI
A26: 27four Life - Pos Ret | B26: DERIVATIVES | C26: Equity Derivatives | D26: 15JUN22 ALSI 63000P | E26: 15JUN22 ALSI 63000P | F26: 15JUN22 ALSI 63000P | G26: -4 | H26: 0 | I26: 0 | J26: 0 | K26: 0 | L26: 0 | M26: 11809 | N26: 0 | P26: 44727 | T26: OP | U26: DER | V26: IDXOP | W26: ZAR | AE26: 0 | AF26: 0 | AG26: 0 | AH26: 795312.24 | AI26: 0 | AJ26: 44673 | AK26: PLPRNA | AL26: 0 | AM26: 0 | AN26: 0 | AP26: ZADA00255067 | AQ26: 15JUN22 ALSI 63000P
A27: 27four Life - Pos Ret | B27: DERIVATIVES | C27: Equity Derivatives | D27: 15JUN22 ALSI 74000C | E27: 15JUN22 ALSI 74000C | F27: 15JUN22 ALSI 74000C | G27: -10 | H27: 0 | I27: 0 | J27: 0 | K27: 0 | L27: 0 | M27: 615 | N27: 0 | P27: 44727 | T27: OP | U27: DER | V27: IDXOP | W27: ZAR | AE27: 0 | AF27: 0 | AG27: 0 | AH27: -241880.94 | AI27: 0 | AJ27: 44673 | AK27: PLPRNA | AL27: 0 | AM27: 0 | AN27: 0 | AP27: ZADA00254565 | AQ27: 15JUN22 ALSI 74000C
A28: 27four Life - Pos Ret | B28: DERIVATIVES | C28: Equity Derivatives | D28: 15SEP22 ALSI | E28: 15SEP22 ALSI | F28: 15SEP22 ALSI | G28: -4 | H28: 0 | I28: 0 | J28: 0 | K28: 0 | L28: 0 | M28: 65741 | N28: 0 | P28: 44819 | T28: FT | U28: DER | V28: IDXFT | W28: ZAR | AE28: 0 | AF28: 0 | AG28: 0 | AH28: -2629640 | AI28: -0.01 | AJ28: 44673 | AK28: PLPRNA | AL28: 0 | AM28: 0 | AN28: 0 | AP28: ZAD000277671 | AQ28: 15SEP22 ALSI
A29: 27four Life - Pos Ret | B29: DERIVATIVES | C29: Equity Derivatives | D29: 15SEP22 ALSI 69000C | E29: 15SEP22 ALSI 69000C | F29: 15SEP22 ALSI 69000C | G29: 11 | H29: 0 | I29: 0 | J29: 0 | K29: 0 | L29: 0 | M29: 17668 | N29: 0 | P29: 44819 | T29: OP | U29: DER | V29: IDXOP | W29: ZAR | AE29: 0 | AF29: 0 | AG29: 0 | AH29: 2607657.7 | AI29: 0.01 | AJ29: 44673 | AK29: PLPRNA | AL29: 0 | AM29: 0 | AN29: 0 | AP29: ZADA00259275 | AQ29: 15SEP22 ALSI 69000C
A30: 27four Life - Pos Ret | B30: DERIVATIVES | C30: Equity Derivatives | D30: 15SEP22 ALSI 70000C | E30: 15SEP22 ALSI 70000C | F30: 15SEP22 ALSI 70000C | G30: 12 | H30: 0 | I30: 0 | J30: 0 | K30: 0 | L30: 0 | M30: 14076 | N30: 0 | P30: 44819 | T30: OP | U30: DER | V30: IDXOP | W30: ZAR | AE30: 0 | AF30: 0 | AG30: 0 | AH30: 2449487 | AI30: 0.01 | AJ30: 44673 | AK30: PLPRNA | AL30: 0 | AM30: 0 | AN30: 0 | AP30: ZADA00256511 | AQ30: 15SEP22 ALSI 70000C
A31: 27four Life - Pos Ret | B31: DERIVATIVES | C31: Equity Derivatives | D31: 15SEP22 ALSI 74000C | E31: 15SEP22 ALSI 74000C | F31: 15SEP22 ALSI 74000C | G31: -11 | H31: 0 | I31: 0 | J31: 0 | K31: 0 | L31: 0 | M31: 5097 | N31: 0 | P31: 44819 | T31: OP | U31: DER | V31: IDXOP | W31: ZAR | AE31: 0 | AF31: 0 | AG31: 0 | AH31: -1062695.8 | AI31: 0 | AJ31: 44673 | AK31: PLPRNA | AL31: 0 | AM31: 0 | AN31: 0 | AP31: ZADA00260075 | AQ31: 15SEP22 ALSI 74000C
A32: 27four Life - Pos Ret | B32: DERIVATIVES | C32: Equity Derivatives | D32: 15SEP22 ALSI 77000C | E32: 15SEP22 ALSI 77000C | F32: 15SEP22 ALSI 77000C | G32: -11 | H32: 0 | I32: 0 | J32: 0 | K32: 0 | L32: 0 | M32: 2268 | N32: 0 | P32: 44819 | T32: OP | U32: DER | V32: IDXOP | W32: ZAR | AE32: 0 | AF32: 0 | AG32: 0 | AH32: -546227.36 | AI32: 0 | AJ32: 44673 | AK32: PLPRNA | AL32: 0 | AM32: 0 | AN32: 0 | AP32: ZADA00259283 | AQ32: 15SEP22 ALSI 77000C
A33: 27four Life - Pos Ret | B33: PREFERENCE SHARES | C33: Preference Shares | D33: Absa Bank Ltd Preference Shares | E33: ABSP | F33: Absa Bank Ltd Preference Shares | G33: 1444 | H33: 953083.22 | I33: 1299600 | J33: 0 | K33: 36014.94 | L33: 1335614.9 | M33: 90000 | N33: 0.00303867 | T33: EQ | U33: EQ | V33: PREF | W33: ZAR | AA33: AA+ | AE33: 0 | AF33: 0 | AG33: 4.59 | AH33: 1335614.9 | AI33: 0 | AJ33: 44673 | AK33: PLPRNA | AL33: 0 | AM33: 0 | AN33: 0 | AO33: ABSA BANK LTD | AP33: ZAE000079810 | AQ33: ABSP
A34: 27four Life - Pos Ret | B34: PREFERENCE SHARES | C34: Preference Shares | D34: Discovery B Preference Shares | E34: DSBP | F34: Discovery B Preference Shares | G34: 9852 | H34: 878996.99 | I34: 952195.8 | J34: 0 | K34: 0 | L34: 952195.8 | M34: 9665 | N34: 0.00216635 | T34: EQ | U34: EQ | V34: PREF | W34: ZAR | X34: PREF | AE34: 0 | AF34: 0 | AG34: 3.27 | AH34: 952195.8 | AI34: 0 | AJ34: 44673 | AK34: PLPRNA | AL34: 0 | AM34: 0 | AN34: 0 | AP34: ZAE000158564 | AQ34: DSBP
A35: 27four Life - Pos Ret | B35: PREFERENCE SHARES | C35: Preference Shares | D35: Investec Ltd Preference Share | E35: INPR | F35: Investec Ltd Preference Share | G35: 7038 | H35: 516804.31 | I35: 678040.92 | J35: 0 | K35: 0 | L35: 678040.92 | M35: 9634 | N35: 0.00154262 | T35: EQ | U35: EQ | V35: PREF | W35: ZAR | AE35: 0 | AF35: 0 | AG35: 2.33 | AH35: 678040.92 | AI35: 0 | AJ35: 44673 | AK35: PLPRNA | AL35: 0 | AM35: 0 | AN35: 0 | AP35: ZAE000063814 | AQ35: INPR
A36: 27four Life - Pos Ret | B36: PREFERENCE SHARES | C36: Preference Shares | D36: Netcare Preference Share Ltd | E36: NTCP | F36: Netcare Preference Share Ltd | G36: 2312 | H36: 179077.7 | I36: 198832 | J36: 0 | K36: 0 | L36: 198832 | M36: 8600 | N36: 0.00045236 | T36: EQ | U36: EQ | V36: PREF | W36: ZAR | AE36: 0 | AF36: 0 | AG36: 0.68 | AH36: 198832 | AI36: 0 | AJ36: 44673 | AK36: PLPRNA | AL36: 0 | AM36: 0 | AN36: 0 | AP36: ZAE000081121 | AQ36: NTCP
A37: 27four Life - Pos Ret | B37: PREFERENCE SHARES | C37: Preference Shares | D37: Standard Bank Group Ltd Preference Shares | E37: SBPP | F37: Standard Bank Group Ltd Pref | G37: 5006 | H37: 378277.66 | I37: 462504.34 | J37: 0 | K37: 0 | L37: 462504.34 | M37: 9239 | N37: 0.00105225 | T37: EQ | U37: EQ | V37: PREF | W37: ZAR | AA37: AA+ | AE37: 0 | AF37: 0 | AG37: 1.59 | AH37: 462504.34 | AI37: 0 | AJ37: 44673 | AK37: PLPRNA | AL37: 0 | AM37: 0 | AN37: 0 | AO37: STANDARD BANK LTD | AP37: ZAE000056339 | AQ37: SBPP
A38: 27four Life - Pos Ret | B38: PRIVATE COMPANY | C38: Private Company | D38: Prescient Clean Energy and Infrastructure Debt Fund Trust | E38: PIMEVOA | F38: Prescient Clean Energy and Infrastructure Debt Fund Trust | G38: 1457675 | H38: 1465981.4 | I38: 1459569.9 | J38: 0 | K38: 0 | L38: 1459569.9 | M38: 1.0013 | N38: 0.00332068 | T38: EQ | U38: PRIVATE COMP | V38: OTHER | W38: ZAR | AE38: 0 | AF38: 0 | AG38: 5.01 | AH38: 1459569.9 | AI38: 0 | AJ38: 44673 | AK38: PLPRNA | AL38: 0 | AM38: 0 | AN38: 0 | AQ38: PIMEVOA
A39: 27four Life - Pos Ret | B39: UNKNOWN | C39: UNKNOWN | D39: Synthetic Cash_15DEC22 ALSI | E39: 15DEC22 ALSI | F39: Synthetic Cash_15DEC22 ALSI | G39: -12 | I39: 0 | L39: 0 | N39: 0 | T39: SYTH | U39: SYNCASHFUT | V39: CASH | W39: ZAR | AE39: 0 | AF39: 0 | AG39: 0 | AH39: 7913160 | AI39: 0.02 | AJ39: 44673 | AK39: PLPRNA | AL39: 0 | AM39: 0 | AN39: 0 | AQ39: SYNZAR
A40: 27four Life - Pos Ret | B40: UNKNOWN | C40: UNKNOWN | D40: Synthetic Cash_15DEC22 ALSI 70000C | E40: 15DEC22 ALSI 70000C | F40: Synthetic Cash_15DEC22 ALSI 70000C | G40: 21 | I40: 0 | L40: 0 | N40: 0 | T40: SYTH | U40: SYNCASHOPT | V40: CASH | W40: ZAR | AE40: 0 | AF40: 0 | AG40: 0 | AH40: -5146819.8 | AI40: -0.01 | AJ40: 44673 | AK40: PLPRNA | AL40: 0 | AM40: 0 | AN40: 0 | AQ40: SYNZAR
...

Sheet D
A1: Entity Name | B1: i Issue Name | C1: Primary Asset ID | D1: Nominal Holding | E1: Delta | F1: Market Value | G1: Effective Exposure
A2: 27four Life - Pos Ret | B2: 15DEC22 ALSI | C2: 15DEC22 ALSI | D2: -12 | E2: 1 | F2: 0 | G2: -7913160
A3: 27four Life - Pos Ret | B3: 15DEC22 ALSI 70000C | C3: 15DEC22 ALSI 70000C | D3: 21 | E3: 0.37166 | F3: 0 | G3: 5146819.8
A4: 27four Life - Pos Ret | B4: 15JUN22 ALSI | C4: 15JUN22 ALSI | D4: 15 | E4: 1 | F4: 0 | G4: 9855600
A5: 27four Life - Pos Ret | B5: 15JUN22 ALSI 63000P | C5: 15JUN22 ALSI 63000P | D5: -4 | E5: -0.30261 | F5: 0 | G5: 795312.24
A6: 27four Life - Pos Ret | B6: 15JUN22 ALSI 74000C | C6: 15JUN22 ALSI 74000C | D6: -10 | E6: 0.03681 | F6: 0 | G6: -241880.94
A7: 27four Life - Pos Ret | B7: 15JUN22 ALSI 75000C | C7: 15JUN22 ALSI 75000C | D7: 0 | E7: 0.04141 | F7: 0 | G7: 0
A8: 27four Life - Pos Ret | B8: 15SEP22 ALSI | C8: 15SEP22 ALSI | D8: -4 | E8: 1 | F8: 0 | G8: -2629640
A9: 27four Life - Pos Ret | B9: 15SEP22 ALSI 65000C | C9: 15SEP22 ALSI 65000C | D9: 0 | E9: 0.56031 | F9: 0 | G9: 0
A10: 27four Life - Pos Ret | B10: 15SEP22 ALSI 69000C | C10: 15SEP22 ALSI 69000C | D10: 11 | E10: 0.3606 | F10: 0 | G10: 2607657.7
A11: 27four Life - Pos Ret | B11: 15SEP22 ALSI 70000C | C11: 15SEP22 ALSI 70000C | D11: 12 | E11: 0.3105 | F11: 0 | G11: 2449487
A12: 27four Life - Pos Ret | B12: 15SEP22 ALSI 74000C | C12: 15SEP22 ALSI 74000C | D12: -11 | E12: 0.14695 | F12: 0 | G12: -1062695.8
A13: 27four Life - Pos Ret | B13: 15SEP22 ALSI 77000C | C13: 15SEP22 ALSI 77000C | D13: -11 | E13: 0.07553 | F13: 0 | G13: -546227.36
... A31: Absa MM Abs Ret Prud Fund | B31: 15SEP22 ALSI 77000C | C31: 15SEP22 ALSI 77000C | D31: -49 | E31: 0.07553 | F31: 0 | G31: -2433194.6
A32: ABSA MM Bond Fund | B32: No Data found for this Entity
A33: ABSA MULTI MAN EQ FUND PRESC | B33: 15JUN22 ALSI | C33: 15JUN22 ALSI | D33: 128 | E33: 1 | F33: 0 | G33: 84101120
A34: AFIL - Life Bond Fund | B34: No Data found for this Entity
A35: AFIL - Pensioner | B35: 15DEC22 ALSI | C35: 15DEC22 ALSI | D35: -60 | E35: 1 | F35: 0 | G35: -39565800
A36: AFIL - Pensioner | B36: 15DEC22 ALSI 70000C | C36: 15DEC22 ALSI 70000C | D36: 109 | E36: 0.37166 | F36: 0 | G36: 26714445
A37: AFIL - Pensioner | B37: 15JUN22 ALSI | C37: 15JUN22 ALSI | D37: 85 | E37: 1 | F37: 0 | G37: 55848400
A38: AFIL - Pensioner | B38: 15JUN22 ALSI 63000P | C38: 15JUN22 ALSI 63000P | D38: -26 | E38: -0.30261 | F38: 0 | G38: 5169529.5
A39: AFIL - Pensioner | B39: 15JUN22 ALSI 74000C | C39: 15JUN22 ALSI 74000C | D39: -72 | E39: 0.03681 | F39: 0 | G39: -1741542.7
A40: AFIL - Pensioner | B40: 15JUN22 ALSI 75000C | C40: 15JUN22 ALSI 75000C | D40: 0 | E40: 0.04141 | F40: 0 | G40: 0
A41: AFIL - Pensioner | B41: 15SEP22 ALSI | C41: 15SEP22 ALSI | D41: -29 | E41: 1 | F41: 0 | G41: -19064890
A42: AFIL - Pensioner | B42: 15SEP22 ALSI 65000C | C42: 15SEP22 ALSI 65000C | D42: 0 | E42: 0.56031 | F42: 0 | G42: 0
A43: AFIL - Pensioner | B43: 15SEP22 ALSI 69000C | C43: 15SEP22 ALSI 69000C | D43: 77 | E43: 0.3606 | F43: 0 | G43: 18253604
A44: AFIL - Pensioner | B44: 15SEP22 ALSI 70000C | C44: 15SEP22 ALSI 70000C | D44: 78 | E44: 0.3105 | F44: 0 | G44: 15921666
A45: AFIL - Pensioner | B45: 15SEP22 ALSI 74000C | C45: 15SEP22 ALSI 74000C | D45: -61 | E45: 0.14695 | F45: 0 | G45: -5893131.2
A46: AFIL - Pensioner | B46: 15SEP22 ALSI 77000C | C46: 15SEP22 ALSI 77000C | D46: -62 | E46: 0.07553 | F46: 0 | G46: -3078736
A47: Custodian BCI Income Plus Fund | B47: No Data found for this Entity
A48: ECIC Composite | B48: No Data found for this Entity
A49: Electric Cont Indust Pens Fund | B49: 15JUN22 DCAP | C49: 15JUN22 DCAP | D49: 96 | E49: 1 | F49: 0 | G49: 19211520
A50: Electric Cont Indust Pens Fund | B50: 15JUN22 DCAR | C50: 15JUN22 DCAR | D50: 30 | E50: 1 | F50: 0 | G50: 8720100
A51: EMBF - Positive Return Fund | B51: 15JUN22 ALSI | C51: 15JUN22 ALSI | D51: 15 | E51: 1 | F51: 0 | G51: 9855600
A52: EMBF - Positive Return Fund | B52: 15SEP22 ALSI | C52: 15SEP22 ALSI | D52: -11 | E52: 1 | F52: 0 | G52: -7231510
A53: EMBF - Positive Return Fund | B53: 15SEP22 ALSI 65000C | C53: 15SEP22 ALSI 65000C | D53: 0 | E53: 0.56031 | F53: 0 | G53: 0
A54: EMBF - Positive Return Fund | B54: 15SEP22 ALSI 69000C | C54: 15SEP22 ALSI 69000C | D54: 21 | E54: 0.3606 | F54: 0 | G54: 4978255.7
A55: EMBF - Positive Return Fund | B55: 15SEP22 ALSI 70000C | C55: 15SEP22 ALSI 70000C | D55: 22 | E55: 0.3105 | F55: 0 | G55: 4490726.2
A56: EMBF - Positive Return Fund | B56: 15SEP22 ALSI 74000C | C56: 15SEP22 ALSI 74000C | D56: -21 | E56: 0.14695 | F56: 0 | G56: -2028782.9
A57: FRB ITF GTC Wealth Preserver2 | B57: 15DEC22 ALSI | C57: 15DEC22 ALSI | D57: -82 | E57: 1 | F57: 0 | G57: -54073260
...

Sheet S
A1: Entity ID | B1: UT? | C1: # | D1: Cash Cover | E1: Cash Cover 2 | F1: Incl CLNs & longer dated debt | G1: Incl underlying UTs | H1: SA Bond Cover | I1: MSCI Cover | J1: ALSI Cover | K1: Total Equity | L1: Total Foreign | M1: Global Exposure | N1: Net Effective Exposure | O1: ="Derivative Calculations "&TEXT(Data!$AJ$2,"ddd d mmm yyyy") -> Derivative Calculations Wed 6 Apr 2022 | P1: Mandate
A2: PPSBAL_C | B2: =[1]Summary!$G$3 -> UT | C2: =[1]Summary!$E$1 -> 10 | D2: =[1]Summary!$C$34 -> 0.23653506 | E2: =[1]Summary!$E$34/100 -> 0.23653506 | F2: =[1]Summary!$C$36 -> 0.18917393 | G2: =[1]Summary!$C$32 -> 0 | H2: =[1]Summary!$E$6/100 -> 0.021755043 | I2: =[1]Summary!$E$10/100 -> 0.019637699 | J2: =[1]Summary!$E$14/100 -> 0.19157251 | K2: =[1]Summary!$C$40 -> 0.59271599 | L2: =[1]Summary!$C$54 -> 20.109194 | M2: ='[1]Glbl Expsr'!$D$2 -> 0.095371567 | N2: ='[1]Glbl Expsr'!$D$3 -> 0.095371567 | O2: \\pim-cpt-statpro\SPC_602\Client\Profiles\PIM\Exports\PPSBAL_C Derv Calc 6Apr2022.xlsx | P2: PPSBAL_C Mandate
A3: PCAEF | B3: =[2]Summary!$G$3 -> UT | C3: =[2]Summary!$E$1 -> 10 | D3: =[2]Summary!$C$34 -> 0.50252909 | E3: =[2]Summary!$E$34/100 -> 0.50252909 | F3: =[2]Summary!$C$36 -> 0 | G3: =[2]Summary!$C$32 -> 0 | H3: =[2]Summary!$E$6/100 -> 0 | I3: =[2]Summary!$E$10/100 -> 0.017757483 | J3: =[2]Summary!$E$14/100 -> 0.12463345 | K3: =[2]Summary!$C$40 -> 0.99223767 | L3: =[2]Summary!$C$54 -> 0 | M3: ='[2]Glbl Expsr'!$D$2 -> 0.066275317 | N3: ='[2]Glbl Expsr'!$D$3 -> 0.066275317 | O3: \\pim-cpt-statpro\SPC_602\Client\Profiles\PIM\Exports\PCAEF Derv Calc 6Apr2022.xlsx | P3: PCAEF Mandate
A4: ADRRC | B4: =[3]Summary!$G$3 -> UT | C4: =[3]Summary!$E$1 -> 9 | D4: =[3]Summary!$C$34 -> 0.01560478 | E4: =[3]Summary!$E$34/100 -> 0.01560478 | F4: =[3]Summary!$C$36 -> 0.19828813 | G4: =[3]Summary!$C$32 -> 0 | H4: =[3]Summary!$E$6/100 -> 0 | I4: =[3]Summary!$E$10/100 -> 0 | J4: =[3]Summary!$E$14/100 -> 0 | K4: =[3]Summary!$C$40 -> 0.40730673 | L4: =[3]Summary!$C$54 -> 0 | M4: ='[3]Glbl Expsr'!$D$2 -> 0.94737804 | N4: ='[3]Glbl Expsr'!$D$3 -> 0.21091173 | O4: \\pim-cpt-statpro\SPC_602\Client\Profiles\PIM\Exports\ADRRC Derv Calc 6Apr2022.xlsx | P4: ADRRC Mandate
A5: PPOS | B5: =[4]Summary!$G$3 -> UT | C5: =[4]Summary!$E$1 -> 9 | D5: =[4]Summary!$C$34 -> 0.029279105 | E5: =[4]Summary!$E$34/100 -> 0.029279105 | F5: =[4]Summary!$C$36 -> 0.20279073 | G5: =[4]Summary!$C$32 -> 0 | H5: =[4]Summary!$E$6/100 -> 0 | I5: =[4]Summary!$E$10/100 -> 0 | J5: =[4]Summary!$E$14/100 -> 0 | K5: =[4]Summary!$C$40 -> 0.42110671 | L5: =[4]Summary!$C$54 -> 0 | M5: ='[4]Glbl Expsr'!$D$2 -> 1.0335819 | N5: ='[4]Glbl Expsr'!$D$3 -> 0.21834449 | O5: \\pim-cpt-statpro\SPC_602\Client\Profiles\PIM\Exports\PPOS Derv Calc 6Apr2022.xlsx | P5: PPOS Mandate
A6: ABMMABR | B6: =[5]Summary!$G$3 -> UT | C6: =[5]Summary!$E$1 -> 9 | D6: =[5]Summary!$C$34 -> 0.032542983 | E6: =[5]Summary!$E$34/100 -> 0.032542983 | F6: =[5]Summary!$C$36 -> 0.16070469 | G6: =[5]Summary!$C$32 -> 0 | H6: =[5]Summary!$E$6/100 -> 0 | I6: =[5]Summary!$E$10/100 -> 0 | J6: =[5]Summary!$E$14/100 -> 0 | K6: =[5]Summary!$C$40 -> 0.35493861 | L6: =[5]Summary!$C$54 -> 19.462523 | M6: ='[5]Glbl Expsr'!$D$2 -> 0.84041325 | N6: ='[5]Glbl Expsr'!$D$3 -> 0.18768625 | O6: \\pim-cpt-statpro\SPC_602\Client\Profiles\PIM\Exports\ABMMABR Derv Calc 6Apr2022.xlsx | P6: ABMMABR Mandate
A7: GTCWP2 | B7: =[6]Summary!$G$3 -> UT | C7: =[6]Summary!$E$1 -> 9 | D7: =[6]Summary!$C$34 -> 0.058168227 | E7: =[6]Summary!$E$34/100 -> 0.058168227 | F7: =[6]Summary!$C$36 -> 0 | G7: =[6]Summary!$C$32 -> 0 | H7: =[6]Summary!$E$6/100 -> 0 | I7: =[6]Summary!$E$10/100 -> 0 | J7: =[6]Summary!$E$14/100 -> 0 | K7: =[6]Summary!$C$40 -> 0.6895952 | L7: =[6]Summary!$C$54 -> 0 | M7: ='[6]Glbl Expsr'!$D$2 -> 1.7138448 | N7: ='[6]Glbl Expsr'!$D$3 -> 0.50317318 | O7: \\pim-cpt-statpro\SPC_602\Client\Profiles\PIM\Exports\GTCWP2 Derv Calc 6Apr2022.xlsx | P7: GTCWP2 Mandate
A8: IJGBAL | B8: =[7]Summary!$G$3 -> UT | C8: =[7]Summary!$E$1 -> 7 | D8: =[7]Summary!$C$34 -> 0.3194741 | E8: =[7]Summary!$E$34/100 -> 0.3194741 | F8: =[7]Summary!$C$36 | G8: =[7]Summary!$C$32 -> 0.19963364 | H8: =[7]Summary!$E$6/100 -> 0 | I8: =[7]Summary!$E$10/100 -> 0 | J8: =[7]Summary!$E$14/100 -> 0 | K8: =[7]Summary!$C$40 -> 2.9931069 | L8: =[7]Summary!$C$54 -> 17.269108 | M8: ='[7]Glbl Expsr'!$D$2 -> 2.81539 | N8: ='[7]Glbl Expsr'!$D$3 -> 2.81539 | O8: \\pim-cpt-statpro\SPC_602\Client\Profiles\PIM\Exports\IJGBAL Derv Calc 6Apr2022.xlsx | P8: IJGBAL Mandate
A9: PCCEF | B9: =[8]Summary!$G$3 -> UT | C9: =[8]Summary!$E$1 -> 7 | D9: =[8]Summary!$C$34 -> 0.25044271 | E9: =[8]Summary!$E$34/100 -> 0.25044271 | F9: =[8]Summary!$C$36 -> 0 | G9: =[8]Summary!$C$32 -> 0 | H9: =[8]Summary!$E$6/100 -> 0 | I9: =[8]Summary!$E$10/100 -> 0.033255527 | J9: =[8]Summary!$E$14/100 -> 0.17587447 | K9: =[8]Summary!$C$40 -> 0.99069313 | L9: =[8]Summary!$C$54 -> 0 | M9: ='[8]Glbl Expsr'!$D$2 -> 0.23999995 | N9: ='[8]Glbl Expsr'!$D$3 -> 0.23999995 | O9: \\pim-cpt-statpro\SPC_602\Client\Profiles\PIM\Exports\PCCEF Derv Calc 6Apr2022.xlsx | P9: PCCEF Mandate
A10: PCEQTF | B10: =[9]Summary!$G$3 -> UT | C10: =[9]Summary!$E$1 -> 7 | D10: =[9]Summary!$C$34 -> 0.34681845 | E10: =[9]Summary!$E$34/100 -> 0.34681845 | F10: =[9]Summary!$C$36 -> 0 | G10: =[9]Summary!$C$32 -> 0 | H10: =[9]Summary!$E$6/100 -> 0 | I10: =[9]Summary!$E$10/100 -> 0.019768545 | J10: =[9]Summary!$E$14/100 -> 0.14712865 | K10: =[9]Summary!$C$40 -> 0.93018558 | L10: =[9]Summary!$C$54 -> 0 | M10: ='[9]Glbl Expsr'!$D$2 -> 0.088422855 | N10: ='[9]Glbl Expsr'!$D$3 -> 0.088422855 | O10: \\pim-cpt-statpro\SPC_602\Client\Profiles\PIM\Exports\PCEQTF Derv Calc 6Apr2022.xlsx | P10: PCEQTF Mandate
A11: PIMBAL | B11: =[10]Summary!$G$3 -> UT | C11: =[10]Summary!$E$1 -> 6 | D11: =[10]Summary!$C$34 -> 0.0071720338 | E11: =[10]Summary!$E$34/100 -> 0.037108757 | F11: =[10]Summary!$C$36 -> 0.12636503 | G11: =[10]Summary!$C$32 -> 0 | H11: =[10]Summary!$E$6/100 -> 0 | I11: =[10]Summary!$E$10/100 -> 0 | J11: =[10]Summary!$E$14/100 -> 0 | K11: =[10]Summary!$C$40 -> 0.64844859 | L11: =[10]Summary!$C$54 -> 43.825415 | M11: ='[10]Glbl Expsr'!$D$2 -> 0.028740154 | N11: ='[10]Glbl Expsr'!$D$3 -> 0.028740154 | O11: \\pim-cpt-statpro\SPC_602\Client\Profiles\PIM\Exports\PIMBAL Derv Calc 6Apr2022.xlsx | P11: PIMBAL Mandate
A12: PEAQ | B12: =[11]Summary!$G$3 -> UT | C12: =[11]Summary!$E$1 -> 5 | D12: =[11]Summary!$C$34 -> 0.47815719 | E12: =[11]Summary!$E$34/100 -> 0.47815719 | F12: =[11]Summary!$C$36 -> 0 | G12: =[11]Summary!$C$32 -> 0 | H12: =[11]Summary!$E$6/100 -> 0 | I12: =[11]Summary!$E$10/100 -> 0.042280309 | J12: =[11]Summary!$E$14/100 -> 0.21361833 | K12: =[11]Summary!$C$40 -> 0.98260704 | L12: =[11]Summary!$C$54 -> 0 | M12: ='[11]Glbl Expsr'!$D$2 -> 0.29444411 | N12: ='[11]Glbl Expsr'!$D$3 -> 0.29444411 | O12: \\pim-cpt-statpro\SPC_602\Client\Profiles\PIM\Exports\PEAQ Derv Calc 6Apr2022.xlsx | P12: PEAQ Mandate
A13: PBAL | B13: =[12]Summary!$G$3 -> UT | C13: =[12]Summary!$E$1 -> 4 | D13: =[12]Summary!$C$34 -> 0.0077845601 | E13: =[12]Summary!$E$34/100 -> 0.052814815 | F13: =[12]Summary!$C$36 -> 0.1589352 | G13: =[12]Summary!$C$32 -> 0 | H13: =[12]Summary!$E$6/100 -> 0 | I13: =[12]Summary!$E$10/100 -> 0 | J13: =[12]Summary!$E$14/100 -> 0 | K13: =[12]Summary!$C$40 -> 0.66108884 | L13: =[12]Summary!$C$54 -> 44.692991 | M13: ='[12]Glbl Expsr'!$D$2 -> 0.02812015 | N13: ='[12]Glbl Expsr'!$D$3 -> 0.02812015 | O13: \\pim-cpt-statpro\SPC_602\Client\Profiles\PIM\Exports\PBAL Derv Calc 6Apr2022.xlsx | P13: PBAL Mandate
A14: PPEF | B14: =[13]Summary!$G$3 -> UT | C14: =[13]Summary!$E$1 -> 4 | D14: =[13]Summary!$C$34 -> 0.12496283 | E14: =[13]Summary!$E$34/100 -> 0.12496283 | F14: =[13]Summary!$C$36 -> 0 | G14: =[13]Summary!$C$32 -> 0 | H14: =[13]Summary!$E$6/100 -> 0 | I14: =[13]Summary!$E$10/100 -> 0.017163907 | J14: =[13]Summary!$E$14/100 -> 0.38376815 | K14: =[13]Summary!$C$40 -> 0.99371009 | L14: =[13]Summary!$C$54 -> 0 | M14: ='[13]Glbl Expsr'!$D$2 -> 0.30927369 | N14: ='[13]Glbl Expsr'!$D$3 -> 0.30927369 | O14: \\pim-cpt-statpro\SPC_602\Client\Profiles\PIM\Exports\PPEF Derv Calc 6Apr2022.xlsx | P14: PPEF Mandate
A15: ABMMEQU | B15: =[14]Summary!$G$3 -> UT | C15: =[14]Summary!$E$1 -> 4 | D15: =[14]Summary!$C$34 -> 0.36844942 | E15: =[14]Summary!$E$34/100 -> 0.36844942 | F15: =[14]Summary!$C$36 -> 0 | G15: =[14]Summary!$C$32 -> 0 | H15: =[14]Summary!$E$6/100 -> 0 | I15: =[14]Summary!$E$10/100 -> 0.014180764 | J15: =[14]Summary!$E$14/100 -> 0.11705303 | K15: =[14]Summary!$C$40 -> 0.99281602 | L15: =[14]Summary!$C$54 -> 0 | M15: ='[14]Glbl Expsr'!$D$2 -> 0.12444838 | N15: ='[14]Glbl Expsr'!$D$3 -> 0.12444838 | O15: \\pim-cpt-statpro\SPC_602\Client\Profiles\PIM\Exports\ABMMEQU Derv Calc 6Apr2022.xlsx | P15: ABMMEQU Mandate
A16: PEQ | B16: =[15]Summary!$G$3 -> UT | C16: =[15]Summary!$E$1 -> 4 | D16: =[15]Summary!$C$34 -> 0.46363122 | E16: =[15]Summary!$E$34/100 -> 0.46363122 | F16: =[15]Summary!$C$36 -> 0 | G16: =[15]Summary!$C$32 -> 0 | H16: =[15]Summary!$E$6/100 -> 0 | I16: =[15]Summary!$E$10/100 -> 0 | J16: =[15]Summary!$E$14/100 -> 0 | K16: =[15]Summary!$C$40 -> 0.99423061 | L16: =[15]Summary!$C$54 -> 0 | M16: ='[15]Glbl Expsr'!$D$2 -> 0.15333856 | N16: ='[15]Glbl Expsr'!$D$3 -> 0.15333856 | O16: \\pim-cpt-statpro\SPC_602\Client\Profiles\PIM\Exports\PEQ Derv Calc 6Apr2022.xlsx | P16: PEQ Mandate
A17: SAAMMAN | B17: =[16]Summary!$G$3 -> UT | C17: =[16]Summary!$E$1 -> 3 | D17: =[16]Summary!$C$34 -> 0.0064514805 | E17: =[16]Summary!$E$34/100 -> 0.0064514805 | F17: =[16]Summary!$C$36 -> 0 | G17: =[16]Summary!$C$32 -> 0 | H17: =[16]Summary!$E$6/100 -> 0 | I17: =[16]Summary!$E$10/100 -> 0 | J17: =[16]Summary!$E$14/100 -> 0 | K17: =[16]Summary!$C$40 -> 4.5373426 | L17: =[16]Summary!$C$54 -> 0 | M17: ='[16]Glbl Expsr'!$D$2 -> 4.5373426 | N17: ='[16]Glbl Expsr'!$D$3 -> 4.5373426 | O17: \\pim-cpt-statpro\SPC_602\Client\Profiles\PIM\Exports\SAAMMAN Derv Calc 6Apr2022.xlsx | P17: SAAMMAN Mandate
A18: SAAMCAU | B18: =[17]Summary!$G$3 -> UT | C18: =[17]Summary!$E$1 -> 3 | D18: =[17]Summary!$C$34 -> 0.0087109861 | E18: =[17]Summary!$E$34/100 -> 0.0087109861 | F18: =[17]Summary!$C$36 -> 0 | G18: =[17]Summary!$C$32 -> 0 | H18: =[17]Summary!$E$6/100 -> 0 | I18: =[17]Summary!$E$10/100 -> 0 | J18: =[17]Summary!$E$14/100 -> 0 | K18: =[17]Summary!$C$40 -> 4.8874986 | L18: =[17]Summary!$C$54 -> 0 | M18: ='[17]Glbl Expsr'!$D$2 -> 4.8874986 | N18: ='[17]Glbl Expsr'!$D$3 -> 4.8874986 | O18: \\pim-cpt-statpro\SPC_602\Client\Profiles\PIM\Exports\SAAMCAU Derv Calc 6Apr2022.xlsx | P18: SAAMCAU Mandate
A19: PABS | B19: =[18]Summary!$G$3 -> UT | C19: =[18]Summary!$E$1 -> 3 | D19: =[18]Summary!$C$34 -> 0.010002733 | E19: =[18]Summary!$E$34/100 -> 0.10720719 | F19: =[18]Summary!$C$36 -> 0.29925094 | G19: =[18]Summary!$C$32 -> 0 | H19: =[18]Summary!$E$6/100 -> 0 | I19: =[18]Summary!$E$10/100 -> 0 | J19: =[18]Summary!$E$14/100 -> 0 | K19: =[18]Summary!$C$40 -> 0.31714404 | L19: =[18]Summary!$C$54 -> 43.613811 | M19: ='[18]Glbl Expsr'!$D$2 -> 0.0092307135 | N19: ='[18]Glbl Expsr'!$D$3 -> 0.0092307135 | O19: \\pim-cpt-statpro\SPC_602\Client\Profiles\PIM\Exports\PABS Derv Calc 6Apr2022.xlsx | P19: PABS Mandate
A20: SAAMMOD | B20: =[19]Summary!$G$3 -> UT | C20: =[19]Summary!$E$1 -> 3 | D20: =[19]Summary!$C$34 -> 0.011947854 | E20: =[19]Summary!$E$34/100 -> 0.011947854 | F20: =[19]Summary!$C$36 -> 0 | G20: =[19]Summary!$C$32 -> 0 | H20: =[19]Summary!$E$6/100 -> 0 | I20: =[19]Summary!$E$10/100 -> 0 | J20: =[19]Summary!$E$14/100 -> 0 | K20: =[19]Summary!$C$40 -> 4.5371611 | L20: =[19]Summary!$C$54 -> 0 | M20: ='[19]Glbl Expsr'!$D$2 -> 4.5371611 | N20: ='[19]Glbl Expsr'!$D$3 -> 4.5371611 | O20: \\pim-cpt-statpro\SPC_602\Client\Profiles\PIM\Exports\SAAMMOD Derv Calc 6Apr2022.xlsx | P20: SAAMMOD Mandate
A21: SMMRRF | B21: =[20]Summary!$G$3 -> UT | C21: =[20]Summary!$E$1 -> 2 | D21: =[20]Summary!$C$34 -> 0.0037491671 | E21: =[20]Summary!$E$34/100 -> 0.0037491671 | F21: =[20]Summary!$C$36 -> 0.0099448086 | G21: =[20]Summary!$C$32 -> 0 | H21: =[20]Summary!$E$6/100 -> 0 | I21: =[20]Summary!$E$10/100 -> 0 | J21: =[20]Summary!$E$14/100 -> 0 | K21: =[20]Summary!$C$40 -> 0.35472694 | L21: =[20]Summary!$C$54 -> 0 | M21: ='[20]Glbl Expsr'!$D$2 -> 0.26707297 | N21: ='[20]Glbl Expsr'!$D$3 -> 0.26707297 | O21: \\pim-cpt-statpro\SPC_602\Client\Profiles\PIM\Exports\SMMRRF Derv Calc 6Apr2022.xlsx | P21: SMMRRF Mandate
A22: HOLDINC | B22: =[21]Summary!$G$3 -> UT | C22: =[21]Summary!$E$1 -> 2 | D22: =[21]Summary!$C$34 -> 0.16480126 | E22: =[21]Summary!$E$34/100 -> 0.16480126 | F22: =[21]Summary!$C$36 -> 0.67706999 | G22: =[21]Summary!$C$32 -> 0 | H22: =[21]Summary!$E$6/100 -> 0.13037834 | I22: =[21]Summary!$E$10/100 -> 0 | J22: =[21]Summary!$E$14/100 -> 0.0020140446 | K22: =[21]Summary!$C$40 -> 0.047540833 | L22: =[21]Summary!$C$54 -> 5.1072566 | M22: ='[21]Glbl Expsr'!$D$2 -> 0.00019583205 | N22: ='[21]Glbl Expsr'!$D$3 -> 0.00019413205 | O22: \\pim-cpt-statpro\SPC_602\Client\Profiles\PIM\Exports\HOLDINC Derv Calc 6Apr2022.xlsx | P22: HOLDINC Mandate
A23: CAPGIP | B23: =[22]Summary!$G$3 -> UT | C23: =[22]Summary!$E$1 -> 2 | D23: =[22]Summary!$C$34 -> 0.1873959 | E23: =[22]Summary!$E$34/100 -> 0.1873959 | F23: =[22]Summary!$C$36 -> 0.45405665 | G23: =[22]Summary!$C$32 -> 0 | H23: =[22]Summary!$E$6/100 -> 0.057555138 | I23: =[22]Summary!$E$10/100 -> 0 | J23: =[22]Summary!$E$14/100 -> 0 | K23: =[22]Summary!$C$40 -> 0.057927489 | L23: =[22]Summary!$C$54 -> 8.4597345 | M23: ='[22]Glbl Expsr'!$D$2 -> 0.00017937063 | N23: ='[22]Glbl Expsr'!$D$3 -> 0.00017781353 | O23: \\pim-cpt-statpro\SPC_602\Client\Profiles\PIM\Exports\CAPGIP Derv Calc 6Apr2022.xlsx | P23: CAPGIP Mandate
A24: MOMBBF | B24: =[23]Summary!$G$3 -> UT | C24: =[23]Summary!$E$1 -> 2 | D24: =[23]Summary!$C$34 -> 0.18812216 | E24: =[23]Summary!$E$34/100 -> 0.18812216 | F24: =[23]Summary!$C$36 -> 0.66968045 | G24: =[23]Summary!$C$32 -> 0 | H24: =[23]Summary!$E$6/100 -> 0.11040074 | I24: =[23]Summary!$E$10/100 -> 0 | J24: =[23]Summary!$E$14/100 -> 0 | K24: =[23]Summary!$C$40 -> 0.056875318 | L24: =[23]Summary!$C$54 -> 5.6319494 | M24: ='[23]Glbl Expsr'!$D$2 -> 0.00023108087 | N24: ='[23]Glbl Expsr'!$D$3 -> 0.00022907488 | O24: \\pim-cpt-statpro\SPC_602\Client\Profiles\PIM\Exports\MOMBBF Derv Calc 6Apr2022.xlsx | P24: MOMBBF Mandate
A25: PPSFLEX | B25: =[24]Summary!$G$3 -> UT | C25: =[24]Summary!$E$1 -> 2 | D25: =[24]Summary!$C$34 -> 0.19016158 | E25: =[24]Summary!$E$34/100 -> 0.19016158 | F25: =[24]Summary!$C$36 -> 0.63298718 | G25: =[24]Summary!$C$32 -> 0 | H25: =[24]Summary!$E$6/100 -> 0.10877986 | I25: =[24]Summary!$E$10/100 -> 0 | J25: =[24]Summary!$E$14/100 -> 0 | K25: =[24]Summary!$C$40 -> 0.057519799 | L25: =[24]Summary!$C$54 -> 7.8233252 | M25: ='[24]Glbl Expsr'!$D$2 -> 0.00028324351 | N25: ='[24]Glbl Expsr'!$D$3 -> 0.0002807847 | O25: \\pim-cpt-statpro\SPC_602\Client\Profiles\PIM\Exports\PPSFLEX Derv Calc 6Apr2022.xlsx | P25: PPSFLEX Mandate
A26: HOLYPF | B26: =[25]Summary!$G$3 -> UT | C26: =[25]Summary!$E$1 -> 2 | D26: =[25]Summary!$C$34 -> 0.22456624 | E26: =[25]Summary!$E$34/100 -> 0.22456624 | F26: =[25]Summary!$C$36 -> 0.77463768 | G26: =[25]Summary!$C$32 -> 0 | H26: =[25]Summary!$E$6/100 -> 0.12072134 | I26: =[25]Summary!$E$10/100 -> 0 | J26: =[25]Summary!$E$14/100 -> 0 | K26: =[25]Summary!$C$40 -> 0.00013893527 | L26: =[25]Summary!$C$54 -> -1.4970156 | M26: ='[25]Glbl Expsr'!$D$2 -> 0.00014015192 | N26: ='[25]Glbl Expsr'!$D$3 -> 0.00013893527 | O26: \\pim-cpt-statpro\SPC_602\Client\Profiles\PIM\Exports\HOLYPF Derv Calc 6Apr2022.xlsx | P26: HOLYPF Mandate
A27: SMMAIF | B27: =[26]Summary!$G$3 -> UT | C27: =[26]Summary!$E$1 -> 2 | D27: =[26]Summary!$C$34 -> 0.22633957 | E27: =[26]Summary!$E$34/100 -> 0.22633957 | F27: =[26]Summary!$C$36 -> 0.57166136 | G27: =[26]Summary!$C$32 -> 0 | H27: =[26]Summary!$E$6/100 -> 0.042692009 | I27: =[26]Summary!$E$10/100 -> 0 | J27: =[26]Summary!$E$14/100 -> 0 | K27: =[26]Summary!$C$40 -> 0.036006721 | L27: =[26]Summary!$C$54 -> 4.7421055 | M27: ='[26]Glbl Expsr'!$D$2 -> 0.0001621699 | N27: ='[26]Glbl Expsr'!$D$3 -> 0.00016076212 | O27: \\pim-cpt-statpro\SPC_602\Client\Profiles\PIM\Exports\SMMAIF Derv Calc 6Apr2022.xlsx | P27: SMMAIF Mandate
A28: GRFINV | B28: =[27]Summary!$G$3 -> UT | C28: =[27]Summary!$E$1 -> 2 | D28: =[27]Summary!$C$34 -> 0.29621998 | E28: =[27]Summary!$E$34/100 -> 0.29621998 | F28: =[27]Summary!$C$36 -> 0.39682893 | G28: =[27]Summary!$C$32 -> 0 | H28: =[27]Summary!$E$6/100 -> 0.046830667 | I28: =[27]Summary!$E$10/100 -> 0 | J28: =[27]Summary!$E$14/100 -> 0 | K28: =[27]Summary!$C$40 -> 0.043889842 | L28: =[27]Summary!$C$54 -> 2.0980708 | M28: ='[27]Glbl Expsr'!$D$2 -> 0.00039647873 | N28: ='[27]Glbl Expsr'!$D$3 -> 0.00039303693 | O28: \\pim-cpt-statpro\SPC_602\Client\Profiles\PIM\Exports\GRFINV Derv Calc 6Apr2022.xlsx | P28: GRFINV Mandate
A29: ASHFLX | B29: =[28]Summary!$G$3 -> UT | C29: =[28]Summary!$E$1 -> 2 | D29: =[28]Summary!$C$34 -> 0.36241963 | E29: =[28]Summary!$E$34/100 -> 0.36241963 | F29: =[28]Summary!$C$36 -> 0.55031471 | G29: =[28]Summary!$C$32 -> 0 | H29: =[28]Summary!$E$6/100 -> 0.1143555 | I29: =[28]Summary!$E$10/100 -> 0 | J29: =[28]Summary!$E$14/100 -> 0 | K29: =[28]Summary!$C$40 -> 0.038489007 | L29: =[28]Summary!$C$54 -> 1.9755032 | M29: ='[28]Glbl Expsr'!$D$2 -> 0.00026332107 | N29: ='[28]Glbl Expsr'!$D$3 -> 0.0002610352 | O29: \\pim-cpt-statpro\SPC_602\Client\Profiles\PIM\Exports\ASHFLX Derv Calc 6Apr2022.xlsx | P29: ASHFLX Mandate
A30: MOMFLX | B30: =[29]Summary!$G$3 -> UT | C30: =[29]Summary!$E$1 -> 0 | D30: =[29]Summary!$C$34 -> 0.002056792 | E30: =[29]Summary!$E$34/100 -> 0.002056792 | F30: =[29]Summary!$C$36 -> 0.99794321 | G30: =[29]Summary!$C$32 -> 0 | H30: =[29]Summary!$E$6/100 -> 0 | I30: =[29]Summary!$E$10/100 -> 0 | J30: =[29]Summary!$E$14/100 -> 0 | K30: =[29]Summary!$C$40 -> 0 | L30: =[29]Summary!$C$54 -> 0 | M30: ='[29]Glbl Expsr'!$D$2 -> 0 | N30: ='[29]Glbl Expsr'!$D$3 -> 0 | O30: \\pim-cpt-statpro\SPC_602\Client\Profiles\PIM\Exports\MOMFLX Derv Calc 6Apr2022.xlsx | P30: MOMFLX Mandate
A31: SMMIBF | B31: =[30]Summary!$G$3 -> UT | C31: =[30]Summary!$E$1 -> 0 | D31: =[30]Summary!$C$34 -> 0.0024365093 | E31: =[30]Summary!$E$34/100 -> 0.0024365093 | F31: =[30]Summary!$C$36 -> 0.99756349 | G31: =[30]Summary!$C$32 -> 0 | H31: =[30]Summary!$E$6/100 -> 0.023064705 | I31: =[30]Summary!$E$10/100 -> 0 | J31: =[30]Summary!$E$14/100 -> 0 | K31: =[30]Summary!$C$40 -> 0 | L31: =[30]Summary!$C$54 -> 0 | M31: ='[30]Glbl Expsr'!$D$2 -> 0 | N31: ='[30]Glbl Expsr'!$D$3 -> 0 | O31: \\pim-cpt-statpro\SPC_602\Client\Profiles\PIM\Exports\SMMIBF Derv Calc 6Apr2022.xlsx | P31: SMMIBF Mandate
A32: PBNDQ | B32: =[31]Summary!$G$3 -> UT | C32: =[31]Summary!$E$1 -> 0 | D32: =[31]Summary!$C$34 -> 0.0030173301 | E32: =[31]Summary!$E$34/100 -> 0.0030173301 | F32: =[31]Summary!$C$36 -> 0.99698267 | G32: =[31]Summary!$C$32 -> 0 | H32: =[31]Summary!$E$6/100 -> 0 | I32: =[31]Summary!$E$10/100 -> 0 | J32: =[31]Summary!$E$14/100 -> 0 | K32: =[31]Summary!$C$40 -> 0 | L32: =[31]Summary!$C$54 -> 0 | M32: ='[31]Glbl Expsr'!$D$2 -> 0 | N32: ='[31]Glbl Expsr'!$D$3 -> 0 | O32: \\pim-cpt-statpro\SPC_602\Client\Profiles\PIM\Exports\PBNDQ Derv Calc 6Apr2022.xlsx | P32: PBNDQ Mandate
A33: OMFLXI5 | B33: =[32]Summary!$G$3 -> UT | C33: =[32]Summary!$E$1 -> 0 | D33: =[32]Summary!$C$34 -> 0.0032614639 | E33: =[32]Summary!$E$34/100 -> 0.0032614639 | F33: =[32]Summary!$C$36 -> 0.99673854 | G33: =[32]Summary!$C$32 -> 0 | H33: =[32]Summary!$E$6/100 -> 0 | I33: =[32]Summary!$E$10/100 -> 0 | J33: =[32]Summary!$E$14/100 -> 0 | K33: =[32]Summary!$C$40 -> 0 | L33: =[32]Summary!$C$54 -> 0 | M33: ='[32]Glbl Expsr'!$D$2 -> 0 | N33: ='[32]Glbl Expsr'!$D$3 -> 0 | O33: \\pim-cpt-statpro\SPC_602\Client\Profiles\PIM\Exports\OMFLXI5 Derv Calc 6Apr2022.xlsx | P33: OMFLXI5 Mandate
A34: SMMBPR | B34: =[33]Summary!$G$3 -> UT | C34: =[33]Summary!$E$1 -> 0 | D34: =[33]Summary!$C$34 -> 0.0035404715 | E34: =[33]Summary!$E$34/100 -> 0.0035404715 | F34: =[33]Summary!$C$36 -> 0.99645953 | G34: =[33]Summary!$C$32 -> 0 | H34: =[33]Summary!$E$6/100 -> 0.0064483781 | I34: =[33]Summary!$E$10/100 -> 0 | J34: =[33]Summary!$E$14/100 -> 0 | K34: =[33]Summary!$C$40 -> 0 | L34: =[33]Summary!$C$54 -> 0 | M34: ='[33]Glbl Expsr'!$D$2 -> 0 | N34: ='[33]Glbl Expsr'!$D$3 -> 0 | O34: \\pim-cpt-statpro\SPC_602\Client\Profiles\PIM\Exports\SMMBPR Derv Calc 6Apr2022.xlsx | P34: SMMBPR Mandate
A35: STSBND | B35: =[34]Summary!$G$3 -> UT | C35: =[34]Summary!$E$1 -> 0 | D35: =[34]Summary!$C$34 -> 0.0037745671 | E35: =[34]Summary!$E$34/100 -> 0.0037745671 | F35: =[34]Summary!$C$36 -> 0.99622543 | G35: =[34]Summary!$C$32 -> 0 | H35: =[34]Summary!$E$6/100 -> 0.01509834 | I35: =[34]Summary!$E$10/100 -> 0 | J35: =[34]Summary!$E$14/100 -> 0 | K35: =[34]Summary!$C$40 -> 0 | L35: =[34]Summary!$C$54 -> 0 | M35: ='[34]Glbl Expsr'!$D$2 -> 0 | N35: ='[34]Glbl Expsr'!$D$3 -> 0 | O35: \\pim-cpt-statpro\SPC_602\Client\Profiles\PIM\Exports\STSBND Derv Calc 6Apr2022.xlsx | P35: STSBND Mandate
A36: ASHGFB | B36: =[35]Summary!$G$3 -> UT | C36: =[35]Summary!$E$1 -> 0 | D36: =[35]Summary!$C$34 -> 0.0042467954 | E36: =[35]Summary!$E$34/100 -> 0.0042467954 | F36: =[35]Summary!$C$36 -> 0.9957532 | G36: =[35]Summary!$C$32 -> 0 | H36: =[35]Summary!$E$6/100 -> 0 | I36: =[35]Summary!$E$10/100 -> 0 | J36: =[35]Summary!$E$14/100 -> 0 | K36: =[35]Summary!$C$40 -> 0 | L36: =[35]Summary!$C$54 -> 0 | M36: ='[35]Glbl Expsr'!$D$2 -> 0 | N36: ='[35]Glbl Expsr'!$D$3 -> 0 | O36: \\pim-cpt-statpro\SPC_602\Client\Profiles\PIM\Exports\ASHGFB Derv Calc 6Apr2022.xlsx | P36: ASHGFB Mandate
A37: ABMMBND | B37: =[36]Summary!$G$3 -> UT | C37: =[36]Summary!$E$1 -> 0 | D37: =[36]Summary!$C$34 -> 0.0056691116 | E37: =[36]Summary!$E$34/100 -> 0.0056691116 | F37: =[36]Summary!$C$36 -> 0.99433089 | G37: =[36]Summary!$C$32 -> 0 | H37: =[36]Summary!$E$6/100 -> 0 | I37: =[36]Summary!$E$10/100 -> 0 | J37: =[36]Summary!$E$14/100 -> 0 | K37: =[36]Summary!$C$40 -> 0 | L37: =[36]Summary!$C$54 -> 0 | M37: ='[36]Glbl Expsr'!$D$2 -> 0 | N37: ='[36]Glbl Expsr'!$D$3 -> 0 | O37: \\pim-cpt-statpro\SPC_602\Client\Profiles\PIM\Exports\ABMMBND Derv Calc 6Apr2022.xlsx | P37: ABMMBND Mandate
A38: PCGEF | B38: =[37]Summary!$G$3 -> UT | C38: =[37]Summary!$E$1 -> 0 | D38: =[37]Summary!$C$34 -> 0.0094445606 | E38: =[37]Summary!$E$34/100 -> 0.0094445606 | F38: =[37]Summary!$C$36 -> 0 | G38: =[37]Summary!$C$32 -> 0 | H38: =[37]Summary!$E$6/100 -> 0 | I38: =[37]Summary!$E$10/100 -> 0 | J38: =[37]Summary!$E$14/100 -> 0 | K38: =[37]Summary!$C$40 -> 0.99055544 | L38: =[37]Summary!$C$54 -> 99.055544 | M38: ='[37]Glbl Expsr'!$D$2 -> 0 | N38: ='[37]Glbl Expsr'!$D$3 -> 0 | O38: \\pim-cpt-statpro\SPC_602\Client\Profiles\PIM\Exports\PCGEF Derv Calc 6Apr2022.xlsx | P38: PCGEF Mandate
A39: PGGF | B39: =[38]Summary!$G$3 -> UT | C39: =[38]Summary!$E$1 -> 0 | D39: =[38]Summary!$C$34 -> 0.010070441 | E39: =[38]Summary!$E$34/100 -> 0.010070441 | F39: =[38]Summary!$C$36 -> 0 | G39: =[38]Summary!$C$32 -> 0 | H39: =[38]Summary!$E$6/100 -> 0 | I39: =[38]Summary!$E$10/100 -> 0 | J39: =[38]Summary!$E$14/100 -> 0 | K39: =[38]Summary!$C$40 -> 0.98992956 | L39: =[38]Summary!$C$54 -> 98.992956 | M39: ='[38]Glbl Expsr'!$D$2 -> 0 | N39: ='[38]Glbl Expsr'!$D$3 -> 0 | O39: \\pim-cpt-statpro\SPC_602\Client\Profiles\PIM\Exports\PGGF Derv Calc 6Apr2022.xlsx | P39: PGGF Mandate
A40: IJGCOR | B40: =[39]Summary!$G$3 -> UT | C40: =[39]Summary!$E$1 -> 0 | D40: =[39]Summary!$C$34 -> 0.035793677 | E40: =[39]Summary!$E$34/100 -> 0.035793677 | F40: =[39]Summary!$C$36 -> 0 | G40: =[39]Summary!$C$32 -> 0 | H40: =[39]Summary!$E$6/100 -> 0 | I40: =[39]Summary!$E$10/100 -> 0 | J40: =[39]Summary!$E$14/100 -> 0 | K40: =[39]Summary!$C$40 -> 0 | L40: =[39]Summary!$C$54 -> 96.420632 | M40: ='[39]Glbl Expsr'!$D$2 -> 0 | N40: ='[39]Glbl Expsr'!$D$3 -> 0 | O40: \\pim-cpt-statpro\SPC_602\Client\Profiles\PIM\Exports\IJGCOR Derv Calc 6Apr2022.xlsx | P40: IJGCOR Mandate
...

Sheet k
A1: =HYPERLINK("https://pimportalprod2015.eagleaccess.com/Default.aspx","Derivative Cover "&TEXT(H!$AJ$2,"dddd d mmmm yyyy")&" from Eagle") -> Derivative Cover Friday 22 April 2022 from Eagle | C1: Entity Name | D1: HoldingsStartRow | E1: DeltasStartRow
A2: Process: | C2: 27four Life - Pos Ret | D2: =MATCH(C2,H!A:A,0) -> 2 | E2: =MATCH(C2,D!A:A,0) -> 2
A3: =HYPERLINK("https://pimportalprod2015.eagleaccess.com/Reports/Reports.aspx","1) Get holdings from Eagle") -> 1) Get holdings from Eagle | C3: 27four Life - Pos Ret Med | D3: =MATCH(C3,H!A:A,0) -> 49 | E3: =MATCH(C3,D!A:A,0) -> 14
A4: i) Get the funds' derivative deltas from Eagle | C4: Absa MM Abs Ret Prud Fund | D4: =MATCH(C4,H!A:A,0) -> 100 | E4: =MATCH(C4,D!A:A,0) -> 20
A5: a) Queries -> Portfolios -> Derivative Exposure -> Edit Criteria | C5: ABSA MM Bond Fund | D5: =MATCH(C5,H!A:A,0) -> 148 | E5: =MATCH(C5,D!A:A,0) -> 32
A6: b) Locate "Entity ID", click on down arrow and select "Favorite" | C6: ABSA MULTI MAN EQ FUND PRESC | D6: =MATCH(C6,H!A:A,0) -> 158 | E6: =MATCH(C6,D!A:A,0) -> 33
A7: c) click on ellipses (…) and then on Entity ID to select all favourites | C7: AFIL - Life Bond Fund | D7: =MATCH(C7,H!A:A,0) -> 240 | E7: =MATCH(C7,D!A:A,0) -> 34
A8: d) Enter prior working day's date in the calendar at bottom left of the screen | C8: AFIL - Pensioner | D8: =MATCH(C8,H!A:A,0) -> 246 | E8: =MATCH(C8,D!A:A,0) -> 35
A9: e) Submit | C9: Custodian BCI Income Plus Fund | D9: =MATCH(C9,H!A:A,0) -> 292 | E9: =MATCH(C9,D!A:A,0) -> 47
A10: f) Hover over "Export" and then left click on "XLS Analysis Mode" | C10: ECIC Composite | D10: =MATCH(C10,H!A:A,0) -> 382 | E10: =MATCH(C10,D!A:A,0) -> 48
A11: g) When it's done downloading, click on "Download Complete" | C11: Electric Cont Indust Pens Fund | D11: =MATCH(C11,H!A:A,0) -> 484 | E11: =MATCH(C11,D!A:A,0) -> 49
A12: h) Copy columns "A" through "G" from the "Derivative Exposure.xls" sheet | C12: EMBF - Positive Return Fund | D12: =MATCH(C12,H!A:A,0) -> 563 | E12: =MATCH(C12,D!A:A,0) -> 51
A13: i) Paste into cell "A1" of sheet "D" in this file | C13: FRB ITF GTC Wealth Preserver2 | D13: =MATCH(C13,H!A:A,0) -> 614 | E13: =MATCH(C13,D!A:A,0) -> 57
A14: ii) Get the funds' holdings from Eagle | C14: FRB ITF Hollard Prime Income | D14: =MATCH(C14,H!A:A,0) -> 649 | E14: =MATCH(C14,D!A:A,0) -> 69
A15: a) Queries -> Portfolios -> Portfolio Analytics Report - New -> Edit Criteria | C15: FRB ITF Hollard Prime Yld Pls | D15: =MATCH(C15,H!A:A,0) -> 736 | E15: =MATCH(C15,D!A:A,0) -> 70
... A24: 2) | C24: IJG Income Provider Fund | D24: =MATCH(C24,H!A:A,0) -> 1072 | E24: =MATCH(C24,D!A:A,0) -> 111
A25: =HYPERLINK("\\pim-cpt-statpro\SPC_602\Client\Profiles\PIM\Exports","3) Get the results in the derivative check folder") -> 3) Get the results in the derivative check folder | C25: Liberty Group Ltd - TAA | D25: =MATCH(C25,H!A:A,0) -> 1190 | E25: =MATCH(C25,D!A:A,0) -> 113
C26: Medipos Medical Scheme Income | D26: =MATCH(C26,H!A:A,0) -> 1210 | E26: =MATCH(C26,D!A:A,0) -> 119
C27: Mineworkers Prov Fund | D27: =MATCH(C27,H!A:A,0) -> 1247 | E27: =MATCH(C27,D!A:A,0) -> 120
C28: Momentum Group Ltd - Pos Ret | D28: =MATCH(C28,H!A:A,0) -> 1267 | E28: =MATCH(C28,D!A:A,0) -> 121
C29: Nestle Provident Fund - PIM | D29: =MATCH(C29,H!A:A,0) -> 1311 | E29: =MATCH(C29,D!A:A,0) -> 133
C30: NFMW - Equity Fund | D30: =MATCH(C30,H!A:A,0) -> 1392 | E30: =MATCH(C30,D!A:A,0) -> 135
C31: OMMM Income Fund No5 - PIM | D31: =MATCH(C31,H!A:A,0) -> 1469 | E31: =MATCH(C31,D!A:A,0) -> 137
C32: Picbel Groepvoorsorgfonds | D32: =MATCH(C32,H!A:A,0) -> 1484 | E32: =MATCH(C32,D!A:A,0) -> 138
C33: PIM Absolute Balanced | D33: =MATCH(C33,H!A:A,0) -> 1487 | E33: =MATCH(C33,D!A:A,0) -> 139
C34: PIM Balanced | D34: =MATCH(C34,H!A:A,0) -> 1528 | E34: =MATCH(C34,D!A:A,0) -> 144
C35: PIM Core All Share Equity | D35: =MATCH(C35,H!A:A,0) -> 1577 | E35: =MATCH(C35,D!A:A,0) -> 152
C36: PIM Core Capped Equity | D36: =MATCH(C36,H!A:A,0) -> 1677 | E36: =MATCH(C36,D!A:A,0) -> 153
C37: PIM Core Equity | D37: =MATCH(C37,H!A:A,0) -> 1779 | E37: =MATCH(C37,D!A:A,0) -> 155
... C77: Tshwane Municipal Prov Fund | D77: =MATCH(C77,H!A:A,0) -> 3869 | E77: =MATCH(C77,D!A:A,0) -> 259
D78: 3724 | E78: 361

Sheet Static
A1: 44181 | B1: Day of Reconciliation | D1: Back to links
A2: 44190 | B2: Christmas Day
A3: 44191 | B3: Boxing Day
A4: 44197 | B4: New Year's Day
A5: 44277 | B5: Human Rights Day
A6: 44288 | B6: Good Friday
A7: 44291 | B7: Family Day
A8: 44313 | B8: Freedom Day
A9: 44317 | B9: International Workers' Day
A10: 44363 | B10: Youth Day (in South Africa)
A11: 44417 | B11: National Women's Day
A12: 44463 | B12: Heritage Day
A13: 44501 | B13: Election Day
... A29: 44921 | B29: Day of Goodwill

Sheet Summary
A1: =Data!$A$2&" ("&Data!$AK$2&")" -> Tshwane Municipal Prov Fund (TSHMPF) | B1: Current Exposure | C1: Market Value | E1: =COUNTIF(Data!$B:$B,"Derivatives")+COUNTIF(Data!$B:$B,"Forwards")+COUNTIF(Data!$B:$B,"Swaps") -> 8 | F1: ="derivative"&IF(E1=1,"","s") -> derivatives | G1: =HYPERLINK("J:\PProfile Operations\Legal\Legal and Compliance Framework\Hilton\Client Mandates\"&SUBSTITUTE(Data!$AK$2,"_C","")&" Rules.docx","Mandate") -> Mandate | H1: {="SA equity indices ("&SUMPRODUCT((Data!$C:$C="Equity Derivatives")*(Data!$W:$W="ZAR"))&")"} -> SA equity indices (2) | I1: {=IF(ISNA(MATCH(1,("Equity derivatives"=Data!C:C)*("ZAR"=Data!W:W),0)),"",INDEX(Data!D:D,MATCH(1,("Equity derivatives"=Data!C:C)*("ZAR"=Data!W:W),0)))} -> 15JUN22 DCAP | J1: {=IF(COUNTA($I$1:I$1)<COUNTIFS(Data!$C:$C,"Equity derivatives",Data!$W:$W,"ZAR"),INDEX(Data!$D:$D,MATCH(I$1,Data!$D:$D,0)+1),"")} -> 15JUN22 DCAR | K1: {=IF(COUNTA($I$1:J$1)<COUNTIFS(Data!$C:$C,"Equity derivatives",Data!$W:$W,"ZAR"),INDEX(Data!$D:$D,MATCH(J$1,Data!$D:$D,0)+1),"")} | L1: {=IF(COUNTA($I$1:K$1)<COUNTIFS(Data!$C:$C,"Equity derivatives",Data!$W:$W,"ZAR"),INDEX(Data!$D:$D,MATCH(K$1,Data!$D:$D,0)+1),"")} | M1: {=IF(COUNTA($I$1:L$1)<COUNTIFS(Data!$C:$C,"Equity derivatives",Data!$W:$W,"ZAR"),INDEX(Data!$D:$D,MATCH(L$1,Data!$D:$D,0)+1),"")} | N1: {=IF(COUNTA($I$1:M$1)<COUNTIFS(Data!$C:$C,"Equity derivatives",Data!$W:$W,"ZAR"),INDEX(Data!$D:$D,MATCH(M$1,Data!$D:$D,0)+1),"")} | O1: {=IF(COUNTA($I$1:N$1)<COUNTIFS(Data!$C:$C,"Equity derivatives",Data!$W:$W,"ZAR"),INDEX(Data!$D:$D,MATCH(N$1,Data!$D:$D,0)+1),"")} | P1: {=IF(COUNTA($I$1:O$1)<COUNTIFS(Data!$C:$C,"Equity derivatives",Data!$W:$W,"ZAR"),INDEX(Data!$D:$D,MATCH(O$1,Data!$D:$D,0)+1),"")} | Q1: {=IF(COUNTA($I$1:P$1)<COUNTIFS(Data!$C:$C,"Equity derivatives",Data!$W:$W,"ZAR"),INDEX(Data!$D:$D,MATCH(P$1,Data!$D:$D,0)+1),"")} | ... BH1: {=IF(COUNTA($I$1:BG$1)<COUNTIFS(Data!$C:$C,"Equity derivatives",Data!$W:$W,"ZAR"),INDEX(Data!$D:$D,MATCH(BG$1,Data!$D:$D,0)+1),"")}
A2: =HYPERLINK("https://pimportalprod2015.eagleaccess.com/Default.aspx","Derivative Cover "&TEXT(Data!$AJ$2,"dddd d mmmm yyyy")) -> Derivative Cover Wednesday 6 April 2022 | B2: R | C2: % | F2: ASSET COVER CHECK | G2: {=CELL("filename")} -> \\pim-cpt-fs\profile$\PProfile Operations\Legal\Legal and Compliance Framework\Hilton\W\[Derv.xlsm]k | H2: =IF(ISNA(SUM(I2:BH2)),0,SUM(I2:BH2)) -> 0.13466471 | I2: =IF(I$1="","",INDEX(Data!$AH:$AH,MATCH(I$1,Data!$D:$D,0))/$B$4) -> 0.074538129 | J2: =IF(J$1="","",INDEX(Data!$AH:$AH,MATCH(J$1,Data!$D:$D,0))/$B$4) -> 0.060126578 | K2: =IF(K$1="","",INDEX(Data!$AH:$AH,MATCH(K$1,Data!$D:$D,0))/$B$4) | L2: =IF(L$1="","",INDEX(Data!$AH:$AH,MATCH(L$1,Data!$D:$D,0))/$B$4) | M2: =IF(M$1="","",INDEX(Data!$AH:$AH,MATCH(M$1,Data!$D:$D,0))/$B$4) | N2: =IF(N$1="","",INDEX(Data!$AH:$AH,MATCH(N$1,Data!$D:$D,0))/$B$4) | O2: =IF(O$1="","",INDEX(Data!$AH:$AH,MATCH(O$1,Data!$D:$D,0))/$B$4) | P2: =IF(P$1="","",INDEX(Data!$AH:$AH,MATCH(P$1,Data!$D:$D,0))/$B$4) | ... BH2: =IF(BH$1="","",INDEX(Data!$AH:$AH,MATCH(BH$1,Data!$D:$D,0))/$B$4)
A3: UT | E3: 0 | F3: Total direct SA bonds available to cover short exposures | G3: =_xlfn.XLOOKUP(Data!AK$2,[77]Funds!$A:$A,[77]Funds!$E:$E) -> ≠ UT
A4: Fund NAV | B4: =SUM(Data!$L:$L) -> 1.7548146e+08 | C4: =SUM(Data!$N:$N)/100 -> 1 | E4: =IF(ISNA(MATCH($G4,Data!$E:$E,0)),0,_xlfn.XLOOKUP($G4,Data!$E:$E,Data!$AI:$AI))+IF(ISNA(MATCH(186,Data!$E:$E,0)),0,_xlfn.XLOOKUP(186,Data!$E:$E,Data!$AI:$AI)) -> 0 | F4: Total same or similar bonds available to cover short exposures | G4: R186 | H4: {="World equity indices ("&SUMPRODUCT((Data!$C:$C="Equity Derivatives")*(Data!$W:$W<>"ZAR"))&")"} -> World equity indices (0) | I4: {=IF(ISNA(MATCH(1,("Equity derivatives"=Data!C:C)*("ZAR"<>Data!W:W),0)),"",INDEX(Data!D:D,MATCH(1,("Equity derivatives"=Data!C:C)*("ZAR"<>Data!W:W),0)))} | J4: {=IF(COUNTA($I$4:I$4)<COUNTIFS(Data!$C:$C,"Equity derivatives",Data!$W:$W,"<>ZAR"),INDEX(Data!$D:$D,MATCH(I$4,Data!$D:$D,0)+1),"")} | K4: {=IF(COUNTA($I$4:J$4)<COUNTIFS(Data!$C:$C,"Equity derivatives",Data!$W:$W,"<>ZAR"),INDEX(Data!$D:$D,MATCH(J$4,Data!$D:$D,0)+1),"")} | L4: {=IF(COUNTA($I$4:K$4)<COUNTIFS(Data!$C:$C,"Equity derivatives",Data!$W:$W,"<>ZAR"),INDEX(Data!$D:$D,MATCH(K$4,Data!$D:$D,0)+1),"")} | M4: {=IF(COUNTA($I$4:L$4)<COUNTIFS(Data!$C:$C,"Equity derivatives",Data!$W:$W,"<>ZAR"),INDEX(Data!$D:$D,MATCH(L$4,Data!$D:$D,0)+1),"")} | N4: {=IF(COUNTA($I$4:M$4)<COUNTIFS(Data!$C:$C,"Equity derivatives",Data!$W:$W,"<>ZAR"),INDEX(Data!$D:$D,MATCH(M$4,Data!$D:$D,0)+1),"")} | O4: {=IF(COUNTA($I$4:N$4)<COUNTIFS(Data!$C:$C,"Equity derivatives",Data!$W:$W,"<>ZAR"),INDEX(Data!$D:$D,MATCH(N$4,Data!$D:$D,0)+1),"")} | P4: {=IF(COUNTA($I$4:O$4)<COUNTIFS(Data!$C:$C,"Equity derivatives",Data!$W:$W,"<>ZAR"),INDEX(Data!$D:$D,MATCH(O$4,Data!$D:$D,0)+1),"")} | Q4: {=IF(COUNTA($I$4:P$4)<COUNTIFS(Data!$C:$C,"Equity derivatives",Data!$W:$W,"<>ZAR"),INDEX(Data!$D:$D,MATCH(P$4,Data!$D:$D,0)+1),"")} | ... BH4: {=IF(COUNTA($I$4:BG$4)<COUNTIFS(Data!$C:$C,"Equity derivatives",Data!$W:$W,"<>ZAR"),INDEX(Data!$D:$D,MATCH(BG$4,Data!$D:$D,0)+1),"")}
E5: =MIN(0,$H$8*100) -> 0 | F5: Net short derivative exposure | H5: =IF(ISNA(SUM(I5:BH5)),0,SUM(I5:BH5)) -> 0 | I5: =IF(I$4="","",INDEX(Data!$AH:$AH,MATCH(I$4,Data!$D:$D,0))/$B$4) | J5: =IF(J$4="","",INDEX(Data!$AH:$AH,MATCH(J$4,Data!$D:$D,0))/$B$4) | K5: =IF(K$4="","",INDEX(Data!$AH:$AH,MATCH(K$4,Data!$D:$D,0))/$B$4) | L5: =IF(L$4="","",INDEX(Data!$AH:$AH,MATCH(L$4,Data!$D:$D,0))/$B$4) | M5: =IF(M$4="","",INDEX(Data!$AH:$AH,MATCH(M$4,Data!$D:$D,0))/$B$4) | N5: =IF(N$4="","",INDEX(Data!$AH:$AH,MATCH(N$4,Data!$D:$D,0))/$B$4) | O5: =IF(O$4="","",INDEX(Data!$AH:$AH,MATCH(O$4,Data!$D:$D,0))/$B$4) | P5: =IF(P$4="","",INDEX(Data!$AH:$AH,MATCH(P$4,Data!$D:$D,0))/$B$4) | ... BH5: =IF(BH$4="","",INDEX(Data!$AH:$AH,MATCH(BH$4,Data!$D:$D,0))/$B$4)
A6: Assets in liquid form | B6: =SUM(B7:B11) -> 31237968 | C6: =SUM(C7:C11) -> 0.17801292 | E6: =SUM(E3:E5) -> 0 | F6: =IF($E6>=0,"Adequate","INADEQUATE")&" short SA bond bond derivative cover [BN90 16(1)(a) & (b)]" -> Adequate short SA bond bond derivative cover [BN90 16(1)(a) & (b)]
