Workbook
Name Hols: Static!$A$1:$A$29

Sheet S
A1: Entity ID | B1: UT? | C1: # | D1: Cash Cover | E1: Cash Cover 2 | F1: Incl CLNs & longer dated debt | G1: Incl underlying UTs | H1: SA Bond Cover | I1: MSCI Cover | J1: ALSI Cover | K1: Total Equity | L1: Total Foreign | M1: Global Exposure | N1: Net Effective Exposure | O1: ="Derivative Calculations "&TEXT(Data!$AJ$2,"ddd d mmm yyyy") -> Derivative Calculations Sat 0 Jan 1900 | P1: Mandate
A2: PPSBAL_C | B2: =[1]Summary!$G$3 -> UT | C2: =[1]Summary!$E$1 -> 10 | D2: =[1]Summary!$C$34 -> 0.23653506 | E2: =[1]Summary!$E$34/100 -> 0.23653506 | F2: =[1]Summary!$C$36 -> 0.18917393 | G2: =[1]Summary!$C$32 -> 0 | H2: =[1]Summary!$E$6/100 -> 0.021755043 | I2: =[1]Summary!$E$10/100 -> 0.019637699 | J2: =[1]Summary!$E$14/100 -> 0.19157251 | K2: =[1]Summary!$C$40 -> 0.59271599 | L2: =[1]Summary!$C$54 -> 20.109194 | M2: ='[1]Glbl Expsr'!$D$2 -> 0.095371567 | N2: ='[1]Glbl Expsr'!$D$3 -> 0.095371567 | O2: \\pim-cpt-statpro\SPC_602\Client\Profiles\PIM\Exports\PPSBAL_C Derv Calc 6Apr2022.xlsx | P2: PPSBAL_C Mandate
A3: PCAEF | B3: =[2]Summary!$G$3 -> UT | C3: =[2]Summary!$E$1 -> 10 | D3: =[2]Summary!$C$34 -> 0.50252909 | E3: =[2]Summary!$E$34/100 -> 0.50252909 | F3: =[2]Summary!$C$36 -> 0 | G3: =[2]Summary!$C$32 -> 0 | H3: =[2]Summary!$E$6/100 -> 0 | I3: =[2]Summary!$E$10/100 -> 0.017757483 | J3: =[2]Summary!$E$14/100 -> 0.12463345 | K3: =[2]Summary!$C$40 -> 0.99223767 | L3: =[2]Summary!$C$54 -> 0 | M3: ='[2]Glbl Expsr'!$D$2 -> 0.066275317 | N3: ='[2]Glbl Expsr'!$D$3 -> 0.066275317 | O3: \\pim-cpt-statpro\SPC_602\Client\Profiles\PIM\Exports\PCAEF Derv Calc 6Apr2022.xlsx | P3: PCAEF Mandate
A4: ADRRC | B4: =[3]Summary!$G$3 -> UT | C4: =[3]Summary!$E$1 -> 9 | D4: =[3]Summary!$C$34 -> 0.01560478 | E4: =[3]Summary!$E$34/100 -> 0.01560478 | F4: =[3]Summary!$C$36 -> 0.19828813 | G4: =[3]Summary!$C$32 -> 0 | H4: =[3]Summary!$E$6/100 -> 0 | I4: =[3]Summary!$E$10/100 -> 0 | J4: =[3]Summary!$E$14/100 -> 0 | K4: =[3]Summary!$C$40 -> 0.40730673 | L4: =[3]Summary!$C$54 -> 0 | M4: ='[3]Glbl Expsr'!$D$2 -> 0.94737804 | N4: ='[3]Glbl Expsr'!$D$3 -> 0.21091173 | O4: \\pim-cpt-statpro\SPC_602\Client\Profiles\PIM\Exports\ADRRC Derv Calc 6Apr2022.xlsx | P4: ADRRC Mandate
A5: PPOS | B5: =[4]Summary!$G$3 -> UT | C5: =[4]Summary!$E$1 -> 9 | D5: =[4]Summary!$C$34 -> 0.029279105 | E5: =[4]Summary!$E$34/100 -> 0.029279105 | F5: =[4]Summary!$C$36 -> 0.20279073 | G5: =[4]Summary!$C$32 -> 0 | H5: =[4]Summary!$E$6/100 -> 0 | I5: =[4]Summary!$E$10/100 -> 0 | J5: =[4]Summary!$E$14/100 -> 0 | K5: =[4]Summary!$C$40 -> 0.42110671 | L5: =[4]Summary!$C$54 -> 0 | M5: ='[4]Glbl Expsr'!$D$2 -> 1.0335819 | N5: ='[4]Glbl Expsr'!$D$3 -> 0.21834449 | O5: \\pim-cpt-statpro\SPC_602\Client\Profiles\PIM\Exports\PPOS Derv Calc 6Apr2022.xlsx | P5: PPOS Mandate
A6: ABMMABR | B6: =[5]Summary!$G$3 -> UT | C6: =[5]Summary!$E$1 -> 9 | D6: =[5]Summary!$C$34 -> 0.032542983 | E6: =[5]Summary!$E$34/100 -> 0.032542983 | F6: =[5]Summary!$C$36 -> 0.16070469 | G6: =[5]Summary!$C$32 -> 0 | H6: =[5]Summary!$E$6/100 -> 0 | I6: =[5]Summary!$E$10/100 -> 0 | J6: =[5]Summary!$E$14/100 -> 0 | K6: =[5]Summary!$C$40 -> 0.35493861 | L6: =[5]Summary!$C$54 -> 19.462523 | M6: ='[5]Glbl Expsr'!$D$2 -> 0.84041325 | N6: ='[5]Glbl Expsr'!$D$3 -> 0.18768625 | O6: \\pim-cpt-statpro\SPC_602\Client\Profiles\PIM\Exports\ABMMABR Derv Calc 6Apr2022.xlsx | P6: ABMMABR Mandate
A7: GTCWP2 | B7: =[6]Summary!$G$3 -> UT | C7: =[6]Summary!$E$1 -> 9 | D7: =[6]Summary!$C$34 -> 0.058168227 | E7: =[6]Summary!$E$34/100 -> 0.058168227 | F7: =[6]Summary!$C$36 -> 0 | G7: =[6]Summary!$C$32 -> 0 | H7: =[6]Summary!$E$6/100 -> 0 | I7: =[6]Summary!$E$10/100 -> 0 | J7: =[6]Summary!$E$14/100 -> 0 | K7: =[6]Summary!$C$40 -> 0.6895952 | L7: =[6]Summary!$C$54 -> 0 | M7: ='[6]Glbl Expsr'!$D$2 -> 1.7138448 | N7: ='[6]Glbl Expsr'!$D$3 -> 0.50317318 | O7: \\pim-cpt-statpro\SPC_602\Client\Profiles\PIM\Exports\GTCWP2 Derv Calc 6Apr2022.xlsx | P7: GTCWP2 Mandate
A8: IJGBAL | B8: =[7]Summary!$G$3 -> UT | C8: =[7]Summary!$E$1 -> 7 | D8: =[7]Summary!$C$34 -> 0.3194741 | E8: =[7]Summary!$E$34/100 -> 0.3194741 | F8: =[7]Summary!$C$36 | G8: =[7]Summary!$C$32 -> 0.19963364 | H8: =[7]Summary!$E$6/100 -> 0 | I8: =[7]Summary!$E$10/100 -> 0 | J8: =[7]Summary!$E$14/100 -> 0 | K8: =[7]Summary!$C$40 -> 2.9931069 | L8: =[7]Summary!$C$54 -> 17.269108 | M8: ='[7]Glbl Expsr'!$D$2 -> 2.81539 | N8: ='[7]Glbl Expsr'!$D$3 -> 2.81539 | O8: \\pim-cpt-statpro\SPC_602\Client\Profiles\PIM\Exports\IJGBAL Derv Calc 6Apr2022.xlsx | P8: IJGBAL Mandate
A9: PCCEF | B9: =[8]Summary!$G$3 -> UT | C9: =[8]Summary!$E$1 -> 7 | D9: =[8]Summary!$C$34 -> 0.25044271 | E9: =[8]Summary!$E$34/100 -> 0.25044271 | F9: =[8]Summary!$C$36 -> 0 | G9: =[8]Summary!$C$32 -> 0 | H9: =[8]Summary!$E$6/100 -> 0 | I9: =[8]Summary!$E$10/100 -> 0.033255527 | J9: =[8]Summary!$E$14/100 -> 0.17587447 | K9: =[8]Summary!$C$40 -> 0.99069313 | L9: =[8]Summary!$C$54 -> 0 | M9: ='[8]Glbl Expsr'!$D$2 -> 0.23999995 | N9: ='[8]Glbl Expsr'!$D$3 -> 0.23999995 | O9: \\pim-cpt-statpro\SPC_602\Client\Profiles\PIM\Exports\PCCEF Derv Calc 6Apr2022.xlsx | P9: PCCEF Mandate
A10: PCEQTF | B10: =[9]Summary!$G$3 -> UT | C10: =[9]Summary!$E$1 -> 7 | D10: =[9]Summary!$C$34 -> 0.34681845 | E10: =[9]Summary!$E$34/100 -> 0.34681845 | F10: =[9]Summary!$C$36 -> 0 | G10: =[9]Summary!$C$32 -> 0 | H10: =[9]Summary!$E$6/100 -> 0 | I10: =[9]Summary!$E$10/100 -> 0.019768545 | J10: =[9]Summary!$E$14/100 -> 0.14712865 | K10: =[9]Summary!$C$40 -> 0.93018558 | L10: =[9]Summary!$C$54 -> 0 | M10: ='[9]Glbl Expsr'!$D$2 -> 0.088422855 | N10: ='[9]Glbl Expsr'!$D$3 -> 0.088422855 | O10: \\pim-cpt-statpro\SPC_602\Client\Profiles\PIM\Exports\PCEQTF Derv Calc 6Apr2022.xlsx | P10: PCEQTF Mandate
A11: PIMBAL | B11: =[10]Summary!$G$3 -> UT | C11: =[10]Summary!$E$1 -> 6 | D11: =[10]Summary!$C$34 -> 0.0071720338 | E11: =[10]Summary!$E$34/100 -> 0.037108757 | F11: =[10]Summary!$C$36 -> 0.12636503 | G11: =[10]Summary!$C$32 -> 0 | H11: =[10]Summary!$E$6/100 -> 0 | I11: =[10]Summary!$E$10/100 -> 0 | J11: =[10]Summary!$E$14/100 -> 0 | K11: =[10]Summary!$C$40 -> 0.64844859 | L11: =[10]Summary!$C$54 -> 43.825415 | M11: ='[10]Glbl Expsr'!$D$2 -> 0.028740154 | N11: ='[10]Glbl Expsr'!$D$3 -> 0.028740154 | O11: \\pim-cpt-statpro\SPC_602\Client\Profiles\PIM\Exports\PIMBAL Derv Calc 6Apr2022.xlsx | P11: PIMBAL Mandate
A12: PEAQ | B12: =[11]Summary!$G$3 -> UT | C12: =[11]Summary!$E$1 -> 5 | D12: =[11]Summary!$C$34 -> 0.47815719 | E12: =[11]Summary!$E$34/100 -> 0.47815719 | F12: =[11]Summary!$C$36 -> 0 | G12: =[11]Summary!$C$32 -> 0 | H12: =[11]Summary!$E$6/100 -> 0 | I12: =[11]Summary!$E$10/100 -> 0.042280309 | J12: =[11]Summary!$E$14/100 -> 0.21361833 | K12: =[11]Summary!$C$40 -> 0.98260704 | L12: =[11]Summary!$C$54 -> 0 | M12: ='[11]Glbl Expsr'!$D$2 -> 0.29444411 | N12: ='[11]Glbl Expsr'!$D$3 -> 0.29444411 | O12: \\pim-cpt-statpro\SPC_602\Client\Profiles\PIM\Exports\PEAQ Derv Calc 6Apr2022.xlsx | P12: PEAQ Mandate
A13: PBAL | B13: =[12]Summary!$G$3 -> UT | C13: =[12]Summary!$E$1 -> 4 | D13: =[12]Summary!$C$34 -> 0.0077845601 | E13: =[12]Summary!$E$34/100 -> 0.052814815 | F13: =[12]Summary!$C$36 -> 0.1589352 | G13: =[12]Summary!$C$32 -> 0 | H13: =[12]Summary!$E$6/100 -> 0 | I13: =[12]Summary!$E$10/100 -> 0 | J13: =[12]Summary!$E$14/100 -> 0 | K13: =[12]Summary!$C$40 -> 0.66108884 | L13: =[12]Summary!$C$54 -> 44.692991 | M13: ='[12]Glbl Expsr'!$D$2 -> 0.02812015 | N13: ='[12]Glbl Expsr'!$D$3 -> 0.02812015 | O13: \\pim-cpt-statpro\SPC_602\Client\Profiles\PIM\Exports\PBAL Derv Calc 6Apr2022.xlsx | P13: PBAL Mandate
A14: PPEF | B14: =[13]Summary!$G$3 -> UT | C14: =[13]Summary!$E$1 -> 4 | D14: =[13]Summary!$C$34 -> 0.12496283 | E14: =[13]Summary!$E$34/100 -> 0.12496283 | F14: =[13]Summary!$C$36 -> 0 | G14: =[13]Summary!$C$32 -> 0 | H14: =[13]Summary!$E$6/100 -> 0 | I14: =[13]Summary!$E$10/100 -> 0.017163907 | J14: =[13]Summary!$E$14/100 -> 0.38376815 | K14: =[13]Summary!$C$40 -> 0.99371009 | L14: =[13]Summary!$C$54 -> 0 | M14: ='[13]Glbl Expsr'!$D$2 -> 0.30927369 | N14: ='[13]Glbl Expsr'!$D$3 -> 0.30927369 | O14: \\pim-cpt-statpro\SPC_602\Client\Profiles\PIM\Exports\PPEF Derv Calc 6Apr2022.xlsx | P14: PPEF Mandate
A15: ABMMEQU | B15: =[14]Summary!$G$3 -> UT | C15: =[14]Summary!$E$1 -> 4 | D15: =[14]Summary!$C$34 -> 0.36844942 | E15: =[14]Summary!$E$34/100 -> 0.36844942 | F15: =[14]Summary!$C$36 -> 0 | G15: =[14]Summary!$C$32 -> 0 | H15: =[14]Summary!$E$6/100 -> 0 | I15: =[14]Summary!$E$10/100 -> 0.014180764 | J15: =[14]Summary!$E$14/100 -> 0.11705303 | K15: =[14]Summary!$C$40 -> 0.99281602 | L15: =[14]Summary!$C$54 -> 0 | M15: ='[14]Glbl Expsr'!$D$2 -> 0.12444838 | N15: ='[14]Glbl Expsr'!$D$3 -> 0.12444838 | O15: \\pim-cpt-statpro\SPC_602\Client\Profiles\PIM\Exports\ABMMEQU Derv Calc 6Apr2022.xlsx | P15: ABMMEQU Mandate
A16: PEQ | B16: =[15]Summary!$G$3 -> UT | C16: =[15]Summary!$E$1 -> 4 | D16: =[15]Summary!$C$34 -> 0.46363122 | E16: =[15]Summary!$E$34/100 -> 0.46363122 | F16: =[15]Summary!$C$36 -> 0 | G16: =[15]Summary!$C$32 -> 0 | H16: =[15]Summary!$E$6/100 -> 0 | I16: =[15]Summary!$E$10/100 -> 0 | J16: =[15]Summary!$E$14/100 -> 0 | K16: =[15]Summary!$C$40 -> 0.99423061 | L16: =[15]Summary!$C$54 -> 0 | M16: ='[15]Glbl Expsr'!$D$2 -> 0.15333856 | N16: ='[15]Glbl Expsr'!$D$3 -> 0.15333856 | O16: \\pim-cpt-statpro\SPC_602\Client\Profiles\PIM\Exports\PEQ Derv Calc 6Apr2022.xlsx | P16: PEQ Mandate
A17: SAAMMAN | B17: =[16]Summary!$G$3 -> UT | C17: =[16]Summary!$E$1 -> 3 | D17: =[16]Summary!$C$34 -> 0.0064514805 | E17: =[16]Summary!$E$34/100 -> 0.0064514805 | F17: =[16]Summary!$C$36 -> 0 | G17: =[16]Summary!$C$32 -> 0 | H17: =[16]Summary!$E$6/100 -> 0 | I17: =[16]Summary!$E$10/100 -> 0 | J17: =[16]Summary!$E$14/100 -> 0 | K17: =[16]Summary!$C$40 -> 4.5373426 | L17: =[16]Summary!$C$54 -> 0 | M17: ='[16]Glbl Expsr'!$D$2 -> 4.5373426 | N17: ='[16]Glbl Expsr'!$D$3 -> 4.5373426 | O17: \\pim-cpt-statpro\SPC_602\Client\Profiles\PIM\Exports\SAAMMAN Derv Calc 6Apr2022.xlsx | P17: SAAMMAN Mandate
A18: SAAMCAU | B18: =[17]Summary!$G$3 -> UT | C18: =[17]Summary!$E$1 -> 3 | D18: =[17]Summary!$C$34 -> 0.0087109861 | E18: =[17]Summary!$E$34/100 -> 0.0087109861 | F18: =[17]Summary!$C$36 -> 0 | G18: =[17]Summary!$C$32 -> 0 | H18: =[17]Summary!$E$6/100 -> 0 | I18: =[17]Summary!$E$10/100 -> 0 | J18: =[17]Summary!$E$14/100 -> 0 | K18: =[17]Summary!$C$40 -> 4.8874986 | L18: =[17]Summary!$C$54 -> 0 | M18: ='[17]Glbl Expsr'!$D$2 -> 4.8874986 | N18: ='[17]Glbl Expsr'!$D$3 -> 4.8874986 | O18: \\pim-cpt-statpro\SPC_602\Client\Profiles\PIM\Exports\SAAMCAU Derv Calc 6Apr2022.xlsx | P18: SAAMCAU Mandate
A19: PABS | B19: =[18]Summary!$G$3 -> UT | C19: =[18]Summary!$E$1 -> 3 | D19: =[18]Summary!$C$34 -> 0.010002733 | E19: =[18]Summary!$E$34/100 -> 0.10720719 | F19: =[18]Summary!$C$36 -> 0.29925094 | G19: =[18]Summary!$C$32 -> 0 | H19: =[18]Summary!$E$6/100 -> 0 | I19: =[18]Summary!$E$10/100 -> 0 | J19: =[18]Summary!$E$14/100 -> 0 | K19: =[18]Summary!$C$40 -> 0.31714404 | L19: =[18]Summary!$C$54 -> 43.613811 | M19: ='[18]Glbl Expsr'!$D$2 -> 0.0092307135 | N19: ='[18]Glbl Expsr'!$D$3 -> 0.0092307135 | O19: \\pim-cpt-statpro\SPC_602\Client\Profiles\PIM\Exports\PABS Derv Calc 6Apr2022.xlsx | P19: PABS Mandate
A20: SAAMMOD | B20: =[19]Summary!$G$3 -> UT | C20: =[19]Summary!$E$1 -> 3 | D20: =[19]Summary!$C$34 -> 0.011947854 | E20: =[19]Summary!$E$34/100 -> 0.011947854 | F20: =[19]Summary!$C$36 -> 0 | G20: =[19]Summary!$C$32 -> 0 | H20: =[19]Summary!$E$6/100 -> 0 | I20: =[19]Summary!$E$10/100 -> 0 | J20: =[19]Summary!$E$14/100 -> 0 | K20: =[19]Summary!$C$40 -> 4.5371611 | L20: =[19]Summary!$C$54 -> 0 | M20: ='[19]Glbl Expsr'!$D$2 -> 4.5371611 | N20: ='[19]Glbl Expsr'!$D$3 -> 4.5371611 | O20: \\pim-cpt-statpro\SPC_602\Client\Profiles\PIM\Exports\SAAMMOD Derv Calc 6Apr2022.xlsx | P20: SAAMMOD Mandate
A21: SMMRRF | B21: =[20]Summary!$G$3 -> UT | C21: =[20]Summary!$E$1 -> 2 | D21: =[20]Summary!$C$34 -> 0.0037491671 | E21: =[20]Summary!$E$34/100 -> 0.0037491671 | F21: =[20]Summary!$C$36 -> 0.0099448086 | G21: =[20]Summary!$C$32 -> 0 | H21: =[20]Summary!$E$6/100 -> 0 | I21: =[20]Summary!$E$10/100 -> 0 | J21: =[20]Summary!$E$14/100 -> 0 | K21: =[20]Summary!$C$40 -> 0.35472694 | L21: =[20]Summary!$C$54 -> 0 | M21: ='[20]Glbl Expsr'!$D$2 -> 0.26707297 | N21: ='[20]Glbl Expsr'!$D$3 -> 0.26707297 | O21: \\pim-cpt-statpro\SPC_602\Client\Profiles\PIM\Exports\SMMRRF Derv Calc 6Apr2022.xlsx | P21: SMMRRF Mandate
A22: HOLDINC | B22: =[21]Summary!$G$3 -> UT | C22: =[21]Summary!$E$1 -> 2 | D22: =[21]Summary!$C$34 -> 0.16480126 | E22: =[21]Summary!$E$34/100 -> 0.16480126 | F22: =[21]Summary!$C$36 -> 0.67706999 | G22: =[21]Summary!$C$32 -> 0 | H22: =[21]Summary!$E$6/100 -> 0.13037834 | I22: =[21]Summary!$E$10/100 -> 0 | J22: =[21]Summary!$E$14/100 -> 0.0020140446 | K22: =[21]Summary!$C$40 -> 0.047540833 | L22: =[21]Summary!$C$54 -> 5.1072566 | M22: ='[21]Glbl Expsr'!$D$2 -> 0.00019583205 | N22: ='[21]Glbl Expsr'!$D$3 -> 0.00019413205 | O22: \\pim-cpt-statpro\SPC_602\Client\Profiles\PIM\Exports\HOLDINC Derv Calc 6Apr2022.xlsx | P22: HOLDINC Mandate
A23: CAPGIP | B23: =[22]Summary!$G$3 -> UT | C23: =[22]Summary!$E$1 -> 2 | D23: =[22]Summary!$C$34 -> 0.1873959 | E23: =[22]Summary!$E$34/100 -> 0.1873959 | F23: =[22]Summary!$C$36 -> 0.45405665 | G23: =[22]Summary!$C$32 -> 0 | H23: =[22]Summary!$E$6/100 -> 0.057555138 | I23: =[22]Summary!$E$10/100 -> 0 | J23: =[22]Summary!$E$14/100 -> 0 | K23: =[22]Summary!$C$40 -> 0.057927489 | L23: =[22]Summary!$C$54 -> 8.4597345 | M23: ='[22]Glbl Expsr'!$D$2 -> 0.00017937063 | N23: ='[22]Glbl Expsr'!$D$3 -> 0.00017781353 | O23: \\pim-cpt-statpro\SPC_602\Client\Profiles\PIM\Exports\CAPGIP Derv Calc 6Apr2022.xlsx | P23: CAPGIP Mandate
A24: MOMBBF | B24: =[23]Summary!$G$3 -> UT | C24: =[23]Summary!$E$1 -> 2 | D24: =[23]Summary!$C$34 -> 0.18812216 | E24: =[23]Summary!$E$34/100 -> 0.18812216 | F24: =[23]Summary!$C$36 -> 0.66968045 | G24: =[23]Summary!$C$32 -> 0 | H24: =[23]Summary!$E$6/100 -> 0.11040074 | I24: =[23]Summary!$E$10/100 -> 0 | J24: =[23]Summary!$E$14/100 -> 0 | K24: =[23]Summary!$C$40 -> 0.056875318 | L24: =[23]Summary!$C$54 -> 5.6319494 | M24: ='[23]Glbl Expsr'!$D$2 -> 0.00023108087 | N24: ='[23]Glbl Expsr'!$D$3 -> 0.00022907488 | O24: \\pim-cpt-statpro\SPC_602\Client\Profiles\PIM\Exports\MOMBBF Derv Calc 6Apr2022.xlsx | P24: MOMBBF Mandate
A25: PPSFLEX | B25: =[24]Summary!$G$3 -> UT | C25: =[24]Summary!$E$1 -> 2 | D25: =[24]Summary!$C$34 -> 0.19016158 | E25: =[24]Summary!$E$34/100 -> 0.19016158 | F25: =[24]Summary!$C$36 -> 0.63298718 | G25: =[24]Summary!$C$32 -> 0 | H25: =[24]Summary!$E$6/100 -> 0.10877986 | I25: =[24]Summary!$E$10/100 -> 0 | J25: =[24]Summary!$E$14/100 -> 0 | K25: =[24]Summary!$C$40 -> 0.057519799 | L25: =[24]Summary!$C$54 -> 7.8233252 | M25: ='[24]Glbl Expsr'!$D$2 -> 0.00028324351 | N25: ='[24]Glbl Expsr'!$D$3 -> 0.0002807847 | O25: \\pim-cpt-statpro\SPC_602\Client\Profiles\PIM\Exports\PPSFLEX Derv Calc 6Apr2022.xlsx | P25: PPSFLEX Mandate
A26: HOLYPF | B26: =[25]Summary!$G$3 -> UT | C26: =[25]Summary!$E$1 -> 2 | D26: =[25]Summary!$C$34 -> 0.22456624 | E26: =[25]Summary!$E$34/100 -> 0.22456624 | F26: =[25]Summary!$C$36 -> 0.77463768 | G26: =[25]Summary!$C$32 -> 0 | H26: =[25]Summary!$E$6/100 -> 0.12072134 | I26: =[25]Summary!$E$10/100 -> 0 | J26: =[25]Summary!$E$14/100 -> 0 | K26: =[25]Summary!$C$40 -> 0.00013893527 | L26: =[25]Summary!$C$54 -> -1.4970156 | M26: ='[25]Glbl Expsr'!$D$2 -> 0.00014015192 | N26: ='[25]Glbl Expsr'!$D$3 -> 0.00013893527 | O26: \\pim-cpt-statpro\SPC_602\Client\Profiles\PIM\Exports\HOLYPF Derv Calc 6Apr2022.xlsx | P26: HOLYPF Mandate
A27: SMMAIF | B27: =[26]Summary!$G$3 -> UT | C27: =[26]Summary!$E$1 -> 2 | D27: =[26]Summary!$C$34 -> 0.22633957 | E27: =[26]Summary!$E$34/100 -> 0.22633957 | F27: =[26]Summary!$C$36 -> 0.57166136 | G27: =[26]Summary!$C$32 -> 0 | H27: =[26]Summary!$E$6/100 -> 0.042692009 | I27: =[26]Summary!$E$10/100 -> 0 | J27: =[26]Summary!$E$14/100 -> 0 | K27: =[26]Summary!$C$40 -> 0.036006721 | L27: =[26]Summary!$C$54 -> 4.7421055 | M27: ='[26]Glbl Expsr'!$D$2 -> 0.0001621699 | N27: ='[26]Glbl Expsr'!$D$3 -> 0.00016076212 | O27: \\pim-cpt-statpro\SPC_602\Client\Profiles\PIM\Exports\SMMAIF Derv Calc 6Apr2022.xlsx | P27: SMMAIF Mandate
A28: GRFINV | B28: =[27]Summary!$G$3 -> UT | C28: =[27]Summary!$E$1 -> 2 | D28: =[27]Summary!$C$34 -> 0.29621998 | E28: =[27]Summary!$E$34/100 -> 0.29621998 | F28: =[27]Summary!$C$36 -> 0.39682893 | G28: =[27]Summary!$C$32 -> 0 | H28: =[27]Summary!$E$6/100 -> 0.046830667 | I28: =[27]Summary!$E$10/100 -> 0 | J28: =[27]Summary!$E$14/100 -> 0 | K28: =[27]Summary!$C$40 -> 0.043889842 | L28: =[27]Summary!$C$54 -> 2.0980708 | M28: ='[27]Glbl Expsr'!$D$2 -> 0.00039647873 | N28: ='[27]Glbl Expsr'!$D$3 -> 0.00039303693 | O28: \\pim-cpt-statpro\SPC_602\Client\Profiles\PIM\Exports\GRFINV Derv Calc 6Apr2022.xlsx | P28: GRFINV Mandate
A29: ASHFLX | B29: =[28]Summary!$G$3 -> UT | C29: =[28]Summary!$E$1 -> 2 | D29: =[28]Summary!$C$34 -> 0.36241963 | E29: =[28]Summary!$E$34/100 -> 0.36241963 | F29: =[28]Summary!$C$36 -> 0.55031471 | G29: =[28]Summary!$C$32 -> 0 | H29: =[28]Summary!$E$6/100 -> 0.1143555 | I29: =[28]Summary!$E$10/100 -> 0 | J29: =[28]Summary!$E$14/100 -> 0 | K29: =[28]Summary!$C$40 -> 0.038489007 | L29: =[28]Summary!$C$54 -> 1.9755032 | M29: ='[28]Glbl Expsr'!$D$2 -> 0.00026332107 | N29: ='[28]Glbl Expsr'!$D$3 -> 0.0002610352 | O29: \\pim-cpt-statpro\SPC_602\Client\Profiles\PIM\Exports\ASHFLX Derv Calc 6Apr2022.xlsx | P29: ASHFLX Mandate
A30: MOMFLX | B30: =[29]Summary!$G$3 -> UT | C30: =[29]Summary!$E$1 -> 0 | D30: =[29]Summary!$C$34 -> 0.002056792 | E30: =[29]Summary!$E$34/100 -> 0.002056792 | F30: =[29]Summary!$C$36 -> 0.99794321 | G30: =[29]Summary!$C$32 -> 0 | H30: =[29]Summary!$E$6/100 -> 0 | I30: =[29]Summary!$E$10/100 -> 0 | J30: =[29]Summary!$E$14/100 -> 0 | K30: =[29]Summary!$C$40 -> 0 | L30: =[29]Summary!$C$54 -> 0 | M30: ='[29]Glbl Expsr'!$D$2 -> 0 | N30: ='[29]Glbl Expsr'!$D$3 -> 0 | O30: \\pim-cpt-statpro\SPC_602\Client\Profiles\PIM\Exports\MOMFLX Derv Calc 6Apr2022.xlsx | P30: MOMFLX Mandate
A31: SMMIBF | B31: =[30]Summary!$G$3 -> UT | C31: =[30]Summary!$E$1 -> 0 | D31: =[30]Summary!$C$34 -> 0.0024365093 | E31: =[30]Summary!$E$34/100 -> 0.0024365093 | F31: =[30]Summary!$C$36 -> 0.99756349 | G31: =[30]Summary!$C$32 -> 0 | H31: =[30]Summary!$E$6/100 -> 0.023064705 | I31: =[30]Summary!$E$10/100 -> 0 | J31: =[30]Summary!$E$14/100 -> 0 | K31: =[30]Summary!$C$40 -> 0 | L31: =[30]Summary!$C$54 -> 0 | M31: ='[30]Glbl Expsr'!$D$2 -> 0 | N31: ='[30]Glbl Expsr'!$D$3 -> 0 | O31: \\pim-cpt-statpro\SPC_602\Client\Profiles\PIM\Exports\SMMIBF Derv Calc 6Apr2022.xlsx | P31: SMMIBF Mandate
A32: PBNDQ | B32: =[31]Summary!$G$3 -> UT | C32: =[31]Summary!$E$1 -> 0 | D32: =[31]Summary!$C$34 -> 0.0030173301 | E32: =[31]Summary!$E$34/100 -> 0.0030173301 | F32: =[31]Summary!$C$36 -> 0.99698267 | G32: =[31]Summary!$C$32 -> 0 | H32: =[31]Summary!$E$6/100 -> 0 | I32: =[31]Summary!$E$10/100 -> 0 | J32: =[31]Summary!$E$14/100 -> 0 | K32: =[31]Summary!$C$40 -> 0 | L32: =[31]Summary!$C$54 -> 0 | M32: ='[31]Glbl Expsr'!$D$2 -> 0 | N32: ='[31]Glbl Expsr'!$D$3 -> 0 | O32: \\pim-cpt-statpro\SPC_602\Client\Profiles\PIM\Exports\PBNDQ Derv Calc 6Apr2022.xlsx | P32: PBNDQ Mandate
A33: OMFLXI5 | B33: =[32]Summary!$G$3 -> UT | C33: =[32]Summary!$E$1 -> 0 | D33: =[32]Summary!$C$34 -> 0.0032614639 | E33: =[32]Summary!$E$34/100 -> 0.0032614639 | F33: =[32]Summary!$C$36 -> 0.99673854 | G33: =[32]Summary!$C$32 -> 0 | H33: =[32]Summary!$E$6/100 -> 0 | I33: =[32]Summary!$E$10/100 -> 0 | J33: =[32]Summary!$E$14/100 -> 0 | K33: =[32]Summary!$C$40 -> 0 | L33: =[32]Summary!$C$54 -> 0 | M33: ='[32]Glbl Expsr'!$D$2 -> 0 | N33: ='[32]Glbl Expsr'!$D$3 -> 0 | O33: \\pim-cpt-statpro\SPC_602\Client\Profiles\PIM\Exports\OMFLXI5 Derv Calc 6Apr2022.xlsx | P33: OMFLXI5 Mandate
A34: SMMBPR | B34: =[33]Summary!$G$3 -> UT | C34: =[33]Summary!$E$1 -> 0 | D34: =[33]Summary!$C$34 -> 0.0035404715 | E34: =[33]Summary!$E$34/100 -> 0.0035404715 | F34: =[33]Summary!$C$36 -> 0.99645953 | G34: =[33]Summary!$C$32 -> 0 | H34: =[33]Summary!$E$6/100 -> 0.0064483781 | I34: =[33]Summary!$E$10/100 -> 0 | J34: =[33]Summary!$E$14/100 -> 0 | K34: =[33]Summary!$C$40 -> 0 | L34: =[33]Summary!$C$54 -> 0 | M34: ='[33]Glbl Expsr'!$D$2 -> 0 | N34: ='[33]Glbl Expsr'!$D$3 -> 0 | O34: \\pim-cpt-statpro\SPC_602\Client\Profiles\PIM\Exports\SMMBPR Derv Calc 6Apr2022.xlsx | P34: SMMBPR Mandate
A35: STSBND | B35: =[34]Summary!$G$3 -> UT | C35: =[34]Summary!$E$1 -> 0 | D35: =[34]Summary!$C$34 -> 0.0037745671 | E35: =[34]Summary!$E$34/100 -> 0.0037745671 | F35: =[34]Summary!$C$36 -> 0.99622543 | G35: =[34]Summary!$C$32 -> 0 | H35: =[34]Summary!$E$6/100 -> 0.01509834 | I35: =[34]Summary!$E$10/100 -> 0 | J35: =[34]Summary!$E$14/100 -> 0 | K35: =[34]Summary!$C$40 -> 0 | L35: =[34]Summary!$C$54 -> 0 | M35: ='[34]Glbl Expsr'!$D$2 -> 0 | N35: ='[34]Glbl Expsr'!$D$3 -> 0 | O35: \\pim-cpt-statpro\SPC_602\Client\Profiles\PIM\Exports\STSBND Derv Calc 6Apr2022.xlsx | P35: STSBND Mandate
A36: ASHGFB | B36: =[35]Summary!$G$3 -> UT | C36: =[35]Summary!$E$1 -> 0 | D36: =[35]Summary!$C$34 -> 0.0042467954 | E36: =[35]Summary!$E$34/100 -> 0.0042467954 | F36: =[35]Summary!$C$36 -> 0.9957532 | G36: =[35]Summary!$C$32 -> 0 | H36: =[35]Summary!$E$6/100 -> 0 | I36: =[35]Summary!$E$10/100 -> 0 | J36: =[35]Summary!$E$14/100 -> 0 | K36: =[35]Summary!$C$40 -> 0 | L36: =[35]Summary!$C$54 -> 0 | M36: ='[35]Glbl Expsr'!$D$2 -> 0 | N36: ='[35]Glbl Expsr'!$D$3 -> 0 | O36: \\pim-cpt-statpro\SPC_602\Client\Profiles\PIM\Exports\ASHGFB Derv Calc 6Apr2022.xlsx | P36: ASHGFB Mandate
A37: ABMMBND | B37: =[36]Summary!$G$3 -> UT | C37: =[36]Summary!$E$1 -> 0 | D37: =[36]Summary!$C$34 -> 0.0056691116 | E37: =[36]Summary!$E$34/100 -> 0.0056691116 | F37: =[36]Summary!$C$36 -> 0.99433089 | G37: =[36]Summary!$C$32 -> 0 | H37: =[36]Summary!$E$6/100 -> 0 | I37: =[36]Summary!$E$10/100 -> 0 | J37: =[36]Summary!$E$14/100 -> 0 | K37: =[36]Summary!$C$40 -> 0 | L37: =[36]Summary!$C$54 -> 0 | M37: ='[36]Glbl Expsr'!$D$2 -> 0 | N37: ='[36]Glbl Expsr'!$D$3 -> 0 | O37: \\pim-cpt-statpro\SPC_602\Client\Profiles\PIM\Exports\ABMMBND Derv Calc 6Apr2022.xlsx | P37: ABMMBND Mandate
A38: PCGEF | B38: =[37]Summary!$G$3 -> UT | C38: =[37]Summary!$E$1 -> 0 | D38: =[37]Summary!$C$34 -> 0.0094445606 | E38: =[37]Summary!$E$34/100 -> 0.0094445606 | F38: =[37]Summary!$C$36 -> 0 | G38: =[37]Summary!$C$32 -> 0 | H38: =[37]Summary!$E$6/100 -> 0 | I38: =[37]Summary!$E$10/100 -> 0 | J38: =[37]Summary!$E$14/100 -> 0 | K38: =[37]Summary!$C$40 -> 0.99055544 | L38: =[37]Summary!$C$54 -> 99.055544 | M38: ='[37]Glbl Expsr'!$D$2 -> 0 | N38: ='[37]Glbl Expsr'!$D$3 -> 0 | O38: \\pim-cpt-statpro\SPC_602\Client\Profiles\PIM\Exports\PCGEF Derv Calc 6Apr2022.xlsx | P38: PCGEF Mandate
A39: PGGF | B39: =[38]Summary!$G$3 -> UT | C39: =[38]Summary!$E$1 -> 0 | D39: =[38]Summary!$C$34 -> 0.010070441 | E39: =[38]Summary!$E$34/100 -> 0.010070441 | F39: =[38]Summary!$C$36 -> 0 | G39: =[38]Summary!$C$32 -> 0 | H39: =[38]Summary!$E$6/100 -> 0 | I39: =[38]Summary!$E$10/100 -> 0 | J39: =[38]Summary!$E$14/100 -> 0 | K39: =[38]Summary!$C$40 -> 0.98992956 | L39: =[38]Summary!$C$54 -> 98.992956 | M39: ='[38]Glbl Expsr'!$D$2 -> 0 | N39: ='[38]Glbl Expsr'!$D$3 -> 0 | O39: \\pim-cpt-statpro\SPC_602\Client\Profiles\PIM\Exports\PGGF Derv Calc 6Apr2022.xlsx | P39: PGGF Mandate
A40: IJGCOR | B40: =[39]Summary!$G$3 -> UT | C40: =[39]Summary!$E$1 -> 0 | D40: =[39]Summary!$C$34 -> 0.035793677 | E40: =[39]Summary!$E$34/100 -> 0.035793677 | F40: =[39]Summary!$C$36 -> 0 | G40: =[39]Summary!$C$32 -> 0 | H40: =[39]Summary!$E$6/100 -> 0 | I40: =[39]Summary!$E$10/100 -> 0 | J40: =[39]Summary!$E$14/100 -> 0 | K40: =[39]Summary!$C$40 -> 0 | L40: =[39]Summary!$C$54 -> 96.420632 | M40: ='[39]Glbl Expsr'!$D$2 -> 0 | N40: ='[39]Glbl Expsr'!$D$3 -> 0 | O40: \\pim-cpt-statpro\SPC_602\Client\Profiles\PIM\Exports\IJGCOR Derv Calc 6Apr2022.xlsx | P40: IJGCOR Mandate
...

Sheet Static
A1: 44181 | B1: Day of Reconciliation | D1: =HYPERLINK("C:\Users\hilton.netta\py","Back to py") -> Back to py
A2: 44190 | B2: Christmas Day
A3: 44191 | B3: Boxing Day
A4: 44197 | B4: New Year's Day
A5: 44277 | B5: Human Rights Day
A6: 44288 | B6: Good Friday
A7: 44291 | B7: Family Day
A8: 44313 | B8: Freedom Day
A9: 44317 | B9: International Workers' Day
A10: 44363 | B10: Youth Day (in South Africa)
A11: 44417 | B11: National Women's Day
A12: 44463 | B12: Heritage Day
A13: 44501 | B13: Election Day
... A29: 44921 | B29: Day of Goodwill

Sheet Summary
A1: =Data!$A$2&" ("&Data!$AK$2&")" -> 0 (44676) | B1: Current Exposure | C1: Market Value | E1: =COUNTIF(Data!$B:$B,"Derivatives")+COUNTIF(Data!$B:$B,"Forwards")+COUNTIF(Data!$B:$B,"Swaps") -> 0 | F1: ="derivative"&IF(E1=1,"","s") -> derivatives | G1: =HYPERLINK("J:\PProfile Operations\Legal\Legal and Compliance Framework\Hilton\Client Mandates\"&SUBSTITUTE(Data!$AK$2,"_C","")&" Rules.docx","Mandate") -> Mandate | H1: {="SA equity indices ("&SUMPRODUCT((Data!$C:$C="Equity Derivatives")*(Data!$W:$W="ZAR"))&")"} -> SA equity indices (0) | I1: {=IF(ISNA(MATCH(1,("Equity derivatives"=Data!C:C)*("ZAR"=Data!W:W),0)),"",INDEX(Data!D:D,MATCH(1,("Equity derivatives"=Data!C:C)*("ZAR"=Data!W:W),0)))} | J1: {=IF(COUNTA($I$1:I$1)<COUNTIFS(Data!$C:$C,"Equity derivatives",Data!$W:$W,"ZAR"),INDEX(Data!$D:$D,MATCH(I$1,Data!$D:$D,0)+1),"")} | K1: {=IF(COUNTA($I$1:J$1)<COUNTIFS(Data!$C:$C,"Equity derivatives",Data!$W:$W,"ZAR"),INDEX(Data!$D:$D,MATCH(J$1,Data!$D:$D,0)+1),"")} | L1: {=IF(COUNTA($I$1:K$1)<COUNTIFS(Data!$C:$C,"Equity derivatives",Data!$W:$W,"ZAR"),INDEX(Data!$D:$D,MATCH(K$1,Data!$D:$D,0)+1),"")} | M1: {=IF(COUNTA($I$1:L$1)<COUNTIFS(Data!$C:$C,"Equity derivatives",Data!$W:$W,"ZAR"),INDEX(Data!$D:$D,MATCH(L$1,Data!$D:$D,0)+1),"")} | N1: {=IF(COUNTA($I$1:M$1)<COUNTIFS(Data!$C:$C,"Equity derivatives",Data!$W:$W,"ZAR"),INDEX(Data!$D:$D,MATCH(M$1,Data!$D:$D,0)+1),"")} | O1: {=IF(COUNTA($I$1:N$1)<COUNTIFS(Data!$C:$C,"Equity derivatives",Data!$W:$W,"ZAR"),INDEX(Data!$D:$D,MATCH(N$1,Data!$D:$D,0)+1),"")} | P1: {=IF(COUNTA($I$1:O$1)<COUNTIFS(Data!$C:$C,"Equity derivatives",Data!$W:$W,"ZAR"),INDEX(Data!$D:$D,MATCH(O$1,Data!$D:$D,0)+1),"")} | Q1: {=IF(COUNTA($I$1:P$1)<COUNTIFS(Data!$C:$C,"Equity derivatives",Data!$W:$W,"ZAR"),INDEX(Data!$D:$D,MATCH(P$1,Data!$D:$D,0)+1),"")} | ... BH1: {=IF(COUNTA($I$1:BG$1)<COUNTIFS(Data!$C:$C,"Equity derivatives",Data!$W:$W,"ZAR"),INDEX(Data!$D:$D,MATCH(BG$1,Data!$D:$D,0)+1),"")}
A2: =HYPERLINK("https://pimportalprod2015.eagleaccess.com/Default.aspx","Derivative Cover "&TEXT(Data!$AJ$2,"dddd d mmmm yyyy")) -> Derivative Cover Saturday 0 January 1900 | B2: R | C2: % | F2: ASSET COVER CHECK | G2: {=CELL("filename")} -> C:\Users\hilton.netta\py\[derv - Copy.xlsx]Deltas | H2: =IF(ISNA(SUM(I2:BH2)),0,SUM(I2:BH2)) -> 0 | I2: =IF(I$1="","",INDEX(Data!$AH:$AH,MATCH(I$1,Data!$D:$D,0))/$B$4) | J2: =IF(J$1="","",INDEX(Data!$AH:$AH,MATCH(J$1,Data!$D:$D,0))/$B$4) | K2: =IF(K$1="","",INDEX(Data!$AH:$AH,MATCH(K$1,Data!$D:$D,0))/$B$4) | L2: =IF(L$1="","",INDEX(Data!$AH:$AH,MATCH(L$1,Data!$D:$D,0))/$B$4) | M2: =IF(M$1="","",INDEX(Data!$AH:$AH,MATCH(M$1,Data!$D:$D,0))/$B$4) | N2: =IF(N$1="","",INDEX(Data!$AH:$AH,MATCH(N$1,Data!$D:$D,0))/$B$4) | O2: =IF(O$1="","",INDEX(Data!$AH:$AH,MATCH(O$1,Data!$D:$D,0))/$B$4) | P2: =IF(P$1="","",INDEX(Data!$AH:$AH,MATCH(P$1,Data!$D:$D,0))/$B$4) | ... BH2: =IF(BH$1="","",INDEX(Data!$AH:$AH,MATCH(BH$1,Data!$D:$D,0))/$B$4)
A3: UT | E3: 0 | F3: Total direct SA bonds available to cover short exposures | G3: =_xlfn.XLOOKUP(Data!AK$2,[77]Funds!$A:$A,[77]Funds!$E:$E) -> #N/A
A4: Fund NAV | B4: =SUM(Data!$L:$L) -> 0 | C4: =SUM(Data!$N:$N)/100 -> 3137.8749 | E4: =IF(ISNA(MATCH($G4,Data!$E:$E,0)),0,_xlfn.XLOOKUP($G4,Data!$E:$E,Data!$AI:$AI))+IF(ISNA(MATCH(186,Data!$E:$E,0)),0,_xlfn.XLOOKUP(186,Data!$E:$E,Data!$AI:$AI)) -> 0 | F4: Total same or similar bonds available to cover short exposures | G4: R186 | H4: {="World equity indices ("&SUMPRODUCT((Data!$C:$C="Equity Derivatives")*(Data!$W:$W<>"ZAR"))&")"} -> World equity indices (0) | I4: {=IF(ISNA(MATCH(1,("Equity derivatives"=Data!C:C)*("ZAR"<>Data!W:W),0)),"",INDEX(Data!D:D,MATCH(1,("Equity derivatives"=Data!C:C)*("ZAR"<>Data!W:W),0)))} | J4: {=IF(COUNTA($I$4:I$4)<COUNTIFS(Data!$C:$C,"Equity derivatives",Data!$W:$W,"<>ZAR"),INDEX(Data!$D:$D,MATCH(I$4,Data!$D:$D,0)+1),"")} | K4: {=IF(COUNTA($I$4:J$4)<COUNTIFS(Data!$C:$C,"Equity derivatives",Data!$W:$W,"<>ZAR"),INDEX(Data!$D:$D,MATCH(J$4,Data!$D:$D,0)+1),"")} | L4: {=IF(COUNTA($I$4:K$4)<COUNTIFS(Data!$C:$C,"Equity derivatives",Data!$W:$W,"<>ZAR"),INDEX(Data!$D:$D,MATCH(K$4,Data!$D:$D,0)+1),"")} | M4: {=IF(COUNTA($I$4:L$4)<COUNTIFS(Data!$C:$C,"Equity derivatives",Data!$W:$W,"<>ZAR"),INDEX(Data!$D:$D,MATCH(L$4,Data!$D:$D,0)+1),"")} | N4: {=IF(COUNTA($I$4:M$4)<COUNTIFS(Data!$C:$C,"Equity derivatives",Data!$W:$W,"<>ZAR"),INDEX(Data!$D:$D,MATCH(M$4,Data!$D:$D,0)+1),"")} | O4: {=IF(COUNTA($I$4:N$4)<COUNTIFS(Data!$C:$C,"Equity derivatives",Data!$W:$W,"<>ZAR"),INDEX(Data!$D:$D,MATCH(N$4,Data!$D:$D,0)+1),"")} | P4: {=IF(COUNTA($I$4:O$4)<COUNTIFS(Data!$C:$C,"Equity derivatives",Data!$W:$W,"<>ZAR"),INDEX(Data!$D:$D,MATCH(O$4,Data!$D:$D,0)+1),"")} | Q4: {=IF(COUNTA($I$4:P$4)<COUNTIFS(Data!$C:$C,"Equity derivatives",Data!$W:$W,"<>ZAR"),INDEX(Data!$D:$D,MATCH(P$4,Data!$D:$D,0)+1),"")} | ... BH4: {=IF(COUNTA($I$4:BG$4)<COUNTIFS(Data!$C:$C,"Equity derivatives",Data!$W:$W,"<>ZAR"),INDEX(Data!$D:$D,MATCH(BG$4,Data!$D:$D,0)+1),"")}
E5: =MIN(0,$H$8*100) -> 0 | F5: Net short derivative exposure | H5: =IF(ISNA(SUM(I5:BH5)),0,SUM(I5:BH5)) -> 0 | I5: =IF(I$4="","",INDEX(Data!$AH:$AH,MATCH(I$4,Data!$D:$D,0))/$B$4) | J5: =IF(J$4="","",INDEX(Data!$AH:$AH,MATCH(J$4,Data!$D:$D,0))/$B$4) | K5: =IF(K$4="","",INDEX(Data!$AH:$AH,MATCH(K$4,Data!$D:$D,0))/$B$4) | L5: =IF(L$4="","",INDEX(Data!$AH:$AH,MATCH(L$4,Data!$D:$D,0))/$B$4) | M5: =IF(M$4="","",INDEX(Data!$AH:$AH,MATCH(M$4,Data!$D:$D,0))/$B$4) | N5: =IF(N$4="","",INDEX(Data!$AH:$AH,MATCH(N$4,Data!$D:$D,0))/$B$4) | O5: =IF(O$4="","",INDEX(Data!$AH:$AH,MATCH(O$4,Data!$D:$D,0))/$B$4) | P5: =IF(P$4="","",INDEX(Data!$AH:$AH,MATCH(P$4,Data!$D:$D,0))/$B$4) | ... BH5: =IF(BH$4="","",INDEX(Data!$AH:$AH,MATCH(BH$4,Data!$D:$D,0))/$B$4)
A6: Assets in liquid form | B6: =SUM(B7:B11) -> 0 | C6: =SUM(C7:C11) -> #DIV/0! | E6: =SUM(E3:E5) -> 0 | F6: =IF($E6>=0,"Adequate","INADEQUATE")&" short SA bond bond derivative cover [BN90 16(1)(a) & (b)]" -> Adequate short SA bond bond derivative cover [BN90 16(1)(a) & (b)]
A7: Cash (incl MMFs, excl margin) | B7: =SUMIF(Data!$B:$B,"CASH",Data!$AH:$AH)-SUMIF(Data!$E:$E,"SAFEX",Data!$AH:$AH)-SUMIF(Data!$E:$E,"VARMARG",Data!$AH:$AH) -> 0 | C7: =$B7/$B$4 -> #DIV/0! | H7: {="SA bond indices ("&SUMPRODUCT((Data!$C:$C="Bond Derivatives")*(Data!$W:$W="ZAR"))&")"} -> SA bond indices (0) | I7: {=IF(ISNA(MATCH(1,("Bond derivatives"=Data!C:C)*("ZAR"=Data!W:W),0)),"",INDEX(Data!D:D,MATCH(1,("Bond derivatives"=Data!C:C)*("ZAR"=Data!W:W),0)))} | J7: {=IF(I7<>"",IF(COUNTA($I$7:I$7)<COUNTIF(Data!$C:$C,"Bond Derivatives"),INDEX(Data!$D:$D,MATCH(I$7,Data!$D:$D,0)+1),""),"")} | K7: {=IF(COUNTA($I$7:J$7)<COUNTIF(Data!$C:$C,"Bond derivatives"),INDEX(Data!$D:$D,MATCH(J$7,Data!$D:$D,0)+1),"")} | L7: {=IF(COUNTA($I$7:K$7)<COUNTIF(Data!$C:$C,"Bond derivatives"),INDEX(Data!$D:$D,MATCH(K$7,Data!$D:$D,0)+1),"")} | M7: {=IF(COUNTA($I$7:L$7)<COUNTIF(Data!$C:$C,"Bond derivatives"),INDEX(Data!$D:$D,MATCH(L$7,Data!$D:$D,0)+1),"")} | N7: {=IF(COUNTA($I$7:M$7)<COUNTIF(Data!$C:$C,"Bond derivatives"),INDEX(Data!$D:$D,MATCH(M$7,Data!$D:$D,0)+1),"")} | O7: {=IF(COUNTA($I$7:N$7)<COUNTIF(Data!$C:$C,"Bond derivatives"),INDEX(Data!$D:$D,MATCH(N$7,Data!$D:$D,0)+1),"")} | P7: {=IF(COUNTA($I$7:O$7)<COUNTIF(Data!$C:$C,"Bond derivatives"),INDEX(Data!$D:$D,MATCH(O$7,Data!$D:$D,0)+1),"")} | Q7: {=IF(COUNTA($I$7:P$7)<COUNTIF(Data!$C:$C,"Bond derivatives"),INDEX(Data!$D:$D,MATCH(P$7,Data!$D:$D,0)+1),"")} | R7: {=IF(COUNTA($I$7:Q$7)<COUNTIF(Data!$C:$C,"Bond derivatives"),INDEX(Data!$D:$D,MATCH(Q$7,Data!$D:$D,0)+1),"")} | ... BH7: {=IF(COUNTA($I$7:BG$7)<COUNTIF(Data!$C:$C,"Bond derivatives"),INDEX(Data!$D:$D,MATCH(BG$7,Data!$D:$D,0)+1),"")}
A8: ="Money market instruments"&IF($A3="UT"," (excl CLNs and > 13 month bonds)","") -> Money market instruments (excl CLNs and > 13 month bonds) | B8: {=IF($A3="UT",SUMPRODUCT((Data!$B:$B="MONEY MARKET")*((Data!$P:$P<Data!$AJ$2+397)*(Data!$V:$V<>"CLN")),(Data!$AH:$AH)),SUMIF(Data!$B:$B,"MONEY MARKET",Data!$AH:$AH))} -> 0 | C8: =$B8/$B$4 -> #DIV/0! | E8: =SUM(BM!$V:$V) -> 0 | F8: Total direct MSCI ACWI assets available to cover short exposures | H8: =SUM(I8:BH8) -> 0 | I8: =IF(I$7="","",INDEX(Data!$AH:$AH,MATCH(I$7,Data!$D:$D,0))/$B$4) | J8: =IF(J$7="","",INDEX(Data!$AH:$AH,MATCH(J$7,Data!$D:$D,0))/$B$4) | K8: =IF(K$7="","",INDEX(Data!$AH:$AH,MATCH(K$7,Data!$D:$D,0))/$B$4) | L8: =IF(L$7="","",INDEX(Data!$AH:$AH,MATCH(L$7,Data!$D:$D,0))/$B$4) | M8: =IF(M$7="","",INDEX(Data!$AH:$AH,MATCH(M$7,Data!$D:$D,0))/$B$4) | N8: =IF(N$7="","",INDEX(Data!$AH:$AH,MATCH(N$7,Data!$D:$D,0))/$B$4) | O8: =IF(O$7="","",INDEX(Data!$AH:$AH,MATCH(O$7,Data!$D:$D,0))/$B$4) | P8: =IF(P$7="","",INDEX(Data!$AH:$AH,MATCH(P$7,Data!$D:$D,0))/$B$4) | ... BH8: =IF(BH$7="","",INDEX(Data!$AH:$AH,MATCH(BH$7,Data!$D:$D,0))/$B$4)
A9: Bonds (excl > 13 month bonds) | B9: {=IF($A3="UT",SUMPRODUCT((Data!$B:$B="BONDS")*((Data!$P:$P<Data!$AJ$2+397)*(Data!$V:$V<>"CLN")),(Data!$AH:$AH)),SUMIF(Data!$B:$B,"BONDS",Data!$AH:$AH))} -> 0 | C9: =$B9/$B$4 -> #DIV/0! | E9: =MIN(0,$H$5*100) -> 0 | F9: Net short derivative exposure
A10: SAFEX [BN90 19(2)] | B10: =SUMIF(Data!$E:$E,"SAFEX",Data!$AH:$AH) -> 0 | C10: =$B10/$B$4 -> #DIV/0! | E10: =SUM(E8:E9) -> 0 | F10: =IF($E10>=0,"Adequate","INADEQUATE")&" short MSCI derivative cover [BN90 16(1)(a) & (b)]" -> Adequate short MSCI derivative cover [BN90 16(1)(a) & (b)] | H10: {="World bond indices ("&SUMPRODUCT((Data!$C:$C="Bond Derivatives")*(Data!$W:$W<>"ZAR"))&")"} -> World bond indices (0) | I10: {=IF(ISNA(MATCH(1,("bond derivatives"=Data!C:C)*("ZAR"<>Data!W:W),0)),"",INDEX(Data!D:D,MATCH(1,("bond derivatives"=Data!C:C)*("ZAR"<>Data!W:W),0)))} | J10: {=IF(I10<>"",IF(COUNTA($I$10:I$10)<COUNTIF(Data!$C:$C,"Bond Derivatives"),INDEX(Data!$D:$D,MATCH(I$10,Data!$D:$D,0)+1),""),"")} | K10: {=IF(COUNTA($I$10:J$10)<COUNTIF(Data!$C:$C,"Bond Derivatives"),INDEX(Data!$D:$D,MATCH(J$10,Data!$D:$D,0)+1),"")} | L10: {=IF(COUNTA($I$10:K$10)<COUNTIF(Data!$C:$C,"Bond Derivatives"),INDEX(Data!$D:$D,MATCH(K$10,Data!$D:$D,0)+1),"")} | M10: {=IF(COUNTA($I$10:L$10)<COUNTIF(Data!$C:$C,"Bond Derivatives"),INDEX(Data!$D:$D,MATCH(L$10,Data!$D:$D,0)+1),"")} | N10: {=IF(COUNTA($I$10:M$10)<COUNTIF(Data!$C:$C,"Bond Derivatives"),INDEX(Data!$D:$D,MATCH(M$10,Data!$D:$D,0)+1),"")} | O10: {=IF(COUNTA($I$10:N$10)<COUNTIF(Data!$C:$C,"Bond Derivatives"),INDEX(Data!$D:$D,MATCH(N$10,Data!$D:$D,0)+1),"")} | P10: {=IF(COUNTA($I$10:O$10)<COUNTIF(Data!$C:$C,"Bond Derivatives"),INDEX(Data!$D:$D,MATCH(O$10,Data!$D:$D,0)+1),"")} | Q10: {=IF(COUNTA($I$10:P$10)<COUNTIF(Data!$C:$C,"Bond Derivatives"),INDEX(Data!$D:$D,MATCH(P$10,Data!$D:$D,0)+1),"")} | R10: {=IF(COUNTA($I$10:Q$10)<COUNTIF(Data!$C:$C,"Bond Derivatives"),INDEX(Data!$D:$D,MATCH(Q$10,Data!$D:$D,0)+1),"")} | ... BH10: {=IF(COUNTA($I$10:BG$10)<COUNTIF(Data!$C:$C,"Bond Derivatives"),INDEX(Data!$D:$D,MATCH(BG$10,Data!$D:$D,0)+1),"")}
A11: Variation Margin [BN90 19(2)] | B11: =SUMIF(Data!$E:$E,"VARMARG",Data!$AH:$AH) -> 0 | C11: =$B11/$B$4 -> #DIV/0! | H11: =SUM(I11:BH11) -> 0 | I11: =IF(I$10="","",INDEX(Data!$AH:$AH,MATCH(I$10,Data!$D:$D,0))/$B$4) | J11: =IF(J$10="","",INDEX(Data!$AH:$AH,MATCH(J$10,Data!$D:$D,0))/$B$4) | K11: =IF(K$10="","",INDEX(Data!$AH:$AH,MATCH(K$10,Data!$D:$D,0))/$B$4) | L11: =IF(L$10="","",INDEX(Data!$AH:$AH,MATCH(L$10,Data!$D:$D,0))/$B$4) | M11: =IF(M$10="","",INDEX(Data!$AH:$AH,MATCH(M$10,Data!$D:$D,0))/$B$4) | N11: =IF(N$10="","",INDEX(Data!$AH:$AH,MATCH(N$10,Data!$D:$D,0))/$B$4) | O11: =IF(O$10="","",INDEX(Data!$AH:$AH,MATCH(O$10,Data!$D:$D,0))/$B$4) | P11: =IF(P$10="","",INDEX(Data!$AH:$AH,MATCH(P$10,Data!$D:$D,0))/$B$4) | ... BH11: =IF(BH$10="","",INDEX(Data!$AH:$AH,MATCH(BH$10,Data!$D:$D,0))/$B$4)
E12: =SUMIF(BM!$A:$A,"J203",BM!$E:$E) -> 0 | F12: Total direct ALSI assets available to cover short exposures
A13: less Sold currency futures to be covered by cash [BN90 16(1)(i)] | B13: =SUM(B14:B14) -> 0 | C13: =SUM(C14:C14) -> #DIV/0! | E13: =MIN(0, $H$2*100) -> 0 | F13: Net short derivative exposure | H13: ="Currency futures ("&COUNTIF(Data!$C:$C,"Currency Derivatives")&")" -> Currency futures (0) | I13: =IF(ISNA(IF(ISNA(MATCH("Currency Derivatives",Data!$C:$C,0)),"",INDEX(Data!$D:$D,MATCH("Currency Derivatives",Data!$C:$C,0)))),"",IF(ISNA(MATCH("Currency Derivatives",Data!$C:$C,0)),"",INDEX(Data!$D:$D,MATCH("Currency Derivatives",Data!$C:$C,0)))) | J13: {=IF(COUNTA($I$13:I$13)<COUNTIF(Data!$C:$C,"Currency derivatives"),INDEX(Data!$D:$D,MATCH(I$13,Data!$D:$D,0)+1),"")} | K13: {=IF(COUNTA($I$13:J$13)<COUNTIF(Data!$C:$C,"Currency derivatives"),INDEX(Data!$D:$D,MATCH(J$13,Data!$D:$D,0)+1),"")} | L13: {=IF(COUNTA($I$13:K$13)<COUNTIF(Data!$C:$C,"Currency derivatives"),INDEX(Data!$D:$D,MATCH(K$13,Data!$D:$D,0)+1),"")} | M13: {=IF(COUNTA($I$13:L$13)<COUNTIF(Data!$C:$C,"Currency derivatives"),INDEX(Data!$D:$D,MATCH(L$13,Data!$D:$D,0)+1),"")} | N13: {=IF(COUNTA($I$13:M$13)<COUNTIF(Data!$C:$C,"Currency derivatives"),INDEX(Data!$D:$D,MATCH(M$13,Data!$D:$D,0)+1),"")} | O13: {=IF(COUNTA($I$13:N$13)<COUNTIF(Data!$C:$C,"Currency derivatives"),INDEX(Data!$D:$D,MATCH(N$13,Data!$D:$D,0)+1),"")} | P13: {=IF(COUNTA($I$13:O$13)<COUNTIF(Data!$C:$C,"Currency derivatives"),INDEX(Data!$D:$D,MATCH(O$13,Data!$D:$D,0)+1),"")} | Q13: {=IF(COUNTA($I$13:P$13)<COUNTIF(Data!$C:$C,"Currency derivatives"),INDEX(Data!$D:$D,MATCH(P$13,Data!$D:$D,0)+1),"")} | ... BH13: {=IF(COUNTA($I$13:BG$13)<COUNTIF(Data!$C:$C,"Currency derivatives"),INDEX(Data!$D:$D,MATCH(BG$13,Data!$D:$D,0)+1),"")}
A14: Currency Derivatives | B14: =IF(SUMIF(Data!$C:$C,$A14,Data!$AH:$AH)<0,SUMIF(Data!$C:$C,$A14,Data!$AH:$AH),0) -> 0 | C14: =$B14/$B$4 -> #DIV/0! | E14: =SUM(E12:E13) -> 0 | F14: =IF($E14>=0,"Adequate","INADEQUATE")&" short ALSI derivative cover [BN90 16(1)(a) & (b)]" -> Adequate short ALSI derivative cover [BN90 16(1)(a) & (b)] | H14: =SUM(I14:BH14) -> 0 | I14: =IF(I$13="","",INDEX(Data!$AH:$AH,MATCH(I$13,Data!$D:$D,0))/$B$4) | J14: =IF(J$13="","",INDEX(Data!$AH:$AH,MATCH(J$13,Data!$D:$D,0))/$B$4) | K14: =IF(K$13="","",INDEX(Data!$AH:$AH,MATCH(K$13,Data!$D:$D,0))/$B$4) | L14: =IF(L$13="","",INDEX(Data!$AH:$AH,MATCH(L$13,Data!$D:$D,0))/$B$4) | M14: =IF(M$13="","",INDEX(Data!$AH:$AH,MATCH(M$13,Data!$D:$D,0))/$B$4) | N14: =IF(N$13="","",INDEX(Data!$AH:$AH,MATCH(N$13,Data!$D:$D,0))/$B$4) | O14: =IF(O$13="","",INDEX(Data!$AH:$AH,MATCH(O$13,Data!$D:$D,0))/$B$4) | P14: =IF(P$13="","",INDEX(Data!$AH:$AH,MATCH(P$13,Data!$D:$D,0))/$B$4) | ... BH14: =IF(BH$13="","",INDEX(Data!$AH:$AH,MATCH(BH$13,Data!$D:$D,0))/$B$4)
A16: less Net negative MtM OTC derivative exposure [BN90 17(1)(a)] | B16: =SUM(B17:B19) -> #VALUE! | C16: =SUM(C17:C19) -> #DIV/0! | E16: ='Glbl Expsr'!$D$3 -> #DIV/0! | F16: Leverage (net effective exposure ÷ NAV) | H16: ="Currency forwards ("&COUNTIF(Data!$C:$C,"Forwards")&")" -> Currency forwards (0) | I16: =IF(ISNA(IF(ISNA(MATCH("Forwards",Data!$C:$C,0)),"",INDEX(Data!$D:$D,MATCH("Forwards",Data!$C:$C,0)))),"",IF(ISNA(MATCH("Forwards",Data!$C:$C,0)),"",INDEX(Data!$D:$D,MATCH("Forwards",Data!$C:$C,0)))) | J16: {=IF(COUNTA($I$16:I$16)<COUNTIF(Data!$C:$C,"Forwards"),INDEX(Data!$D:$D,MATCH(I$16,Data!$D:$D,0)+1),"")} | K16: {=IF(COUNTA($I$16:J$16)<COUNTIF(Data!$C:$C,"Forwards"),INDEX(Data!$D:$D,MATCH(J$16,Data!$D:$D,0)+1),"")} | L16: {=IF(COUNTA($I$16:K$16)<COUNTIF(Data!$C:$C,"Forwards"),INDEX(Data!$D:$D,MATCH(K$16,Data!$D:$D,0)+1),"")} | M16: {=IF(COUNTA($I$16:L$16)<COUNTIF(Data!$C:$C,"Forwards"),INDEX(Data!$D:$D,MATCH(L$16,Data!$D:$D,0)+1),"")} | N16: {=IF(COUNTA($I$16:M$16)<COUNTIF(Data!$C:$C,"Forwards"),INDEX(Data!$D:$D,MATCH(M$16,Data!$D:$D,0)+1),"")} | O16: {=IF(COUNTA($I$16:N$16)<COUNTIF(Data!$C:$C,"Forwards"),INDEX(Data!$D:$D,MATCH(N$16,Data!$D:$D,0)+1),"")} | P16: {=IF(COUNTA($I$16:O$16)<COUNTIF(Data!$C:$C,"Forwards"),INDEX(Data!$D:$D,MATCH(O$16,Data!$D:$D,0)+1),"")} | Q16: {=IF(COUNTA($I$16:P$16)<COUNTIF(Data!$C:$C,"Forwards"),INDEX(Data!$D:$D,MATCH(P$16,Data!$D:$D,0)+1),"")} | ... BH16: {=IF(COUNTA($I$16:BG$16)<COUNTIF(Data!$C:$C,"Forwards"),INDEX(Data!$D:$D,MATCH(BG$16,Data!$D:$D,0)+1),"")} | BI16: {=IF(COUNTA($I$1:BH$1)<COUNTIF(Data!$C:$C,"Swaps"),INDEX(Data!$D:$D,MATCH(BH$1,Data!$D:$D,0)+1),"")} | BJ16: {=IF(COUNTA($I$1:BI$1)<COUNTIF(Data!$C:$C,"Swaps"),INDEX(Data!$D:$D,MATCH(BI$1,Data!$D:$D,0)+1),"")} | BK16: {=IF(COUNTA($I$1:BJ$1)<COUNTIF(Data!$C:$C,"Swaps"),INDEX(Data!$D:$D,MATCH(BJ$1,Data!$D:$D,0)+1),"")} | BL16: {=IF(COUNTA($I$1:BK$1)<COUNTIF(Data!$C:$C,"Swaps"),INDEX(Data!$D:$D,MATCH(BK$1,Data!$D:$D,0)+1),"")} | BM16: {=IF(COUNTA($I$1:BL$1)<COUNTIF(Data!$C:$C,"Swaps"),INDEX(Data!$D:$D,MATCH(BL$1,Data!$D:$D,0)+1),"")} | BN16: {=IF(COUNTA($I$1:BM$1)<COUNTIF(Data!$C:$C,"Swaps"),INDEX(Data!$D:$D,MATCH(BM$1,Data!$D:$D,0)+1),"")} | BO16: {=IF(COUNTA($I$1:BN$1)<COUNTIF(Data!$C:$C,"Swaps"),INDEX(Data!$D:$D,MATCH(BN$1,Data!$D:$D,0)+1),"")} | BP16: {=IF(COUNTA($I$1:BO$1)<COUNTIF(Data!$C:$C,"Swaps"),INDEX(Data!$D:$D,MATCH(BO$1,Data!$D:$D,0)+1),"")} | ... DO16: {=IF(COUNTA($I$1:DN$1)<COUNTIF(Data!$C:$C,"Swaps"),INDEX(Data!$D:$D,MATCH(DN$1,Data!$D:$D,0)+1),"")}
A17: Forwards | B17: =MIN(0,SUMIF(Data!$C:$C,$A17,Data!$AH:$AH)) -> 0 | C17: =$B17/$B$4 -> #DIV/0! | H17: =SUM(I17:BH17) -> 0 | I17: =IF(I$16="","",INDEX(Data!$AH:$AH,MATCH(I$16,Data!$D:$D,0))/$B$4) | J17: =IF(J$16="","",INDEX(Data!$AH:$AH,MATCH(J$16,Data!$D:$D,0))/$B$4) | K17: =IF(K$16="","",INDEX(Data!$AH:$AH,MATCH(K$16,Data!$D:$D,0))/$B$4) | L17: =IF(L$16="","",INDEX(Data!$AH:$AH,MATCH(L$16,Data!$D:$D,0))/$B$4) | M17: =IF(M$16="","",INDEX(Data!$AH:$AH,MATCH(M$16,Data!$D:$D,0))/$B$4) | N17: =IF(N$16="","",INDEX(Data!$AH:$AH,MATCH(N$16,Data!$D:$D,0))/$B$4) | O17: =IF(O$16="","",INDEX(Data!$AH:$AH,MATCH(O$16,Data!$D:$D,0))/$B$4) | P17: =IF(P$16="","",INDEX(Data!$AH:$AH,MATCH(P$16,Data!$D:$D,0))/$B$4) | ... BH17: =IF(BH$16="","",INDEX(Data!$AH:$AH,MATCH(BH$16,Data!$D:$D,0))/$B$4)
A18: Swaps | B18: {=MIN(0,SUMPRODUCT((Data!$B$2:$B$1000="SWAPS")*((Data!$G$2:$G$1000)*(Data!$M$2:$M$1000))))/100} -> #VALUE! | C18: =$B18/$B$4 -> #VALUE!
A19: FRAs | B19: {=MIN(0,SUMPRODUCT((Data!$B$2:$B$1000="FORWARD RATE AGREEMENT")*((Data!$G$2:$G$1000)*(Data!$M$2:$M$1000))))/100} -> #VALUE! | C19: =$B19/$B$4 -> #VALUE! | F19: CASH COVER CHECK | H19: ="Swaps ("&COUNTIF(Data!$C:$C,"SWAPS")&")" -> Swaps (0) | I19: =IF(ISNA(IF(ISNA(MATCH("Swaps",Data!$C:$C,0)),"",INDEX(Data!$D:$D,MATCH("Swaps",Data!$C:$C,0)))),"",IF(ISNA(MATCH("Swaps",Data!$C:$C,0)),"",INDEX(Data!$D:$D,MATCH("Swaps",Data!$C:$C,0)))) | J19: {=IF(COUNTA($I$19:I$19)<COUNTIF(Data!$C:$C,"Swaps"),INDEX(Data!$D:$D,MATCH(I$19,Data!$D:$D,0)+1),"")} | K19: {=IF(COUNTA($I$19:J$19)<COUNTIF(Data!$C:$C,"Swaps"),INDEX(Data!$D:$D,MATCH(J$19,Data!$D:$D,0)+1),"")} | L19: {=IF(COUNTA($I$19:K$19)<COUNTIF(Data!$C:$C,"Swaps"),INDEX(Data!$D:$D,MATCH(K$19,Data!$D:$D,0)+1),"")} | M19: {=IF(COUNTA($I$19:L$19)<COUNTIF(Data!$C:$C,"Swaps"),INDEX(Data!$D:$D,MATCH(L$19,Data!$D:$D,0)+1),"")} | N19: {=IF(COUNTA($I$19:M$19)<COUNTIF(Data!$C:$C,"Swaps"),INDEX(Data!$D:$D,MATCH(M$19,Data!$D:$D,0)+1),"")} | O19: {=IF(COUNTA($I$19:N$19)<COUNTIF(Data!$C:$C,"Swaps"),INDEX(Data!$D:$D,MATCH(N$19,Data!$D:$D,0)+1),"")} | P19: {=IF(COUNTA($I$19:O$19)<COUNTIF(Data!$C:$C,"Swaps"),INDEX(Data!$D:$D,MATCH(O$19,Data!$D:$D,0)+1),"")} | Q19: {=IF(COUNTA($I$19:P$19)<COUNTIF(Data!$C:$C,"Swaps"),INDEX(Data!$D:$D,MATCH(P$19,Data!$D:$D,0)+1),"")} | ... BH19: {=IF(COUNTA($I$19:BG$19)<COUNTIF(Data!$C:$C,"Swaps"),INDEX(Data!$D:$D,MATCH(BG$19,Data!$D:$D,0)+1),"")} | BI19: {=IF(COUNTA($I$1:BH$1)<COUNTIF(Data!$C:$C,"Forward Rate Agreement"),INDEX(Data!$D:$D,MATCH(BH$1,Data!$D:$D,0)+1),"")} | BJ19: {=IF(COUNTA($I$1:BI$1)<COUNTIF(Data!$C:$C,"Forward Rate Agreements"),INDEX(Data!$D:$D,MATCH(BI$1,Data!$D:$D,0)+1),"")} | BK19: {=IF(COUNTA($I$1:BJ$1)<COUNTIF(Data!$C:$C,"Forward Rate Agreements"),INDEX(Data!$D:$D,MATCH(BJ$1,Data!$D:$D,0)+1),"")} | BL19: {=IF(COUNTA($I$1:BK$1)<COUNTIF(Data!$C:$C,"Forward Rate Agreements"),INDEX(Data!$D:$D,MATCH(BK$1,Data!$D:$D,0)+1),"")} | BM19: {=IF(COUNTA($I$1:BL$1)<COUNTIF(Data!$C:$C,"Forward Rate Agreements"),INDEX(Data!$D:$D,MATCH(BL$1,Data!$D:$D,0)+1),"")} | BN19: {=IF(COUNTA($I$1:BM$1)<COUNTIF(Data!$C:$C,"Forward Rate Agreements"),INDEX(Data!$D:$D,MATCH(BM$1,Data!$D:$D,0)+1),"")} | BO19: {=IF(COUNTA($I$1:BN$1)<COUNTIF(Data!$C:$C,"Forward Rate Agreements"),INDEX(Data!$D:$D,MATCH(BN$1,Data!$D:$D,0)+1),"")} | BP19: {=IF(COUNTA($I$1:BO$1)<COUNTIF(Data!$C:$C,"Forward Rate Agreements"),INDEX(Data!$D:$D,MATCH(BO$1,Data!$D:$D,0)+1),"")} | BQ19: {=IF(COUNTA($I$1:BP$1)<COUNTIF(Data!$C:$C,"Swaps"),INDEX(Data!$D:$D,MATCH(BP$1,Data!$D:$D,0)+1),"")} | BR19: {=IF(COUNTA($I$1:BQ$1)<COUNTIF(Data!$C:$C,"Swaps"),INDEX(Data!$D:$D,MATCH(BQ$1,Data!$D:$D,0)+1),"")} | BS19: {=IF(COUNTA($I$1:BR$1)<COUNTIF(Data!$C:$C,"Swaps"),INDEX(Data!$D:$D,MATCH(BR$1,Data!$D:$D,0)+1),"")} | BT19: {=IF(COUNTA($I$1:BS$1)<COUNTIF(Data!$C:$C,"Swaps"),INDEX(Data!$D:$D,MATCH(BS$1,Data!$D:$D,0)+1),"")} | BU19: {=IF(COUNTA($I$1:BT$1)<COUNTIF(Data!$C:$C,"Swaps"),INDEX(Data!$D:$D,MATCH(BT$1,Data!$D:$D,0)+1),"")} | BV19: {=IF(COUNTA($I$1:BU$1)<COUNTIF(Data!$C:$C,"Swaps"),INDEX(Data!$D:$D,MATCH(BU$1,Data!$D:$D,0)+1),"")} | BW19: {=IF(COUNTA($I$1:BV$1)<COUNTIF(Data!$C:$C,"Swaps"),INDEX(Data!$D:$D,MATCH(BV$1,Data!$D:$D,0)+1),"")}
E20: =$C6*100 -> #DIV/0! | F20: ="Cash, including cash value of options, available for long cover"&IF($A3="UT","",", and including underlying UT cash") -> Cash, including cash value of options, available for long cover | H20: =SUM(I20:BH20) -> 0 | I20: =IF(I$19="","",INDEX(Data!$AH:$AH,MATCH(I$19,Data!$D:$D,0))/$B$4) | J20: =IF(J$19="","",INDEX(Data!$AH:$AH,MATCH(J$19,Data!$D:$D,0))/$B$4) | K20: =IF(K$19="","",INDEX(Data!$AH:$AH,MATCH(K$19,Data!$D:$D,0))/$B$4) | L20: =IF(L$19="","",INDEX(Data!$AH:$AH,MATCH(L$19,Data!$D:$D,0))/$B$4) | M20: =IF(M$19="","",INDEX(Data!$AH:$AH,MATCH(M$19,Data!$D:$D,0))/$B$4) | N20: =IF(N$19="","",INDEX(Data!$AH:$AH,MATCH(N$19,Data!$D:$D,0))/$B$4) | O20: =IF(O$19="","",INDEX(Data!$AH:$AH,MATCH(O$19,Data!$D:$D,0))/$B$4) | P20: =IF(P$19="","",INDEX(Data!$AH:$AH,MATCH(P$19,Data!$D:$D,0))/$B$4) | ... BH20: =IF(BH$19="","",INDEX(Data!$AH:$AH,MATCH(BH$19,Data!$D:$D,0))/$B$4)
E21: =MIN(0,$H$11*100) -> 0 | F21: ="Net "&IF(E21<0,"short","long")&" currency derivatives, so "&IF(E21<0,"adequate","no")&" cash cover required" -> Net long currency derivatives, so no cash cover required
A22: =IF(B22>=0,"A","Ina")&"dequate cash cover for currency derivatives" -> #VALUE! | B22: =B6+B13+B16 -> #VALUE! | C22: =C6+C13+C16 -> #DIV/0! | E22: =SUM(E20:E21) -> #DIV/0! | F22: =IF($E22>=0,"Adequate","INADEQUATE")&" currency future cover [BN90 16(1)(i)]" -> #DIV/0! | H22: ="FRAs ("&COUNTIF(Data!$C:$C,"Forward Rate Agreement")&")" -> FRAs (0) | I22: =IF(ISNA(IF(ISNA(MATCH("Forward Rate Agreement",Data!$C:$C,0)),"",INDEX(Data!$D:$D,MATCH("Forward Rate Agreement",Data!$C:$C,0)))),"",IF(ISNA(MATCH("Forward Rate Agreement",Data!$C:$C,0)),"",INDEX(Data!$D:$D,MATCH("Forward Rate Agreement",Data!$C:$C,0)))) | J22: {=IF(COUNTA($I$22:I$22)<COUNTIF(Data!$C:$C,"Forward Rate Agreement"),INDEX(Data!$D:$D,MATCH(I$22,Data!$D:$D,0)+1),"")} | K22: {=IF(COUNTA($I$22:J$22)<COUNTIF(Data!$C:$C,"Forward Rate Agreement"),INDEX(Data!$D:$D,MATCH(J$22,Data!$D:$D,0)+1),"")} | L22: {=IF(COUNTA($I$22:K$22)<COUNTIF(Data!$C:$C,"Forward Rate Agreement"),INDEX(Data!$D:$D,MATCH(K$22,Data!$D:$D,0)+1),"")} | M22: {=IF(COUNTA($I$22:L$22)<COUNTIF(Data!$C:$C,"Forward Rate Agreement"),INDEX(Data!$D:$D,MATCH(L$22,Data!$D:$D,0)+1),"")} | N22: {=IF(COUNTA($I$22:M$22)<COUNTIF(Data!$C:$C,"Forward Rate Agreement"),INDEX(Data!$D:$D,MATCH(M$22,Data!$D:$D,0)+1),"")} | O22: {=IF(COUNTA($I$22:N$22)<COUNTIF(Data!$C:$C,"Forward Rate Agreement"),INDEX(Data!$D:$D,MATCH(N$22,Data!$D:$D,0)+1),"")} | P22: {=IF(COUNTA($I$22:O$22)<COUNTIF(Data!$C:$C,"Forward Rate Agreement"),INDEX(Data!$D:$D,MATCH(O$22,Data!$D:$D,0)+1),"")} | Q22: {=IF(COUNTA($I$22:P$22)<COUNTIF(Data!$C:$C,"Forward Rate Agreement"),INDEX(Data!$D:$D,MATCH(P$22,Data!$D:$D,0)+1),"")} | ... BH22: {=IF(COUNTA($I$22:BG$22)<COUNTIF(Data!$C:$C,"Forward Rate Agreement"),INDEX(Data!$D:$D,MATCH(BG$22,Data!$D:$D,0)+1),"")}
E23: =MIN(0,$H$14*100) -> 0 | F23: ="Net "&IF($E23>0,"positive","negative")&" MtM OTC forwards, so "&IF($E23>0,"no ","")&"cash cover required" -> Net negative MtM OTC forwards, so cash cover required | H23: =SUM(I23:BH23) -> 0 | I23: =IF(I$22="","",INDEX(Data!$AH:$AH,MATCH(I$22,Data!$D:$D,0))/$B$4) | J23: =IF(J$22="","",INDEX(Data!$AH:$AH,MATCH(J$22,Data!$D:$D,0))/$B$4) | K23: =IF(K$22="","",INDEX(Data!$AH:$AH,MATCH(K$22,Data!$D:$D,0))/$B$4) | L23: =IF(L$22="","",INDEX(Data!$AH:$AH,MATCH(L$22,Data!$D:$D,0))/$B$4) | M23: =IF(M$22="","",INDEX(Data!$AH:$AH,MATCH(M$22,Data!$D:$D,0))/$B$4) | N23: =IF(N$22="","",INDEX(Data!$AH:$AH,MATCH(N$22,Data!$D:$D,0))/$B$4) | O23: =IF(O$22="","",INDEX(Data!$AH:$AH,MATCH(O$22,Data!$D:$D,0))/$B$4) | P23: =IF(P$22="","",INDEX(Data!$AH:$AH,MATCH(P$22,Data!$D:$D,0))/$B$4) | ... BH23: =IF(BH$22="","",INDEX(Data!$AH:$AH,MATCH(BH$22,Data!$D:$D,0))/$B$4)
A24: less Bought futures or calls & sold puts to be covered by cash [BN90 16(1)(c)] | B24: =SUM(B25:B30) -> #VALUE! | C24: =SUM(C25:C30) -> #DIV/0! | E24: =MIN(0,B18/B$4)*100 -> #VALUE! | F24: ="Net "&IF($E24>0,"positive","negative")&" MtM OTC swaps, so "&IF($E24>0,"no ","")&"cash cover required" -> #VALUE!
A25: Equity Derivatives | B25: =IF(SUMIF(Data!$C:$C,"Equity Derivatives",Data!$AH:$AH)>=0,SUMIF(Data!$C:$C,"Equity Derivatives",Data!$AH:$AH),0) -> 0 | C25: =$B25/$B$4 -> #DIV/0! | E25: =MIN(0,B19/B$4)*100 -> #VALUE! | F25: ="Net "&IF($E25>0,"positive","negative")&" MtM OTC FRAs, so "&IF($E25>0,"no ","")&"cash cover required" -> #VALUE!
A26: excl MtM P&L on internationally listed derivatives | B26: =IF($H$5=0,0,-SUMIF(Data!$B:$B,"DERIVATIVES",Data!$AH:$AH)-SUMIF(Data!$B:$B,"UNKNOWN",Data!$AH:$AH)) -> 0 | C26: =$B26/$B$4 -> #DIV/0! | E26: =SUM(E22:E24) -> #DIV/0! | F26: =IF($E26>=0,"Adequate","INADEQUATE")&" OTC currency forward and swap cover [BN90 17(1)(a)]" -> #DIV/0!
A27: Effective equity exposure from swaps | B27: {=SUMPRODUCT((Data!$C$2:$C$1000="SWAPS")*((Data!$G$2:$G$1000)*(Data!$M$2:$M$1000))>0)} -> #VALUE! | C27: =$B27/$B$4 -> #VALUE! | E27: =MAX(0,($H$2+$H$5+C26)*100) -> #DIV/0! | F27: ="Net "&IF(E27>=0,"long","short")&" equity index, so adequate "&IF(E27>=0,"cash","similar asset")&" cover required" -> #DIV/0!
A28: excl MtM P&L on OTC swaps | B28: {=-SUMPRODUCT((Data!$C$2:$C$1000="SWAPS")*((Data!$AH$2:$AH$1000)))} -> 0 | C28: =$B28/$B$4 -> #DIV/0! | E28: =MAX(0,$H$8*100) -> 0 | F28: ="Net "&IF(E28>=0,"long","short")&" bond index, so adequate "&IF(E28>=0,"cash","similar asset")&" cover required" -> Net long bond index, so adequate cash cover required
A29: Currency Derivatives | B29: =IF(SUMIF(Data!$C:$C,$A29,Data!$AH:$AH)>=0,SUMIF(Data!$C:$C,$A29,Data!$AH:$AH),0) -> 0 | C29: =$B29/$B$4 -> #DIV/0!
A30: Bond Derivatives | B30: =IF(SUMIF(Data!$C:$C,$A30,Data!$AH:$AH)>=0,SUMIF(Data!$C:$C,$A30,Data!$AH:$AH),0) -> 0 | C30: =$B30/$B$4 -> #DIV/0! | E30: =SUM(C27:C28)*100 -> #VALUE! | F30: Effective equity exposure from swaps, after MtM
A32: =IF($A3="UT","","Cash from the "&COUNTIF(Data!$B:$B,"COLLECTIVE INVESTMENT SCHEMES")&" underlying UT"&IF(COUNTIF(Data!$B:$B,"COLLECTIVE INVESTMENT SCHEMES")=1,"","s")) | B32: =IF($A$3="UT",0,SUMIF(Data!$B:$B,"COLLECTIVE INVESTMENT SCHEMES",Data!$AH:$AH)) -> 0 | C32: =IF($A3="UT",0,$B32/$B$4) -> 0 | E32: =C32*100 -> 0
A34: =IF(B34>=0,"A","Ina")&"dequate cash cover for derivatives" -> #VALUE! | B34: =B22-B24+B32 -> #VALUE! | C34: =C22-C24+C32 -> #DIV/0! | E34: =E26-E27-E28-E29-E30+E32 -> #DIV/0! | F34: =IF($E34>=0,"Adequate","INADEQUATE")&" long derivative cash cover [BN90 16(1)(c)]" -> #DIV/0!
A36: =IF($A3="UT","The numbers above exclude these assets which don't qualify as AiLF for UTs: *","") -> The numbers above exclude these assets which don't qualify as AiLF for UTs: * | B36: =IF($A3="UT",SUM(B37:B38),"") -> 0 | C36: =IF($A3="UT",SUM(C37:C38),"") -> #DIV/0!
A37: =IF($A3="UT","Money Market","") -> Money Market | B37: {=IF($A3="UT",SUMIF(Data!$B:$B,"MONEY MARKET",Data!$AH:$AH)-SUMPRODUCT((Data!$B:$B="MONEY MARKET")*((Data!$P:$P<Data!$AJ$2+397)*(Data!$V:$V<>"CLN")),(Data!$AH:$AH)),"")} -> 0 | C37: =IF($A3="UT",B37/$B$4,"") -> #DIV/0!
A38: =IF($A3="UT","Bonds","") -> Bonds | B38: {=IF($A3="UT",SUMIF(Data!$B:$B,"BONDS",Data!$AH:$AH)-SUMPRODUCT((Data!$B:$B="BONDS")*((Data!$P:$P<Data!$AJ$2+397)*(Data!$V:$V<>"CLN")),(Data!$AH:$AH)),"")} -> 0 | C38: =IF($A3="UT",B38/$B$4,"") -> #DIV/0!
A40: Total equity, incl property equity | B40: =B42+B50 -> #VALUE! | C40: =C42+C50 -> #DIV/0!
A42: Total non-property equity | B42: =SUM(B43:B48) -> #VALUE! | C42: =SUM(C43:C48) -> #DIV/0!
A43: Equity futures and options | B43: {=SUMPRODUCT(('Glbl Expsr'!$H$2:$H$68)*('Glbl Expsr'!$I$2:$I$68)*('Glbl Expsr'!$J$2:$J$68)*('Glbl Expsr'!$L$2:$L$68)*('Glbl Expsr'!$O$2:$O$68))+$B$26} -> 0 | C43: {=SUMPRODUCT(('Glbl Expsr'!$H$2:$H$68)*('Glbl Expsr'!$I$2:$I$68)*('Glbl Expsr'!$J$2:$J$68)*('Glbl Expsr'!$L$2:$L$68)*('Glbl Expsr'!$O$2:$O$68))/SUM(Data!$L:$L)+$C$26} -> #DIV/0!
A44: Equity linked notes | B44: {=SUMPRODUCT(--(Data!$C$2:$C$1000="EQUITY LINKED NOTES"), (Data!$AH$2:$AH$1000))} -> 0 | C44: {=SUMPRODUCT(--(Data!$C$2:$C$1000="EQUITY LINKED NOTES"),(Data!$AI2:$AI1000))/100} -> 0
A45: Equity TRSs | B45: {=SUMPRODUCT((Data!$C$2:$C$1000="SWAPS")*((Data!$G$2:$G$1000)*(Data!$M$2:$M$1000)))} -> #VALUE! | C45: {=SUMPRODUCT((Data!$C$2:$C$1000="SWAPS")*((Data!$G$2:$G$1000)*(Data!$M$2:$M$1000)))/SUM(Data!$L:$L)} -> #VALUE!
A46: Direct equities, excl direct property equity | B46: {=SUMPRODUCT((Data!$B:$B="EQUITIES")*(Data!$X:$X<>"REAL ESTATE")*(Data!$V:$V<>"EQUITY - ELN"),(Data!$AH:$AH))} -> 0 | C46: {=SUMPRODUCT((Data!$B:$B="EQUITIES")*(Data!$X:$X<>"REAL ESTATE")*(Data!$V:$V<>"EQUITY - ELN"),(Data!$AI:$AI))/100} -> 0
...

Sheet Glbl Expsr
A1: =Data!$A$2&" ("&Data!$AK$2&") Exposures "&TEXT(Data!$AJ$2,"d mmm yy") -> 0 (44676) Exposures 0 Jan 00 | C1: ZAR | D1: % NAV | F1: =_xlfn.XLOOKUP(Data!$AK$2,[77]Funds!$A:$A,[77]Funds!$E:$E) -> #N/A | G1: {="SA Equity Derivatives ("&SUMPRODUCT((Data!$C:$C="Equity Derivatives")*(Data!$W:$W="ZAR"))&")"} -> SA Equity Derivatives (0) | H1: Contracts Held | I1: Multiplier | J1: Market Price | K1: Nominal Exposure | L1: Delta | M1: Effective Exposure | N1: Gross Effective Exposure (%) | O1: Forex rate
A2: Global exposure (sum of the absolute effective exposures) | B2: a | C2: {=SUMPRODUCT(ABS(($H$2:$H$68))*($I$2:$I$68)*ABS(($J$2:$J$68))*ABS(($L$2:$L$68))*(O2:O68))+Summary!$B$26} -> 0 | D2: {=SUMPRODUCT(ABS(($H$2:$H$68))*($I$2:$I$68)*ABS(($J$2:$J$68))*ABS(($L$2:$L$68))*(O2:O68))/SUM(Data!$L:$L)+Summary!$C$26} -> #DIV/0! | G2: =Summary!I$1 | H2: =IF($G2<>"",INDEX(Data!$G:$G,MATCH($G2,Data!$D:$D,0)),0) -> 0 | I2: =IF($G2<>"",10,0) -> 0 | J2: =IF($G2<>"",INDEX(Data!$M:$M,MATCH($G2,Data!$D:$D,0)),0) -> 0 | K2: =PRODUCT($H2:$J2)*$O$53 -> 0 | L2: =IF($G2<>"",INDEX(Deltas!$E:$E,MATCH($G2,Deltas!$B:$B,0)),0) -> 0 | M2: =PRODUCT($H2:$J2,$L2) -> 0 | N2: =ABS(PRODUCT($H2:$J2,$L2))/Summary!$B$4*$O$53 -> #DIV/0! | O2: 1
A3: Net effective exposure (sum of the net effective exposures) | B3: b | C3: {=SUMPRODUCT(($H$2:$H$68)*($I$2:$I$68)*($J$2:$J$68)*($L$2:$L$68)*($O$2:$O$68))+Summary!$B$26} -> 0 | D3: {=SUMPRODUCT(($H$2:$H$68)*($I$2:$I$68)*($J$2:$J$68)*($L$2:$L$68)*($O$2:$O$68))/SUM(Data!$L:$L)+Summary!$C$26} -> #DIV/0! | G3: =Summary!J$1 | H3: =IF($G3<>"",INDEX(Data!$G:$G,MATCH($G3,Data!$D:$D,0)),0) -> 0 | I3: =IF($G3<>"",10,0) -> 0 | J3: =IF($G3<>"",INDEX(Data!$M:$M,MATCH($G3,Data!$D:$D,0)),0) -> 0 | K3: =PRODUCT($H3:$J3)*$O$53 -> 0 | L3: =IF($G3<>"",INDEX(Deltas!$E:$E,MATCH($G3,Deltas!$B:$B,0)),0) -> 0 | M3: =PRODUCT($H3:$J3,$L3) -> 0 | N3: =ABS(PRODUCT($H3:$J3,$L3))/Summary!$B$4*$O$53 -> #DIV/0! | O3: 1
A4: Liquid assets | B4: c | C4: =Summary!$B6 -> 0 | D4: =Summary!$B6/SUM(Data!$L:$L) -> #DIV/0! | G4: =Summary!K$1 | H4: =IF($G4<>"",INDEX(Data!$G:$G,MATCH($G4,Data!$D:$D,0)),0) -> 0 | I4: =IF($G4<>"",10,0) -> 0 | J4: =IF($G4<>"",INDEX(Data!$M:$M,MATCH($G4,Data!$D:$D,0)),0) -> 0 | K4: =PRODUCT($H4:$J4)*$O$53 -> 0 | L4: =IF($G4<>"",INDEX(Deltas!$E:$E,MATCH($G4,Deltas!$B:$B,0)),0) -> 0 | M4: =PRODUCT($H4:$J4,$L4) -> 0 | N4: =ABS(PRODUCT($H4:$J4,$L4))/Summary!$B$4*$O$53 -> #DIV/0! | O4: 1
A5: Liquid assets and collective investment schemes | B5: d | C5: =Summary!$B6+SUMIF(Data!$B:$B,"COLLECTIVE INVESTMENT SCHEMES",Data!$AH:$AH) -> 0 | D5: =(Summary!$B6+SUMIF(Data!$B:$B,"COLLECTIVE INVESTMENT SCHEMES",Data!$AH:$AH))/SUM(Data!$L:$L) -> #DIV/0! | G5: =Summary!L$1 | H5: =IF($G5<>"",INDEX(Data!$G:$G,MATCH($G5,Data!$D:$D,0)),0) -> 0 | I5: =IF($G5<>"",10,0) -> 0 | J5: =IF($G5<>"",INDEX(Data!$M:$M,MATCH($G5,Data!$D:$D,0)),0) -> 0 | K5: =PRODUCT($H5:$J5)*$O$53 -> 0 | L5: =IF($G5<>"",INDEX(Deltas!$E:$E,MATCH($G5,Deltas!$B:$B,0)),0) -> 0 | M5: =PRODUCT($H5:$J5,$L5) -> 0 | N5: =ABS(PRODUCT($H5:$J5,$L5))/Summary!$B$4*$O$53 -> #DIV/0! | O5: 1
G6: =Summary!M$1 | H6: =IF($G6<>"",INDEX(Data!$G:$G,MATCH($G6,Data!$D:$D,0)),0) -> 0 | I6: =IF($G6<>"",10,0) -> 0 | J6: =IF($G6<>"",INDEX(Data!$M:$M,MATCH($G6,Data!$D:$D,0)),0) -> 0 | K6: =PRODUCT($H6:$J6)*$O$53 -> 0 | L6: =IF($G6<>"",INDEX(Deltas!$E:$E,MATCH($G6,Deltas!$B:$B,0)),0) -> 0 | M6: =PRODUCT($H6:$J6,$L6) -> 0 | N6: =ABS(PRODUCT($H6:$J6,$L6))/Summary!$B$4*$O$53 -> #DIV/0! | O6: 1
A7: Liquid asset cover over global exposure (must be > 100%) | B7: c ÷ a | C7: =IF(C2=0,1,C4/C2) -> 1 | D7: =D4-D2 -> #DIV/0! | E7: c - a | G7: =Summary!N$1 | H7: =IF($G7<>"",INDEX(Data!$G:$G,MATCH($G7,Data!$D:$D,0)),0) -> 0 | I7: =IF($G7<>"",10,0) -> 0 | J7: =IF($G7<>"",INDEX(Data!$M:$M,MATCH($G7,Data!$D:$D,0)),0) -> 0 | K7: =PRODUCT($H7:$J7)*$O$53 -> 0 | L7: =IF($G7<>"",INDEX(Deltas!$E:$E,MATCH($G7,Deltas!$B:$B,0)),0) -> 0 | M7: =PRODUCT($H7:$J7,$L7) -> 0 | N7: =ABS(PRODUCT($H7:$J7,$L7))/Summary!$B$4*$O$53 -> #DIV/0! | O7: 1
A8: Liquid asset cover over net effective exposure (must be > 100%) | B8: c ÷ b | C8: =IF(C3=0,1,C4/C3) -> 1 | D8: =D4-D3 -> #DIV/0! | E8: c - b | G8: =Summary!O$1 | H8: =IF($G8<>"",INDEX(Data!$G:$G,MATCH($G8,Data!$D:$D,0)),0) -> 0 | I8: =IF($G8<>"",10,0) -> 0 | J8: =IF($G8<>"",INDEX(Data!$M:$M,MATCH($G8,Data!$D:$D,0)),0) -> 0 | K8: =PRODUCT($H8:$J8)*$O$53 -> 0 | L8: =IF($G8<>"",INDEX(Deltas!$E:$E,MATCH($G8,Deltas!$B:$B,0)),0) -> 0 | M8: =PRODUCT($H8:$J8,$L8) -> 0 | N8: =ABS(PRODUCT($H8:$J8,$L8))/Summary!$B$4*$O$53 -> #DIV/0! | O8: 1
G9: =Summary!P$1 | H9: =IF($G9<>"",INDEX(Data!$G:$G,MATCH($G9,Data!$D:$D,0)),0) -> 0 | I9: =IF($G9<>"",10,0) -> 0 | J9: =IF($G9<>"",INDEX(Data!$M:$M,MATCH($G9,Data!$D:$D,0)),0) -> 0 | K9: =PRODUCT($H9:$J9)*$O$53 -> 0 | L9: =IF($G9<>"",INDEX(Deltas!$E:$E,MATCH($G9,Deltas!$B:$B,0)),0) -> 0 | M9: =PRODUCT($H9:$J9,$L9) -> 0 | N9: =ABS(PRODUCT($H9:$J9,$L9))/Summary!$B$4*$O$53 -> #DIV/0! | O9: 1
A10: Liquid asset cover, incl CISes, over net effective exposure (must be > 100%) | B10: d ÷ a | C10: =IF(C2=0,1,C5/C2) -> 1 | D10: =D5-D2 -> #DIV/0! | E10: d - a | G10: =Summary!Q$1 | H10: =IF($G10<>"",INDEX(Data!$G:$G,MATCH($G10,Data!$D:$D,0)),0) -> 0 | I10: =IF($G10<>"",10,0) -> 0 | J10: =IF($G10<>"",INDEX(Data!$M:$M,MATCH($G10,Data!$D:$D,0)),0) -> 0 | K10: =PRODUCT($H10:$J10)*$O$53 -> 0 | L10: =IF($G10<>"",INDEX(Deltas!$E:$E,MATCH($G10,Deltas!$B:$B,0)),0) -> 0 | M10: =PRODUCT($H10:$J10,$L10) -> 0 | N10: =ABS(PRODUCT($H10:$J10,$L10))/Summary!$B$4*$O$53 -> #DIV/0! | O10: 1
