Workbook

Sheet Process
A1: PROCESS | G1: =HYPERLINK("\\fileserver.prescient.local\pim-business\Business Practice\PGF UCITS Share Class Hedges","Shares Classes Folder") -> Shares Classes Folder | Z1: py | AA1: Unit trust prices | AB1: PAR-N | AC1: Date
A2: 1) Unit Trust Prices: Queries -> Unit Trust Pricing -> Unit Trust Prices (PGPCGED, PGPGBFD, PGPGIFE, PGPGIFI, PGPRFE, PGPRFG, PGPCEMD) | E2: Fund Hedge Instrument | G2: =HYPERLINK("http://www.irishstatutebook.ie/eli/2013/si/257/made/en/print","SI 257 of 2013 EU (AIFM) Regulation 2013") -> SI 257 of 2013 EU (AIFM) Regulation 2013 | AA2: PGPCEMD | AB2: PGPRUSD | AC2: 45167
A3: Get UTP for PGPCxxx | B3: PGPCEMD, PGPCGED | E3: =_xlfn.XLOOKUP($B3,$D$12:$D$22,$B$12:$B$22) -> #N/A | AA3: PGPCGED | AB3: PGPRZAR
A4: Get UTP for PGPGBxx | B4: PGPGBFD | E4: =_xlfn.XLOOKUP($B4,$D$12:$D$22,$B$12:$B$22) -> PGBEUR, PGBGBP, PGBZAR | AA4: PGPGBFD | AB4: PGPRUS0%
A5: Get UTP for PGPGIxx | B5: PGPGIFE, PGPGIFI | E5: =_xlfn.XLOOKUP($B5,$D$12:$D$22,$B$12:$B$22) -> PGIPZAR, PGIP_I | AA5: PGPGIFE | AB5: PGPRGBP
A6: Get UTP for PGPRFxx | B6: PGPRFE, PGPRFG | E6: =_xlfn.XLOOKUP($B6,$D$12:$D$22,$B$12:$B$22) -> PGPRUSD, PGPRZAR, PGPRUS0%,PGPRGBP | AA6: PGPGIFI | AB6: PGIPZAR
AA7: PGPRFE | AB7: PGIP_I
AA8: PGPRFG | AB8: PGPCZAR
AB9: PGBEUR
G10: =HYPERLINK("http://www.irishstatutebook.ie/eli/2015/si/420/made/en/print","SI 420 of 2015 CBoI UCITS Regulations 2015") -> SI 420 of 2015 CBoI UCITS Regulations 2015 | AB10: PGBGBP
A11: 2) Class holdings: Queries -> Portfolios -> Portfolio Analytics Report -> New | B11: Fund Hedge Instrument | C11: Fund | D11: Fund Share Class | E11: Fund Name | G11: =HYPERLINK("https://www.centralbank.ie/docs/default-source/publications/Consultation-Papers/CP27/gn-399-share-classes---hedging-against-exchange-rate-movements.pdf?sfvrsn=2","UCITS share class hedging GN3/99") -> UCITS share class hedging GN3/99 | AB11: PGBZAR
A12: Get PAR-N for classes with PGPRxxx | B12: PGPRUSD, PGPRZAR, PGPRUS0%,PGPRGBP | C12: PGPRF_C | D12: PGPRFE, PGPRFG | E12: Prescient Global Positive Return Fund | G12: =HYPERLINK("\\pim-cpt-statpro\SPC_602\Client\Profiles\PIM\Exports\PGF ICAV Hedged Classes 12Nov2020.xlsx","ICAV Hedge Classes 12Nov 2020") -> ICAV Hedge Classes 12Nov 2020 | AB12: PGEMZAR
A13: Get PAR-N for classes with PGIPxxx | B13: PGIPZAR, PGIP_I | C13: PGPGIF_C | D13: PGPGIFE, PGPGIFI | E13: Prescient Global Income Provider Fund
A14: Get PAR-N for classes with PGPCxxx | B14: PGPCZAR | C14: PGPCGE_C | D14: PGPCGED | E14: Prescient Core Global Equity Fund
A15: Get PAR-N for classes with PGBxxx | B15: PGBEUR, PGBGBP, PGBZAR | C15: PGPGBF_C | D15: PGPGBFD | E15: Prescient Global Balanced Fund
A16: Get PAR-N for classes with PGEMxxx | B16: PGEMZAR | C16: PGPCEM | D16: PGPCEMD | E16: Prescient Core Global Emerging Markets Equity Fund | F16: added 27 Sep 2022
A17: - | B17: - | C17: PCGEARF | D17: - | E17: Prescient China Growth Enhanced Absolute Return Fund
A18: - | B18: - | C18: PGCEF | D18: - | E18: Prescient China Equity Fund
A19: - | B19: - | C19: PGCBF | D19: - | E19: Prescient China Balanced Fund
A20: - | B20: - | C20: PGCCF (terminating) | D20: - | E20: Prescient China Conservative Fund
A21: - | B21: - | C21: PGPGGF (terminating) | D21: - | E21: Prescient Global Equity Fund
A22: - | B22: - | C22: QIFFGIF (QIAIF) | D22: - | E22: Prescient Flexible Global Income (USD) Fund
B24: Fund Hedge Instrument | C24: Fund Share Class | D24: Fund | E24: Fund Name
B25: PGPRUSD | C25: PGPRFE | D25: PGPRF_C | E25: Prescient Global Positive Return Fund
B26: PGPRZAR | C26: PGPRFG | D26: PGPRF_C | E26: Prescient Global Positive Return Fund
B27: PGPRUS0% | C27: PGPRFI | D27: PGPRF_C | E27: Prescient Global Positive Return Fund
B28: PGPRGBP | C28: PGPRFJ | D28: PGPRF_C | E28: Prescient Global Positive Return Fund
B29: PGIPZAR | C29: PGPGIFE | D29: PGPGIF_C | E29: Prescient Global Income Provider Fund
B30: PGIP_I | C30: PGPGIFI | D30: PGPGIF_C | E30: Prescient Global Income Provider Fund
B31: PGPCZAR | C31: PGPCGED | D31: PGPCGE_C | E31: =-'Class NAVs'!G11 -> 0
B32: PGBEUR | C32: PGPGBFG | D32: PGPGBF_C | E32: Prescient Global Balanced Fund
B33: PGBGBP | C33: PGPGBFF | D33: PGPGBF_C | E33: Prescient Global Balanced Fund
B34: PGBZAR | C34: PGPGBFD | D34: PGPGBF_C | E34: Prescient Global Balanced Fund
B35: PGEMZAR | C35: PGPCEMD | D35: PGPCEM_C | E35: Prescient Core Global Emerging Markets Equity Fund | F35: added 27 Sep 2022

Sheet Static
A1: Fund Names
A2: Funds | B2: Fund Name | C2: Note
A3: PGPRF_C | B3: Prescient Global Positive Return Fund
A4: PGPGIF_C | B4: Prescient Global Income Provider Fund
A5: PGPCGE_C | B5: Prescient Core Global Equity Fund
A6: PGPGBF_C | B6: Prescient Global Balanced Fund
A7: PGPCEM_C | B7: Prescient Core Global Emerging Markets Equity Fund
A8: PCGEARF | B8: Prescient China Growth Enhanced Absolute Return Fund
A9: PGCEF | B9: Prescient China Equity Fund
A10: PGCBF | B10: Prescient China Balanced Fund
A11: PGCCF | B11: Prescient China Conservative Fund | C11: terminating
A12: PGPGGF | B12: Prescient Global Equity Fund | C12: terminating
A13: QIFFGIF | B13: Prescient Flexible Global Income (USD) Fund | C13: QIAIF
D14: Hedge Classes
D15: Instrument | E15: Share Class | F15: Fund
D16: PGPRUSD | E16: PGPRFE | F16: PGPRF_C
D17: PGPRZAR | E17: PGPRFG | F17: PGPRF_C
D18: PGPRUS0% | E18: PGPRFI | F18: PGPRF_C
D19: PGPRGBP | E19: PGPRFJ | F19: PGPRF_C
D20: PGIPZAR | E20: PGPGIFE | F20: PGPGIF_C
D21: PGIP_I | E21: PGPGIFI | F21: PGPGIF_C
D22: PGPCZAR | E22: PGPCGED | F22: PGPCGE_C
D23: PGBEUR | E23: PGPGBFG | F23: PGPGBF_C
D24: PGBGBP | E24: PGPGBFF | F24: PGPGBF_C
D25: PGEMZAR | E25: PGPCEMD | F25: PGPCEM_C
D26: PGBZAR | E26: PGPGBFD | F26: PGPGBF_C

Sheet Summary
A1: Class | B1: Class Name | C1: EUR | D1: ZAR | E1: GBP | F1: USD | G1: Fund | H1: Class NAV | I1: ="Hedge Effectiveness "&TEXT('Class NAVs'!B2,"ddd d mmm yyyy") -> Hedge Effectiveness Wed 4 Oct 2023 | J1: ="Hedge Effectiveness "&TEXT('[1]Class NAVs'!$B$2,"ddd d mmm yyyy") -> Hedge Effectiveness Tue 3 Oct 2023 | K1: =HYPERLINK("\\PRE-CPT-FS\Profile-Documents$\PProfile Operations\Legal\Legal and Compliance Framework\Hilton\PFS Daily Compliance\2A - Fund Codes, Breach Register.xlsx","Team") -> Team | L1: Fund Name | M1: =HYPERLINK("P:\Investment Operations\GRC\Compliance\PGF UCITS Share Class Hedges","Folder") -> Folder | N1: Subject | O1: Content | P1: ="\\PIM-CPT-FS.prescient.local\PIM-Documents$\Investment Operations\GRC\Compliance\PGF UCITS Share Class Hedges\"&TEXT('Class NAVs'!B2,"yyyymmdd")&" PGF Share Class Hedges.xlsx" -> \\PIM-CPT-FS.prescient.local\PIM-Documents$\Investment Operations\GRC\Compliance\PGF UCITS Share Class Hedges\20231004 PGF Share Class Hedges.xlsx
A2: PGIPZAR | B2: =_xlfn.XLOOKUP($A2,'Portfolio Valuation'!$AK:$AK,'Portfolio Valuation'!$A:$A) -> Prescient Global Income Provid | C2: {=MAX(0,SUMPRODUCT(('Portfolio Valuation'!$AK:$AK=$A2)*('Portfolio Valuation'!$W:$W=C$1),'Portfolio Valuation'!$L:$L))} -> 0 | D2: {=MAX(0,SUMPRODUCT(('Portfolio Valuation'!$AK:$AK=$A2)*('Portfolio Valuation'!$W:$W=D$1),'Portfolio Valuation'!$L:$L))} -> 43941531 | E2: {=MAX(0,SUMPRODUCT(('Portfolio Valuation'!$AK:$AK=$A2)*('Portfolio Valuation'!$W:$W=E$1),'Portfolio Valuation'!$L:$L))} -> 0 | F2: {=MAX(0,SUMPRODUCT(('Portfolio Valuation'!$AK:$AK=$A2)*('Portfolio Valuation'!$W:$W=F$1),'Portfolio Valuation'!$L:$L))} -> 0 | G2: =SUBSTITUTE(_xlfn.XLOOKUP($A2,Static!$D:$D,Static!$F:$F),"_C","") -> PGPGIF | H2: =SUMIF('Class NAVs'!$C:$C,_xlfn.XLOOKUP($A2,Static!$D:$D,Static!$E:$E),'Class NAVs'!$H:$H) -> 43263314 | I2: =IF(H2=0,"Inactive share class",SUM(C2:F2)/H2) -> 1.0156765 | J2: =_xlfn.XLOOKUP($A2,[1]Summary!$A:$A,[1]Summary!$I:$I) -> 1.0161577 | K2: =_xlfn.XLOOKUP($G2,[2]Funds!$A:$A,[2]Funds!$D:$D) -> FxdInt | L2: =_xlfn.XLOOKUP(_xlfn.XLOOKUP($A2,Static!$D:$D,Static!$F:$F),Static!$A:$A,Static!$B:$B)&" ("&_xlfn.XLOOKUP($A2,Static!$D:$D,Static!$F:$F)&")" -> Prescient Global Income Provider Fund (PGPGIF_C) | M2: =IF(OR($I2<0.95,$I2>1.05),$G2&" "&RIGHT($A2,3)&" class","") | N2: ="PGF Share Class Hedging - "&TEXT('Class NAVs'!B2,"dddd d mmmm yyyy")&IF($M2=""," - ALL HEDGES ARE WITHIN THE REGULATORY LIMITS"," - "&UPPER($M2)&" IS "&IF($I2<0.95,"BELOW","ABOVE")&" THE REGULATORY LIMIT") -> PGF Share Class Hedging - Wednesday 4 October 2023 - ALL HEDGES ARE WITHIN THE REGULATORY LIMITS | O2: ="Please see below PIM's Prescient Global Funds share class hedges for "&TEXT('Class NAVs'!B2,"dddd d mmmm yyyy")&"; workings are stored here."&IF($M2="",""," Please advise regarding the "&$M2&" breach.") -> Please see below PIM's Prescient Global Funds share class hedges for Wednesday 4 October 2023; workings are stored here.
A3: PGPRUSD | B3: =_xlfn.XLOOKUP($A3,'Portfolio Valuation'!$AK:$AK,'Portfolio Valuation'!$A:$A) -> Pos Return Fund USD Sec | C3: {=MAX(0,SUMPRODUCT(('Portfolio Valuation'!$AK:$AK=$A3)*('Portfolio Valuation'!$W:$W=C$1),'Portfolio Valuation'!$L:$L))} -> 0 | D3: {=MAX(0,SUMPRODUCT(('Portfolio Valuation'!$AK:$AK=$A3)*('Portfolio Valuation'!$W:$W=D$1),'Portfolio Valuation'!$L:$L))} -> 0 | E3: {=MAX(0,SUMPRODUCT(('Portfolio Valuation'!$AK:$AK=$A3)*('Portfolio Valuation'!$W:$W=E$1),'Portfolio Valuation'!$L:$L))} -> 0 | F3: {=MAX(0,SUMPRODUCT(('Portfolio Valuation'!$AK:$AK=$A3)*('Portfolio Valuation'!$W:$W=F$1),'Portfolio Valuation'!$L:$L))} -> 230983.03 | G3: =SUBSTITUTE(_xlfn.XLOOKUP($A3,Static!$D:$D,Static!$F:$F),"_C","") -> PGPRF | H3: =SUMIF('Class NAVs'!$C:$C,_xlfn.XLOOKUP($A3,Static!$D:$D,Static!$E:$E),'Class NAVs'!$H:$H) -> 222951.81 | I3: =IF(H3=0,"Inactive share class",SUM(C3:F3)/H3) -> 1.0360222 | J3: =_xlfn.XLOOKUP($A3,[1]Summary!$A:$A,[1]Summary!$I:$I) -> 1.0363358 | K3: =_xlfn.XLOOKUP($G3,[2]Funds!$A:$A,[2]Funds!$D:$D) -> MultAsst | L3: =_xlfn.XLOOKUP(_xlfn.XLOOKUP($A3,Static!$D:$D,Static!$F:$F),Static!$A:$A,Static!$B:$B)&" ("&_xlfn.XLOOKUP($A3,Static!$D:$D,Static!$F:$F)&")" -> Prescient Global Positive Return Fund (PGPRF_C) | M3: =IF(OR($I3<0.95,$I3>1.05),$G3&" "&RIGHT($A3,3)&" class","") | N3: ="PGF Share Class Hedging - "&TEXT('Class NAVs'!B2,"dddd d mmmm yyyy")&IF($M3=""," - ALL HEDGES ARE WITHIN THE REGULATORY LIMITS"," - "&UPPER($M3)&" IS "&IF($I3<0.95,"BELOW","ABOVE")&" THE REGULATORY LIMIT") -> PGF Share Class Hedging - Wednesday 4 October 2023 - ALL HEDGES ARE WITHIN THE REGULATORY LIMITS | O3: ="Please see below PIM's Prescient Global Funds share class hedges for "&TEXT('Class NAVs'!B3,"dddd d mmmm yyyy")&"; workings are stored here."&IF($M3="",""," Please advise regarding the "&$M3&" breach.") -> Please see below PIM's Prescient Global Funds share class hedges for Wednesday 4 October 2023; workings are stored here.
A4: PGPRZAR | B4: =_xlfn.XLOOKUP($A4,'Portfolio Valuation'!$AK:$AK,'Portfolio Valuation'!$A:$A) -> Pos Return Fund ZAR Sec | C4: {=MAX(0,SUMPRODUCT(('Portfolio Valuation'!$AK:$AK=$A4)*('Portfolio Valuation'!$W:$W=C$1),'Portfolio Valuation'!$L:$L))} -> 0 | D4: {=MAX(0,SUMPRODUCT(('Portfolio Valuation'!$AK:$AK=$A4)*('Portfolio Valuation'!$W:$W=D$1),'Portfolio Valuation'!$L:$L))} -> 3350094.9 | E4: {=MAX(0,SUMPRODUCT(('Portfolio Valuation'!$AK:$AK=$A4)*('Portfolio Valuation'!$W:$W=E$1),'Portfolio Valuation'!$L:$L))} -> 0 | F4: {=MAX(0,SUMPRODUCT(('Portfolio Valuation'!$AK:$AK=$A4)*('Portfolio Valuation'!$W:$W=F$1),'Portfolio Valuation'!$L:$L))} -> 0 | G4: =SUBSTITUTE(_xlfn.XLOOKUP($A4,Static!$D:$D,Static!$F:$F),"_C","") -> PGPRF | H4: =SUMIF('Class NAVs'!$C:$C,_xlfn.XLOOKUP($A4,Static!$D:$D,Static!$E:$E),'Class NAVs'!$H:$H) -> 3280284.7 | I4: =IF(H4=0,"Inactive share class",SUM(C4:F4)/H4) -> 1.0212818 | J4: =_xlfn.XLOOKUP($A4,[1]Summary!$A:$A,[1]Summary!$I:$I) -> 1.0215677 | K4: =_xlfn.XLOOKUP($G4,[2]Funds!$A:$A,[2]Funds!$D:$D) -> MultAsst | L4: =_xlfn.XLOOKUP(_xlfn.XLOOKUP($A4,Static!$D:$D,Static!$F:$F),Static!$A:$A,Static!$B:$B)&" ("&_xlfn.XLOOKUP($A4,Static!$D:$D,Static!$F:$F)&")" -> Prescient Global Positive Return Fund (PGPRF_C) | M4: =IF(OR($I4<0.95,$I4>1.05),$G4&" "&RIGHT($A4,3)&" class","") | N4: ="PGF Share Class Hedging - "&TEXT('Class NAVs'!B2,"dddd d mmmm yyyy")&IF($M4=""," - ALL HEDGES ARE WITHIN THE REGULATORY LIMITS"," - "&UPPER($M4)&" IS "&IF($I4<0.95,"BELOW","ABOVE")&" THE REGULATORY LIMIT") -> PGF Share Class Hedging - Wednesday 4 October 2023 - ALL HEDGES ARE WITHIN THE REGULATORY LIMITS | O4: ="Please see below PIM's Prescient Global Funds share class hedges for "&TEXT('Class NAVs'!B4,"dddd d mmmm yyyy")&"; workings are stored here."&IF($M4="",""," Please advise regarding the "&$M4&" breach.") -> Please see below PIM's Prescient Global Funds share class hedges for Wednesday 4 October 2023; workings are stored here.
A5: PGBZAR | B5: =_xlfn.XLOOKUP($A5,'Portfolio Valuation'!$AK:$AK,'Portfolio Valuation'!$A:$A) -> Prescient Global Balanced Zar | C5: {=MAX(0,SUMPRODUCT(('Portfolio Valuation'!$AK:$AK=$A5)*('Portfolio Valuation'!$W:$W=C$1),'Portfolio Valuation'!$L:$L))} -> 0 | D5: {=MAX(0,SUMPRODUCT(('Portfolio Valuation'!$AK:$AK=$A5)*('Portfolio Valuation'!$W:$W=D$1),'Portfolio Valuation'!$L:$L))} -> 22991427 | E5: {=MAX(0,SUMPRODUCT(('Portfolio Valuation'!$AK:$AK=$A5)*('Portfolio Valuation'!$W:$W=E$1),'Portfolio Valuation'!$L:$L))} -> 0 | F5: {=MAX(0,SUMPRODUCT(('Portfolio Valuation'!$AK:$AK=$A5)*('Portfolio Valuation'!$W:$W=F$1),'Portfolio Valuation'!$L:$L))} -> 0 | G5: =SUBSTITUTE(_xlfn.XLOOKUP($A5,Static!$D:$D,Static!$F:$F),"_C","") -> PGPGBF | H5: =SUMIF('Class NAVs'!$C:$C,_xlfn.XLOOKUP($A5,Static!$D:$D,Static!$E:$E),'Class NAVs'!$H:$H) -> 22589967 | I5: =IF(H5=0,"Inactive share class",SUM(C5:F5)/H5) -> 1.0177716 | J5: =_xlfn.XLOOKUP($A5,[1]Summary!$A:$A,[1]Summary!$I:$I) -> 1.0186197 | K5: =_xlfn.XLOOKUP($G5,[2]Funds!$A:$A,[2]Funds!$D:$D) -> MultAsst | L5: =_xlfn.XLOOKUP(_xlfn.XLOOKUP($A5,Static!$D:$D,Static!$F:$F),Static!$A:$A,Static!$B:$B)&" ("&_xlfn.XLOOKUP($A5,Static!$D:$D,Static!$F:$F)&")" -> Prescient Global Balanced Fund (PGPGBF_C) | M5: =IF(OR($I5<0.95,$I5>1.05),$G5&" "&RIGHT($A5,3)&" class","") | N5: ="PGF Share Class Hedging - "&TEXT('Class NAVs'!B2,"dddd d mmmm yyyy")&IF($M5=""," - ALL HEDGES ARE WITHIN THE REGULATORY LIMITS"," - "&UPPER($M5)&" IS "&IF($I5<0.95,"BELOW","ABOVE")&" THE REGULATORY LIMIT") -> PGF Share Class Hedging - Wednesday 4 October 2023 - ALL HEDGES ARE WITHIN THE REGULATORY LIMITS | O5: ="Please see below PIM's Prescient Global Funds share class hedges for "&TEXT('Class NAVs'!B5,"dddd d mmmm yyyy")&"; workings are stored here."&IF($M5="",""," Please advise regarding the "&$M5&" breach.") -> Please see below PIM's Prescient Global Funds share class hedges for Wednesday 4 October 2023; workings are stored here.
A6: PGEMZAR | B6: =_xlfn.XLOOKUP($A6,'Portfolio Valuation'!$AK:$AK,'Portfolio Valuation'!$A:$A) -> PIM Core Global Emerging Marke | C6: {=MAX(0,SUMPRODUCT(('Portfolio Valuation'!$AK:$AK=$A6)*('Portfolio Valuation'!$W:$W=C$1),'Portfolio Valuation'!$L:$L))} -> 0 | D6: {=MAX(0,SUMPRODUCT(('Portfolio Valuation'!$AK:$AK=$A6)*('Portfolio Valuation'!$W:$W=D$1),'Portfolio Valuation'!$L:$L))} -> 12471949 | E6: {=MAX(0,SUMPRODUCT(('Portfolio Valuation'!$AK:$AK=$A6)*('Portfolio Valuation'!$W:$W=E$1),'Portfolio Valuation'!$L:$L))} -> 0 | F6: {=MAX(0,SUMPRODUCT(('Portfolio Valuation'!$AK:$AK=$A6)*('Portfolio Valuation'!$W:$W=F$1),'Portfolio Valuation'!$L:$L))} -> 0 | G6: =SUBSTITUTE(_xlfn.XLOOKUP($A6,Static!$D:$D,Static!$F:$F),"_C","") -> PGPCEM | H6: =SUMIF('Class NAVs'!$C:$C,_xlfn.XLOOKUP($A6,Static!$D:$D,Static!$E:$E),'Class NAVs'!$H:$H) -> 12134817 | I6: =IF(H6=0,"Inactive share class",SUM(C6:F6)/H6) -> 1.0277822 | J6: =_xlfn.XLOOKUP($A6,[1]Summary!$A:$A,[1]Summary!$I:$I) -> 1.0209124 | K6: =_xlfn.XLOOKUP($G6,[2]Funds!$A:$A,[2]Funds!$D:$D) -> Eqty | L6: =_xlfn.XLOOKUP(_xlfn.XLOOKUP($A6,Static!$D:$D,Static!$F:$F),Static!$A:$A,Static!$B:$B)&" ("&_xlfn.XLOOKUP($A6,Static!$D:$D,Static!$F:$F)&")" -> Prescient Core Global Emerging Markets Equity Fund (PGPCEM_C) | M6: =IF(OR($I6<0.95,$I6>1.05),$G6&" "&RIGHT($A6,3)&" class","") | N6: ="PGF Share Class Hedging - "&TEXT('Class NAVs'!B2,"dddd d mmmm yyyy")&IF($M6=""," - ALL HEDGES ARE WITHIN THE REGULATORY LIMITS"," - "&UPPER($M6)&" IS "&IF($I6<0.95,"BELOW","ABOVE")&" THE REGULATORY LIMIT") -> PGF Share Class Hedging - Wednesday 4 October 2023 - ALL HEDGES ARE WITHIN THE REGULATORY LIMITS | O6: ="Please see below PIM's Prescient Global Funds share class hedges for "&TEXT('Class NAVs'!B6,"dddd d mmmm yyyy")&"; workings are stored here."&IF($M6="",""," Please advise regarding the "&$M6&" breach.") -> Please see below PIM's Prescient Global Funds share class hedges for Wednesday 4 October 2023; workings are stored here.
A7: PGPCZAR | B7: =_xlfn.XLOOKUP($A7,'Portfolio Valuation'!$AK:$AK,'Portfolio Valuation'!$A:$A) -> Prescient Core Global Equity Z | C7: {=MAX(0,SUMPRODUCT(('Portfolio Valuation'!$AK:$AK=$A7)*('Portfolio Valuation'!$W:$W=C$1),'Portfolio Valuation'!$L:$L))} -> 0 | D7: {=MAX(0,SUMPRODUCT(('Portfolio Valuation'!$AK:$AK=$A7)*('Portfolio Valuation'!$W:$W=D$1),'Portfolio Valuation'!$L:$L))} -> 18091982 | E7: {=MAX(0,SUMPRODUCT(('Portfolio Valuation'!$AK:$AK=$A7)*('Portfolio Valuation'!$W:$W=E$1),'Portfolio Valuation'!$L:$L))} -> 0 | F7: {=MAX(0,SUMPRODUCT(('Portfolio Valuation'!$AK:$AK=$A7)*('Portfolio Valuation'!$W:$W=F$1),'Portfolio Valuation'!$L:$L))} -> 0 | G7: =SUBSTITUTE(_xlfn.XLOOKUP($A7,Static!$D:$D,Static!$F:$F),"_C","") -> PGPCGE | H7: =SUMIF('Class NAVs'!$C:$C,_xlfn.XLOOKUP($A7,Static!$D:$D,Static!$E:$E),'Class NAVs'!$H:$H) -> 17666275 | I7: =IF(H7=0,"Inactive share class",SUM(C7:F7)/H7) -> 1.0240972 | J7: =_xlfn.XLOOKUP($A7,[1]Summary!$A:$A,[1]Summary!$I:$I) -> 1.0258641 | K7: =_xlfn.XLOOKUP($G7,[2]Funds!$A:$A,[2]Funds!$D:$D) -> Eqty | L7: =_xlfn.XLOOKUP(_xlfn.XLOOKUP($A7,Static!$D:$D,Static!$F:$F),Static!$A:$A,Static!$B:$B)&" ("&_xlfn.XLOOKUP($A7,Static!$D:$D,Static!$F:$F)&")" -> Prescient Core Global Equity Fund (PGPCGE_C) | M7: =IF(OR($I7<0.95,$I7>1.05),$G7&" "&RIGHT($A7,3)&" class","") | N7: ="PGF Share Class Hedging - "&TEXT('Class NAVs'!B2,"dddd d mmmm yyyy")&IF($M7=""," - ALL HEDGES ARE WITHIN THE REGULATORY LIMITS"," - "&UPPER($M7)&" IS "&IF($I7<0.95,"BELOW","ABOVE")&" THE REGULATORY LIMIT") -> PGF Share Class Hedging - Wednesday 4 October 2023 - ALL HEDGES ARE WITHIN THE REGULATORY LIMITS | O7: ="Please see below PIM's Prescient Global Funds share class hedges for "&TEXT('Class NAVs'!B7,"dddd d mmmm yyyy")&"; workings are stored here."&IF($M7="",""," Please advise regarding the "&$M7&" breach.") -> Please see below PIM's Prescient Global Funds share class hedges for Wednesday 4 October 2023; workings are stored here.
A8: PGIP_I | B8: =_xlfn.XLOOKUP($A8,'Portfolio Valuation'!$AK:$AK,'Portfolio Valuation'!$A:$A) -> PIM Global Income Provider Cla | C8: {=MAX(0,SUMPRODUCT(('Portfolio Valuation'!$AK:$AK=$A8)*('Portfolio Valuation'!$W:$W=C$1),'Portfolio Valuation'!$L:$L))} -> 0 | D8: {=MAX(0,SUMPRODUCT(('Portfolio Valuation'!$AK:$AK=$A8)*('Portfolio Valuation'!$W:$W=D$1),'Portfolio Valuation'!$L:$L))} -> 7721436.5 | E8: {=MAX(0,SUMPRODUCT(('Portfolio Valuation'!$AK:$AK=$A8)*('Portfolio Valuation'!$W:$W=E$1),'Portfolio Valuation'!$L:$L))} -> 0 | F8: {=MAX(0,SUMPRODUCT(('Portfolio Valuation'!$AK:$AK=$A8)*('Portfolio Valuation'!$W:$W=F$1),'Portfolio Valuation'!$L:$L))} -> 0 | G8: =SUBSTITUTE(_xlfn.XLOOKUP($A8,Static!$D:$D,Static!$F:$F),"_C","") -> PGPGIF | H8: =SUMIF('Class NAVs'!$C:$C,_xlfn.XLOOKUP($A8,Static!$D:$D,Static!$E:$E),'Class NAVs'!$H:$H) -> 7829324.5 | I8: =IF(H8=0,"Inactive share class",SUM(C8:F8)/H8) -> 0.98622002 | J8: =_xlfn.XLOOKUP($A8,[1]Summary!$A:$A,[1]Summary!$I:$I) -> 0.98676906 | K8: =_xlfn.XLOOKUP($G8,[2]Funds!$A:$A,[2]Funds!$D:$D) -> FxdInt | L8: =_xlfn.XLOOKUP(_xlfn.XLOOKUP($A8,Static!$D:$D,Static!$F:$F),Static!$A:$A,Static!$B:$B)&" ("&_xlfn.XLOOKUP($A8,Static!$D:$D,Static!$F:$F)&")" -> Prescient Global Income Provider Fund (PGPGIF_C) | M8: =IF(OR($I8<0.95,$I8>1.05),$G8&" "&RIGHT($A8,3)&" class","") | N8: ="PGF Share Class Hedging - "&TEXT('Class NAVs'!B2,"dddd d mmmm yyyy")&IF($M8=""," - ALL HEDGES ARE WITHIN THE REGULATORY LIMITS"," - "&UPPER($M8)&" IS "&IF($I8<0.95,"BELOW","ABOVE")&" THE REGULATORY LIMIT") -> PGF Share Class Hedging - Wednesday 4 October 2023 - ALL HEDGES ARE WITHIN THE REGULATORY LIMITS | O8: ="Please see below PIM's Prescient Global Funds share class hedges for "&TEXT('Class NAVs'!B8,"dddd d mmmm yyyy")&"; workings are stored here."&IF($M8="",""," Please advise regarding the "&$M8&" breach.") -> Please see below PIM's Prescient Global Funds share class hedges for Wednesday 4 October 2023; workings are stored here.
A9: PGPRUS0% | B9: =_xlfn.XLOOKUP($A9,'Portfolio Valuation'!$AK:$AK,'Portfolio Valuation'!$A:$A) -> Positive Return Fund Class I ( | C9: {=MAX(0,SUMPRODUCT(('Portfolio Valuation'!$AK:$AK=$A9)*('Portfolio Valuation'!$W:$W=C$1),'Portfolio Valuation'!$L:$L))} -> 0 | D9: {=MAX(0,SUMPRODUCT(('Portfolio Valuation'!$AK:$AK=$A9)*('Portfolio Valuation'!$W:$W=D$1),'Portfolio Valuation'!$L:$L))} -> 0 | E9: {=MAX(0,SUMPRODUCT(('Portfolio Valuation'!$AK:$AK=$A9)*('Portfolio Valuation'!$W:$W=E$1),'Portfolio Valuation'!$L:$L))} -> 0 | F9: {=MAX(0,SUMPRODUCT(('Portfolio Valuation'!$AK:$AK=$A9)*('Portfolio Valuation'!$W:$W=F$1),'Portfolio Valuation'!$L:$L))} -> 0 | G9: =_xlfn.XLOOKUP($A9,Static!$D:$D,Static!$F:$F) -> PGPRF_C | H9: =SUMIF('Class NAVs'!$C:$C,_xlfn.XLOOKUP($A9,Static!$D:$D,Static!$E:$E),'Class NAVs'!$H:$H) -> 0 | I9: =IF(H9=0,"Inactive share class",SUM(C9:F9)/H9) -> Inactive share class | J9: =_xlfn.XLOOKUP($A9,[1]Summary!$A:$A,[1]Summary!$I:$I) -> Inactive share class | K9: =_xlfn.XLOOKUP($G9,[2]Funds!$A:$A,[2]Funds!$D:$D) -> MultAsst | L9: =_xlfn.XLOOKUP(_xlfn.XLOOKUP($A9,Static!$D:$D,Static!$F:$F),Static!$A:$A,Static!$B:$B)&" ("&_xlfn.XLOOKUP($A9,Static!$D:$D,Static!$F:$F)&")" -> Prescient Global Positive Return Fund (PGPRF_C) | N9: ="PGF Share Class Hedging - "&TEXT('Class NAVs'!B2,"dddd d mmmm yyyy")&IF($M9="",""," - "&UPPER($M9)&" IS "&IF($I9<0.95,"BELOW","ABOVE")&" THE REGULATORY LIMIT") -> PGF Share Class Hedging - Wednesday 4 October 2023
A10: PGPRGBP | B10: =_xlfn.XLOOKUP($A10,'Portfolio Valuation'!$AK:$AK,'Portfolio Valuation'!$A:$A) -> Pos Return Fund GBP Sec | C10: {=MAX(0,SUMPRODUCT(('Portfolio Valuation'!$AK:$AK=$A10)*('Portfolio Valuation'!$W:$W=C$1),'Portfolio Valuation'!$L:$L))} -> 0 | D10: {=MAX(0,SUMPRODUCT(('Portfolio Valuation'!$AK:$AK=$A10)*('Portfolio Valuation'!$W:$W=D$1),'Portfolio Valuation'!$L:$L))} -> 0 | E10: {=MAX(0,SUMPRODUCT(('Portfolio Valuation'!$AK:$AK=$A10)*('Portfolio Valuation'!$W:$W=E$1),'Portfolio Valuation'!$L:$L))} -> 0 | F10: {=MAX(0,SUMPRODUCT(('Portfolio Valuation'!$AK:$AK=$A10)*('Portfolio Valuation'!$W:$W=F$1),'Portfolio Valuation'!$L:$L))} -> 0 | G10: =_xlfn.XLOOKUP($A10,Static!$D:$D,Static!$F:$F) -> PGPRF_C | H10: =SUMIF('Class NAVs'!$C:$C,_xlfn.XLOOKUP($A10,Static!$D:$D,Static!$E:$E),'Class NAVs'!$H:$H) -> 0 | I10: =IF(H10=0,"Inactive share class",SUM(C10:F10)/H10) -> Inactive share class | J10: =_xlfn.XLOOKUP($A10,[1]Summary!$A:$A,[1]Summary!$I:$I) -> Inactive share class | K10: =_xlfn.XLOOKUP($G10,[2]Funds!$A:$A,[2]Funds!$D:$D) -> MultAsst | L10: =_xlfn.XLOOKUP(_xlfn.XLOOKUP($A10,Static!$D:$D,Static!$F:$F),Static!$A:$A,Static!$B:$B)&" ("&_xlfn.XLOOKUP($A10,Static!$D:$D,Static!$F:$F)&")" -> Prescient Global Positive Return Fund (PGPRF_C) | N10: ="PGF Share Class Hedging - "&TEXT('Class NAVs'!B2,"dddd d mmmm yyyy")&IF($M10="",""," - "&UPPER($M10)&" IS "&IF($I10<0.95,"BELOW","ABOVE")&" THE REGULATORY LIMIT") -> PGF Share Class Hedging - Wednesday 4 October 2023
A11: PGBEUR | B11: =_xlfn.XLOOKUP($A11,'Portfolio Valuation'!$AK:$AK,'Portfolio Valuation'!$A:$A) -> Prescient Global Balanced EUR | C11: {=MAX(0,SUMPRODUCT(('Portfolio Valuation'!$AK:$AK=$A11)*('Portfolio Valuation'!$W:$W=C$1),'Portfolio Valuation'!$L:$L))} -> 0 | D11: {=MAX(0,SUMPRODUCT(('Portfolio Valuation'!$AK:$AK=$A11)*('Portfolio Valuation'!$W:$W=D$1),'Portfolio Valuation'!$L:$L))} -> 0 | E11: {=MAX(0,SUMPRODUCT(('Portfolio Valuation'!$AK:$AK=$A11)*('Portfolio Valuation'!$W:$W=E$1),'Portfolio Valuation'!$L:$L))} -> 0 | F11: {=MAX(0,SUMPRODUCT(('Portfolio Valuation'!$AK:$AK=$A11)*('Portfolio Valuation'!$W:$W=F$1),'Portfolio Valuation'!$L:$L))} -> 0 | G11: =_xlfn.XLOOKUP($A11,Static!$D:$D,Static!$F:$F) -> PGPGBF_C | H11: =SUMIF('Class NAVs'!$C:$C,_xlfn.XLOOKUP($A11,Static!$D:$D,Static!$E:$E),'Class NAVs'!$H:$H) -> 0 | I11: =IF(H11=0,"Inactive share class",SUM(C11:F11)/H11) -> Inactive share class | J11: =_xlfn.XLOOKUP($A11,[1]Summary!$A:$A,[1]Summary!$I:$I) -> Inactive share class | K11: =_xlfn.XLOOKUP($G11,[2]Funds!$A:$A,[2]Funds!$D:$D) -> MultAsst | L11: =_xlfn.XLOOKUP(_xlfn.XLOOKUP($A11,Static!$D:$D,Static!$F:$F),Static!$A:$A,Static!$B:$B)&" ("&_xlfn.XLOOKUP($A11,Static!$D:$D,Static!$F:$F)&")" -> Prescient Global Balanced Fund (PGPGBF_C) | N11: ="PGF Share Class Hedging - "&TEXT('Class NAVs'!B2,"dddd d mmmm yyyy")&IF($M11="",""," - "&UPPER($M11)&" IS "&IF($I11<0.95,"BELOW","ABOVE")&" THE REGULATORY LIMIT") -> PGF Share Class Hedging - Wednesday 4 October 2023
A12: PGBGBP | B12: =_xlfn.XLOOKUP($A12,'Portfolio Valuation'!$AK:$AK,'Portfolio Valuation'!$A:$A) -> Prescient Global Balanced GBP | C12: {=MAX(0,SUMPRODUCT(('Portfolio Valuation'!$AK:$AK=$A12)*('Portfolio Valuation'!$W:$W=C$1),'Portfolio Valuation'!$L:$L))} -> 0 | D12: {=MAX(0,SUMPRODUCT(('Portfolio Valuation'!$AK:$AK=$A12)*('Portfolio Valuation'!$W:$W=D$1),'Portfolio Valuation'!$L:$L))} -> 0 | E12: {=MAX(0,SUMPRODUCT(('Portfolio Valuation'!$AK:$AK=$A12)*('Portfolio Valuation'!$W:$W=E$1),'Portfolio Valuation'!$L:$L))} -> 0 | F12: {=MAX(0,SUMPRODUCT(('Portfolio Valuation'!$AK:$AK=$A12)*('Portfolio Valuation'!$W:$W=F$1),'Portfolio Valuation'!$L:$L))} -> 0 | G12: =_xlfn.XLOOKUP($A12,Static!$D:$D,Static!$F:$F) -> PGPGBF_C | H12: =SUMIF('Class NAVs'!$C:$C,_xlfn.XLOOKUP($A12,Static!$D:$D,Static!$E:$E),'Class NAVs'!$H:$H) -> 0 | I12: =IF(H12=0,"Inactive share class",SUM(C12:F12)/H12) -> Inactive share class | J12: =_xlfn.XLOOKUP($A12,[1]Summary!$A:$A,[1]Summary!$I:$I) -> Inactive share class | K12: =_xlfn.XLOOKUP($G12,[2]Funds!$A:$A,[2]Funds!$D:$D) -> MultAsst | L12: =_xlfn.XLOOKUP(_xlfn.XLOOKUP($A12,Static!$D:$D,Static!$F:$F),Static!$A:$A,Static!$B:$B)&" ("&_xlfn.XLOOKUP($A12,Static!$D:$D,Static!$F:$F)&")" -> Prescient Global Balanced Fund (PGPGBF_C) | N12: ="PGF Share Class Hedging - "&TEXT('Class NAVs'!B2,"dddd d mmmm yyyy")&IF($M12="",""," - "&UPPER($M12)&" IS "&IF($I12<0.95,"BELOW","ABOVE")&" THE REGULATORY LIMIT") -> PGF Share Class Hedging - Wednesday 4 October 2023
B14: Hedge exceeds regulatory 95% to 105% limit
B15: Hedge exceeds early warning 96.5% to 103.5% limit
B16: Hedge is within early warning and regulatory limits
B18: Useful Links
B19: =HYPERLINK("P:\Investment Operations\GRC\Compliance\PGF UCITS Share Class Hedges","PGF Shares Classes Folder") -> PGF Shares Classes Folder
B20: =HYPERLINK("http://www.irishstatutebook.ie/eli/2013/si/257/made/en/print","SI 257 of 2013 EU (AIFM) Regulation 2013") -> SI 257 of 2013 EU (AIFM) Regulation 2013
B21: =HYPERLINK("http://www.irishstatutebook.ie/eli/2015/si/420/made/en/print","SI 420 of 2015 CBoI UCITS Regulations 2015") -> SI 420 of 2015 CBoI UCITS Regulations 2015
B22: =HYPERLINK("https://www.centralbank.ie/docs/default-source/publications/Consultation-Papers/CP27/gn-399-share-classes---hedging-against-exchange-rate-movements.pdf?sfvrsn=2","UCITS share class hedging GN3/99") -> UCITS share class hedging GN3/99
B23: =HYPERLINK("https://www.centralbank.ie/docs/default-source/publications/Consultation-Papers/CP27/gn-399-share-classes---hedging-against-exchange-rate-movements.pdf?sfvrsn=2","UCITS share class hedging GN3/99") -> UCITS share class hedging GN3/99
B24: =HYPERLINK("\\pim-cpt-statpro\SPC_602\Client\Profiles\PIM\Exports\PGF ICAV Hedged Classes 12Nov2020.xlsx","ICAV Hedge Classes 12Nov 2020") -> ICAV Hedge Classes 12Nov 2020

Sheet Portfolio Valuation
A1: Entity Name | B1: Valuation First Level | C1: Valuation Second Level | D1: i Issue Name | E1: PrimaryAssetID | F1: Issue Description | G1: Original Nominal | H1: Clean Book Value | I1: Clean Market Value | J1: Accrued Income | K1: Dividend Receivable | L1: Sum of Market Value Income | M1: Market Price /Yield | N1: % of Total Market Value | O1: Next Coupon Date | P1: Maturity Date | Q1: Coupon | R1: Duration | S1: Modified Duration | T1: Investment Type | U1: Security Type | V1: Sub Security Type | W1: CCY | X1: Sector | Y1: Supersector | Z1: Industry | AA1: Issuer Rating | AB1: Security Rating | AC1: NACA Yield | AD1: NACM Yield | AE1: Weighted Avg NACA Yield | AF1: Weighted Avg NACM Yield | AG1: Market Value % | AH1: Current Exposure | AI1: Current Exposure % | AJ1: i Position Effective Date | AK1: Entity ID | AL1: Weighted Average NACS Yield | AM1: Weighted Average Coupon | AN1: Weighted Modified Duration | AO1: Issuer | AP1: ISIN Code | AQ1: Ticker
A2: PIM Core Glbl Equity Fd Cl D | B2: UNKNOWN | C2: UNKNOWN | D2: No Data found for this Entity | N2: 0 | AI2: 0 | AK2: PGPCGED
A3: PIM Core Glo EM Equity Fund D | B3: UNKNOWN | C3: UNKNOWN | D3: No Data found for this Entity | N3: 0 | AI3: 0 | AK3: PGPCEMD
A4: PIM Core Global Emerging Marke | B4: FORWARDS | C4: Forwards | D4: USD/ZAR FWD 20240226 BAR0.29 | E4: 514NK00GBEIRI623 | F4: USD/ZAR FWD 20240226 BAR0.29 | G4: -10850000 | H4: -10850000 | I4: -10850000 | J4: 0 | K4: 0 | L4: -10850000 | M4: 1 | N4: 469.0558 | P4: 45348 | T4: FWD | W4: USD | AG4: 6093.76 | AH4: -10850000 | AI4: 469.06 | AJ4: 45203 | AK4: PGEMZAR | AQ4: USD
A5: PIM Core Global Emerging Marke | B5: FORWARDS | C5: Forwards | D5: USD/ZAR FWD 20240226 BAR0.31 | E5: SSCFNLQ5QDJOR8SN | F5: USD/ZAR FWD 20240226 BAR0.31 | G5: 900000 | H5: 900000 | I5: 900000 | J5: 0 | K5: 0 | L5: 900000 | M5: 1 | N5: -38.907855 | P5: 45348 | T5: FWD | W5: USD | AG5: -505.47 | AH5: 900000 | AI5: -38.91 | AJ5: 45203 | AK5: PGEMZAR | AQ5: USD
A6: PIM Core Global Emerging Marke | B6: FORWARDS | C6: Forwards | D6: USD/ZAR FWD 20240226 GSS0.01 | E6: ULJBLHLTSRAGHNRB | F6: USD/ZAR FWD 20240226 GSS0.01 | G6: -2700000 | H6: -2700000 | I6: -2700000 | J6: 0 | K6: 0 | L6: -2700000 | M6: 1 | N6: 116.72356 | P6: 45348 | T6: FWD | W6: USD | AG6: 1516.42 | AH6: -2700000 | AI6: 116.72 | AJ6: 45203 | AK6: PGEMZAR | AQ6: USD
A7: PIM Core Global Emerging Marke | B7: FORWARDS | C7: Forwards | D7: ZAR/USD FWD 20240226 BAR0.29 | E7: 514NK00GBEIRI623 | F7: ZAR/USD FWD 20240226 BAR0.29 | G7: 210409710 | H7: 10850000 | I7: 10705623 | J7: 0 | K7: 0 | L7: 10705623 | M7: 19.654131 | N7: -462.81423 | P7: 45348 | T7: FWD | W7: ZAR | AG7: -6012.67 | AH7: 10705623 | AI7: -462.81 | AJ7: 45203 | AK7: PGEMZAR | AQ7: ZAR
A8: PIM Core Global Emerging Marke | B8: FORWARDS | C8: Forwards | D8: ZAR/USD FWD 20240226 BAR0.31 | E8: SSCFNLQ5QDJOR8SN | F8: ZAR/USD FWD 20240226 BAR0.31 | G8: -17538750 | H8: -900000 | I8: -892369.64 | J8: 0 | K8: 0 | L8: -892369.64 | M8: 19.654131 | N8: 38.577987 | P8: 45348 | T8: FWD | W8: ZAR | AG8: 501.19 | AH8: -892369.64 | AI8: 38.58 | AJ8: 45203 | AK8: PGEMZAR | AQ8: ZAR
A9: PIM Core Global Emerging Marke | B9: FORWARDS | C9: Forwards | D9: ZAR/USD FWD 20240226 GSS0.01 | E9: ULJBLHLTSRAGHNRB | F9: ZAR/USD FWD 20240226 GSS0.01 | G9: 52254361 | H9: 2700000 | I9: 2658696 | J9: 0 | K9: 0 | L9: 2658696 | M9: 19.654131 | N9: -114.93796 | P9: 45348 | T9: FWD | W9: ZAR | AG9: -1493.22 | AH9: 2658696 | AI9: -114.94 | AJ9: 45203 | AK9: PGEMZAR | AQ9: ZAR
A10: PIM Global Balanced D | B10: UNKNOWN | C10: UNKNOWN | D10: No Data found for this Entity | N10: 0 | AI10: 0 | AK10: PGPGBFD
A11: PIM Global Income Provider Cla | B11: CASH | C11: Traded Cash | D11: South African Rand | E11: CASHZAR | F11: South African Rand | G11: -0.03 | H11: 0 | I11: 0 | J11: 0 | K11: 0 | L11: 0 | N11: 0 | R11: 0.08 | T11: CASH | U11: CRNY | W11: ZAR | AC11: 5.116339 | AD11: 5.0001425 | AE11: 5.12 | AF11: 5.0001425 | AG11: 0 | AH11: 0 | AI11: 0 | AJ11: 45203 | AK11: PGIP_I | AL11: 5.05 | AQ11: ZAR
A12: PIM Global Income Provider Cla | B12: FORWARDS | C12: Forwards | D12: USD/ZAR FWD 20231124 BAR0.19 | E12: GUIF8RPBUKFIA10M | F12: USD/ZAR FWD 20231124 BAR0.19 | G12: -7825414.6 | H12: -7825414.6 | I12: -7825414.6 | J12: 0 | K12: 0 | L12: -7825414.6 | M12: 1 | N12: 338.3001 | P12: 45254 | T12: FWD | W12: USD | AG12: 7526.03 | AH12: -7825414.6 | AI12: 338.3 | AJ12: 45203 | AK12: PGIP_I | AQ12: USD
A13: PIM Global Income Provider Cla | B13: FORWARDS | C13: Forwards | D13: ZAR/USD FWD 20231124 BAR0.19 | E13: GUIF8RPBUKFIA10M | F13: ZAR/USD FWD 20231124 BAR0.19 | G13: 150460811 | H13: 7825414.6 | I13: 7721436.5 | J13: 0 | K13: 0 | L13: 7721436.5 | M13: 19.486116 | N13: -333.80503 | P13: 45254 | T13: FWD | W13: ZAR | AG13: -7426.03 | AH13: 7721436.5 | AI13: -333.81 | AJ13: 45203 | AK13: PGIP_I | AQ13: ZAR
A14: PIM Global Income Provider E | B14: UNKNOWN | C14: UNKNOWN | D14: No Data found for this Entity | N14: 0 | AI14: 0 | AK14: PGPGIFE
A15: PIM Global Income Provider I | B15: UNKNOWN | C15: UNKNOWN | D15: No Data found for this Entity | N15: 0 | AI15: 0 | AK15: PGPGIFI
A16: PIM Global Positive Return E | B16: UNKNOWN | C16: UNKNOWN | D16: No Data found for this Entity | N16: 0 | AI16: 0 | AK16: PGPRFE
A17: PIM Global Positive Return G | B17: UNKNOWN | C17: UNKNOWN | D17: No Data found for this Entity | N17: 0 | AI17: 0 | AK17: PGPRFG
A18: Pos Return Fund GBP Sec | B18: UNKNOWN | C18: UNKNOWN | D18: No Data found for this Entity | N18: 0 | AI18: 0 | AK18: PGPRGBP
A19: Pos Return Fund USD Sec | B19: FORWARDS | C19: Forwards | D19: EUR/USD FWD 20240125 BAR0.01 | E19: 65Q86KO41MMT5FIP | F19: EUR/USD FWD 20240125 BAR0.01 | G19: -185284.85 | H19: -185284.85 | I19: -185284.85 | J19: 0 | K19: 0 | L19: -185284.85 | M19: 1 | N19: 8.01004 | P19: 45316 | T19: FWD | W19: EUR | AG19: -1180.3 | AH19: -185284.85 | AI19: 8.01 | AJ19: 45203 | AK19: PGPRUSD | AQ19: EUR
A20: Pos Return Fund USD Sec | B20: FORWARDS | C20: Forwards | D20: EUR/USD FWD 20240125 BAR0.03 | E20: 9321D8HKNK0M833M | F20: EUR/USD FWD 20240125 BAR0.03 | G20: -30000 | H20: -30000 | I20: -30000 | J20: 0 | K20: 0 | L20: -30000 | M20: 1 | N20: 1.2969285 | P20: 45316 | T20: FWD | W20: EUR | AG20: -191.1 | AH20: -30000 | AI20: 1.3 | AJ20: 45203 | AK20: PGPRUSD | AQ20: EUR
A21: Pos Return Fund USD Sec | B21: FORWARDS | C21: Forwards | D21: USD/EUR FWD 20240125 BAR0.01 | E21: 65Q86KO41MMT5FIP | F21: USD/EUR FWD 20240125 BAR0.01 | G21: 210000 | H21: 185284.85 | I21: 199037.51 | J21: 0 | K21: 0 | L21: 199037.51 | M21: 1.055077 | N21: -8.6045806 | P21: 45316 | T21: FWD | W21: USD | AG21: 1267.9 | AH21: 199037.51 | AI21: -8.6 | AJ21: 45203 | AK21: PGPRUSD | AQ21: USD
A22: Pos Return Fund USD Sec | B22: FORWARDS | C22: Forwards | D22: USD/EUR FWD 20240125 BAR0.03 | E22: 9321D8HKNK0M833M | F22: USD/EUR FWD 20240125 BAR0.03 | G22: 33705 | H22: 30000 | I22: 31945.52 | J22: 0 | K22: 0 | L22: 31945.52 | M22: 1.055077 | N22: -1.3810352 | P22: 45316 | T22: FWD | W22: USD | AG22: 203.5 | AH22: 31945.52 | AI22: -1.38 | AJ22: 45203 | AK22: PGPRUSD | AQ22: USD
A23: Pos Return Fund ZAR Sec | B23: FORWARDS | C23: Forwards | D23: EUR/ZAR FWD 20240125 BAR0.03 | E23: GR4BKNIG09OUIICA | F23: EUR/ZAR FWD 20240125 BAR0.03 | G23: -4600000 | H23: -4600000 | I23: -4600000 | J23: 0 | K23: 0 | L23: -4600000 | M23: 1 | N23: 198.86237 | P23: 45316 | T23: FWD | W23: EUR | AG23: 23109.7 | AH23: -4600000 | AI23: 198.86 | AJ23: 45203 | AK23: PGPRZAR | AQ23: EUR
A24: Pos Return Fund ZAR Sec | B24: FORWARDS | C24: Forwards | D24: EUR/ZAR FWD 20240125 BAR0.04 | E24: 2CL3QB8SGFSSJQKJ | F24: EUR/ZAR FWD 20240125 BAR0.04 | G24: -200000 | H24: -200000 | I24: -200000 | J24: 0 | K24: 0 | L24: -200000 | M24: 1 | N24: 8.64619 | P24: 45316 | T24: FWD | W24: EUR | AG24: 1004.77 | AH24: -200000 | AI24: 8.65 | AJ24: 45203 | AK24: PGPRZAR | AQ24: EUR
A25: Pos Return Fund ZAR Sec | B25: FORWARDS | C25: Forwards | D25: EUR/ZAR FWD 20240125 BAR0.05 | E25: H6P9TP07ORKJMB2V | F25: EUR/ZAR FWD 20240125 BAR0.05 | G25: 230000 | H25: 230000 | I25: 230000 | J25: 0 | K25: 0 | L25: 230000 | M25: 1 | N25: -9.9431185 | P25: 45316 | T25: FWD | W25: EUR | AG25: -1155.49 | AH25: 230000 | AI25: -9.94 | AJ25: 45203 | AK25: PGPRZAR | AQ25: EUR
A26: Pos Return Fund ZAR Sec | B26: FORWARDS | C26: Forwards | D26: EUR/ZAR FWD 20240125 BAR0.07 | E26: J963C3SR6M9F6L57 | F26: EUR/ZAR FWD 20240125 BAR0.07 | G26: 1200000 | H26: 1200000 | I26: 1200000 | J26: 0 | K26: 0 | L26: 1200000 | M26: 1 | N26: -51.87714 | P26: 45316 | T26: FWD | W26: EUR | AG26: -6028.62 | AH26: 1200000 | AI26: -51.88 | AJ26: 45203 | AK26: PGPRZAR | AQ26: EUR
A27: Pos Return Fund ZAR Sec | B27: FORWARDS | C27: Forwards | D27: ZAR/EUR FWD 20240125 BAR0.03 | E27: GR4BKNIG09OUIICA | F27: ZAR/EUR FWD 20240125 BAR0.03 | G27: 94829000 | H27: 4600000 | I27: 4584070.2 | J27: 0 | K27: 0 | L27: 4584070.2 | M27: 20.686638 | N27: -198.17371 | P27: 45316 | T27: FWD | W27: ZAR | AG27: -23029.67 | AH27: 4584070.2 | AI27: -198.17 | AJ27: 45203 | AK27: PGPRZAR | AQ27: ZAR
A28: Pos Return Fund ZAR Sec | B28: FORWARDS | C28: Forwards | D28: ZAR/EUR FWD 20240125 BAR0.04 | E28: 2CL3QB8SGFSSJQKJ | F28: ZAR/EUR FWD 20240125 BAR0.04 | G28: 3982000 | H28: 200000 | I28: 192491.41 | J28: 0 | K28: 0 | L28: 192491.41 | M28: 20.686638 | N28: -8.3215865 | P28: 45316 | T28: FWD | W28: ZAR | AG28: -967.05 | AH28: 192491.41 | AI28: -8.32 | AJ28: 45203 | AK28: PGPRZAR | AQ28: ZAR
A29: Pos Return Fund ZAR Sec | B29: FORWARDS | C29: Forwards | D29: ZAR/EUR FWD 20240125 BAR0.05 | E29: H6P9TP07ORKJMB2V | F29: ZAR/EUR FWD 20240125 BAR0.05 | G29: -4866800 | H29: -230000 | I29: -235262.98 | J29: 0 | K29: 0 | L29: -235262.98 | M29: 20.686638 | N29: 10.170642 | P29: 45316 | T29: FWD | W29: ZAR | AG29: 1181.93 | AH29: -235262.98 | AI29: 10.17 | AJ29: 45203 | AK29: PGPRZAR | AQ29: ZAR
A30: Pos Return Fund ZAR Sec | B30: FORWARDS | C30: Forwards | D30: ZAR/EUR FWD 20240125 BAR0.07 | E30: J963C3SR6M9F6L57 | F30: ZAR/EUR FWD 20240125 BAR0.07 | G30: -24642000 | H30: -1200000 | I30: -1191203.7 | J30: 0 | K30: 0 | L30: -1191203.7 | M30: 20.686638 | N30: 51.496869 | P30: 45316 | T30: FWD | W30: ZAR | AG30: 5984.43 | AH30: -1191203.7 | AI30: 51.5 | AJ30: 45203 | AK30: PGPRZAR | AQ30: ZAR
A31: Positive Return Fund Class I ( | B31: UNKNOWN | C31: UNKNOWN | D31: No Data found for this Entity | N31: 0 | AI31: 0 | AK31: PGPRUS0%
A32: Prescient Core Global Equity Z | B32: FORWARDS | C32: Forwards | D32: USD/ZAR FWD 20240226 BAR0.02 | E32: O2T00GRJKRIMG742 | F32: USD/ZAR FWD 20240226 BAR0.02 | G32: -2750000 | H32: -2750000 | I32: -2750000 | J32: 0 | K32: 0 | L32: -2750000 | M32: 1 | N32: 118.88511 | P32: 45348 | T32: FWD | W32: USD | AG32: 907.54 | AH32: -2750000 | AI32: 118.89 | AJ32: 45203 | AK32: PGPCZAR | AQ32: USD
A33: Prescient Core Global Equity Z | B33: FORWARDS | C33: Forwards | D33: USD/ZAR FWD 20240226 BAR0.03 | E33: V1BDHNFDE51I54BM | F33: USD/ZAR FWD 20240226 BAR0.03 | G33: 1850000 | H33: 1850000 | I33: 1850000 | J33: 0 | K33: 0 | L33: 1850000 | M33: 1 | N33: -79.977257 | P33: 45348 | T33: FWD | W33: USD | AG33: -610.53 | AH33: 1850000 | AI33: -79.98 | AJ33: 45203 | AK33: PGPCZAR | AQ33: USD
A34: Prescient Core Global Equity Z | B34: FORWARDS | C34: Forwards | D34: USD/ZAR FWD 20240226 BAR0.30 | E34: FNEPI3QR9PJSV9OJ | F34: USD/ZAR FWD 20240226 BAR0.30 | G34: -13995000 | H34: -13995000 | I34: -13995000 | J34: 0 | K34: 0 | L34: -13995000 | M34: 1 | N34: 605.01714 | P34: 45348 | T34: FWD | W34: USD | AG34: 4618.54 | AH34: -13995000 | AI34: 605.02 | AJ34: 45203 | AK34: PGPCZAR | AQ34: USD
A35: Prescient Core Global Equity Z | B35: FORWARDS | C35: Forwards | D35: USD/ZAR FWD 20240226 GSS0.02 | E35: RJQKGG7F88A7NMHR | F35: USD/ZAR FWD 20240226 GSS0.02 | G35: -3500000 | H35: -3500000 | I35: -3500000 | J35: 0 | K35: 0 | L35: -3500000 | M35: 1 | N35: 151.30832 | P35: 45348 | T35: FWD | W35: USD | AG35: 1155.05 | AH35: -3500000 | AI35: 151.31 | AJ35: 45203 | AK35: PGPCZAR | AQ35: USD
A36: Prescient Core Global Equity Z | B36: FORWARDS | C36: Forwards | D36: ZAR/USD FWD 20240226 BAR0.02 | E36: O2T00GRJKRIMG742 | F36: ZAR/USD FWD 20240226 BAR0.02 | G36: 52497500 | H36: 2750000 | I36: 2671066.9 | J36: 0 | K36: 0 | L36: 2671066.9 | M36: 19.654131 | N36: -115.47276 | P36: 45348 | T36: FWD | W36: ZAR | AG36: -881.49 | AH36: 2671066.9 | AI36: -115.47 | AJ36: 45203 | AK36: PGPCZAR | AQ36: ZAR
A37: Prescient Core Global Equity Z | B37: FORWARDS | C37: Forwards | D37: ZAR/USD FWD 20240226 BAR0.03 | E37: V1BDHNFDE51I54BM | F37: ZAR/USD FWD 20240226 BAR0.03 | G37: -36051875 | H37: -1850000 | I37: -1834315.4 | J37: 0 | K37: 0 | L37: -1834315.4 | M37: 19.654131 | N37: 79.299196 | P37: 45348 | T37: FWD | W37: ZAR | AG37: 605.35 | AH37: -1834315.4 | AI37: 79.3 | AJ37: 45203 | AK37: PGPCZAR | AQ37: ZAR
A38: Prescient Core Global Equity Z | B38: FORWARDS | C38: Forwards | D38: ZAR/USD FWD 20240226 BAR0.30 | E38: FNEPI3QR9PJSV9OJ | F38: ZAR/USD FWD 20240226 BAR0.30 | G38: 271399437 | H38: 13995000 | I38: 13808773 | J38: 0 | K38: 0 | L38: 13808773 | M38: 19.654131 | N38: -596.96637 | P38: 45348 | T38: FWD | W38: ZAR | AG38: -4557.09 | AH38: 13808773 | AI38: -596.97 | AJ38: 45203 | AK38: PGPCZAR | AQ38: ZAR
A39: Prescient Core Global Equity Z | B39: FORWARDS | C39: Forwards | D39: ZAR/USD FWD 20240226 GSS0.02 | E39: RJQKGG7F88A7NMHR | F39: ZAR/USD FWD 20240226 GSS0.02 | G39: 67737135 | H39: 3500000 | I39: 3446457.9 | J39: 0 | K39: 0 | L39: 3446457.9 | M39: 19.654131 | N39: -148.99365 | P39: 45348 | T39: FWD | W39: ZAR | AG39: -1137.38 | AH39: 3446457.9 | AI39: -148.99 | AJ39: 45203 | AK39: PGPCZAR | AQ39: ZAR
A40: Prescient Global Balanced EUR | B40: UNKNOWN | C40: UNKNOWN | D40: No Data found for this Entity | N40: 0 | AI40: 0 | AK40: PGBEUR
...

Sheet Class NAVs
A1: Entity Name | B1: Effective Date | C1: NAV Entity ID | D1: JSE Code | E1: NAV Price | F1: Clean Price | G1: Income Price | H1: Class Size | I1: Units in Class | J1: Daily Flows | K1: Distribution Rate | L1: Mgmt Fee | M1: Performance Fee
A2: PIM Core Glbl Equity Fd Cl D (PGPCGED) | B2: 45203 | C2: PGPCGED | D2: PR39DZAR | E2: 49.1 | F2: 47.86 | G2: 1.24 | H2: 17666275 | I2: 35945332 | J2: 0 | K2: 0 | L2: 0 | M2: 0
A3: PIM Core Glo EM Equity Fund D (PGPCEMD) | B3: 45203 | C3: PGPCEMD | D3: PR58DZAR | E3: 51.6 | F3: 50 | G3: 1.6 | H3: 12134817 | I3: 23529404 | J3: 0 | K3: 0 | L3: 0 | M3: 0
A4: PIM Global Balanced D (PGPGBFD) | B4: 45203 | C4: PGPGBFD | D4: PR30DZAR | E4: 62.2 | F4: 59 | G4: 3.2 | H4: 22589967 | I4: 36326204 | J4: 0 | K4: 0 | L4: 0 | M4: 0
A5: PIM Global Income Provider E (PGPGIFE) | B5: 45203 | C5: PGPGIFE | D5: PR03EZAR | E5: 59 | F5: 56.98 | G5: 2.02 | H5: 43263314 | I5: 73384024 | J5: 0 | K5: 0 | L5: 0 | M5: 0
A6: PIM Global Income Provider I (PGPGIFI) | B6: 45203 | C6: PGPGIFI | D6: PR03IZAR | E6: 55.7 | F6: 53.8 | G6: 1.9 | H6: 7829324.5 | I6: 14058908 | J6: 0 | K6: 0 | L6: 107.25 | M6: 0
A7: PIM Global Positive Return E (PGPRFE) | B7: 45203 | C7: PGPRFE | D7: PR04EUSD | E7: 109.8 | F7: 108.17 | G7: 1.63 | H7: 222951.81 | I7: 203077.38 | J7: 0 | K7: 0 | L7: 7.63 | M7: 0
A8: PIM Global Positive Return G (PGPRFG) | B8: 45203 | C8: PGPRFG | D8: PR04GZAR | E8: 107.7 | F8: 55.67 | G8: 52.03 | H8: 3280284.7 | I8: 3045804.4 | J8: 0 | K8: 0 | L8: 0 | M8: 0

Sheet UCITS rules
B1: Maximum % of Net Assets | E1: =HYPERLINK("http://www.irishstatutebook.ie/eli/2019/si/230/made/en/pdf","CBoI UCITS Regulations, SI 230 of 2019, incl Share Classes") -> CBoI UCITS Regulations, SI 230 of 2019, incl Share Classes
A2: 1. Transferable Securities and Money Market Instruments
A3: Other than those referred to in Paragraph 1 of UCITS 9.4 | B3: 0.1
A5: 2. Collective Investment Schemes
A6: Any one CIS | B6: 0.2
A8: 3. Transferable Securities and Money Market Instruments
A9: Issued by the same body | B9: 0.1
A10: Total value held in issuing bodies of which holdings are greater than 5% | B10: 0.4
A12: 4. Deposits
A13: Same Credit Institution | B13: 0.2
A14: Deposits with any one credit institution, other than those specified below * held as ancillary liquidity | B14: 0.1
A16: 5. OTC Derivatives
A17: risk exposure to a counterparty to an OTC derivative | B17: 0.05
A18: risk exposure to a counterparty to an OTC derivative with credit institutions below * | B18: 0.1
A20: 6. Special Cases
A21: (a) Bonds issued by a credit institution registered in a Member State and subject by law to special public supervision designed to protect bond-holders | B21: 0.25
A22: Total value of bonds held in issuing bodies (a) above of which holdings are greater than 5% | B22: 0.8
A23: (b) Transferable securities or money market instruments issued or guaranteed by a Member State or its local authorities or by a non-Member State or public international body of which one or more Member States are members | B23: 0.25
A25: 7. Combinations
A26: two or more of 3,4 or 5 issued by, or made or undertaken with, the same body | B26: 0.2
B27: 0.35
A30: * Specified deposits with credit instutions:
A31: A UCITS may invest in deposits provided that they are repayable on demand or have the right to be withdrawn, will mature in no more than 12 months and are made with a credit institution which falls under one of the following categories:
A32: (i) authorised in the European Economic Area (EEA) (European Union Member States, Norway, Iceland, Liechtenstein);
A33: (ii) authorised within a signatory state, other than a Member State of the EEA, to the Basle Capital Convergence Agreement of July 1988 (Switzerland, Canada, Japan, United States);
A34: (iii) authorised in Jersey, Guernsey, the Isle of Man, Australia or New Zealand.
A36: Significant Holdings
A37: A UCITS may acquire no more than:
A38: (i) 10 per cent of the non-voting shares of any single issuing body;
A39: (ii) 10 per cent of the debt securities of any single issuing body;
A40: (iii) 25 per cent of the units of any single CIS;
A41: (iv) 10 per cent of the money market instruments of any single issuing body.
A43: Derogation
... A63: complying with the requirements of this Regulation.
